Workbook
Name a: #REF!
Name a: #REF!
Name a: #REF!
Name a: #REF!
Name aa: #REF!
Name aa: #REF!
Name aa: #REF!
Name aa: #REF!
Name ABC_1: #REF!
Name abc_18: #REF!
Name abc_20: #REF!
Name abc_21: #REF!
Name ABC_4: #REF!
Name ABC_7: #REF!
Name ABC_8: #REF!
Name Admin: #REF!
Name admin_cross: #REF!
Name admin_cross_1: #REF!
Name adminfee: #REF!
Name adminfee: #REF!
Name adminfee: #REF!
Name adminfee: #REF!
Name AJK: #REF!,#REF!
Name all.Regions: #REF!
Name as: #REF!
Name b: #REF!
Name b: #REF!
Name b: #REF!
Name b: #REF!
Name Bal: #REF!
Name Balochistan2: #REF!,#REF!,#REF!,#REF!,#REF!,#REF!,#REF!,#REF!,#REF!,#REF!,#REF!,#REF!,#REF!,#REF!,#REF!,#REF!,#REF!,#REF!,#REF!,#REF!,#REF!,#REF!,#REF!,#REF!
Name BUDGET: #REF!
Name BUDGETCURRENCYCODE1: #REF!
Name BUDGETCURRENCYCODE12: #REF!
Name BUDGETCURRENCYCODE13: #REF!
Name BUDGETCURRENCYCODE2: #REF!
Name BUDGETCURRENCYCODE3: #REF!
Name BUDGETCURRENCYCODE4: #REF!
Name BUDGETCURRENCYCODE5: #REF!
Name BUDGETCURRENCYCODE6: #REF!
Name BUDGETNAME1: #REF!
Name BUDGETNAME12: #REF!
Name BUDGETNAME13: #REF!
Name BUDGETNAME2: #REF!
Name BUDGETNAME3: #REF!
Name BUDGETNAME4: #REF!
Name BUDGETNAME5: #REF!
Name BUDGETNAME6: #REF!
Name BUDGETORG1: #REF!
Name BUDGETORG12: #REF!
Name BUDGETORG13: #REF!
Name BUDGETORG2: #REF!
Name BUDGETORG3: #REF!
Name BUDGETORG4: #REF!
Name BUDGETORG5: #REF!
Name BUDGETORG6: #REF!
Name bus_catg: #REF!
Name Category: #REF!
Name cogos_cross: #REF!
Name cogos_cross_1: #REF!

Sheet Master File FMCG Team
N1: ` | GO1: 2 | GP1: =GO1+1 -> 3 | GQ1: =GP1+1 -> 4 | GR1: =GQ1+1 -> 5 | GS1: =GR1+1 -> 6 | GT1: =GS1+1 -> 7 | GU1: =GT1+1 -> 8 | GV1: =GU1+1 -> 9 | GW1: =GV1+1 -> 10 | ... HQ1: =HP1+1 -> 30 | HT1: 2 | HU1: =+HT1+1 -> 3 | HV1: =+HU1+1 -> 4 | HW1: =+HV1+1 -> 5 | HX1: =+HW1+1 -> 6 | HY1: =+HX1+1 -> 7 | HZ1: =+HY1+1 -> 8 | IA1: =+HZ1+1 -> 9 | IB1: =+IA1+1 -> 10 | ... IW1: =+IV1+1 -> 31
A2: FMCG Team – IKON MTD Call Performance Summary Till 14-Oct-2026 | V2: Attendance (Oct-2026) | BC2: Calls + Exceptions Other Calls (Oct-2026) | GM2: IKON Calls | GO2: Attendance | HT2: Calls
A3: Legend | B3: Team | C3: Zone | D3: Region | E3: Dept. Territory Code | F3: Position_Code | G3: SAS_ID | H3: SPO Name | I3: LAST EMP | J3: Base Town | K3: Emp. Type | L3: Emp. Code | M3: Payroll Status | N3: D.O.J | O3: Reps | P3: # Of Vacant | Q3: Active SPOs Today Attn | R3: Active SPOs MTD Attn | S3: Active SPOs Today Calls | T3: Active SPOs MTD Calls | U3: IKON Used | V3: 1 | W3: =V3+1 -> 2 | X3: =W3+1 -> 3 | Y3: =X3+1 -> 4 | Z3: =Y3+1 -> 5 | AA3: =Z3+1 -> 6 | AB3: =AA3+1 -> 7 | AC3: =AB3+1 -> 8 | AD3: =AC3+1 -> 9 | ... AZ3: =AY3+1 -> 31 | BA3: Attendance | BB3: Avrg Attn | BC3: 1 | BD3: =BC3+1 -> 2 | BE3: =BD3+1 -> 3 | BF3: =BE3+1 -> 4 | BG3: =BF3+1 -> 5 | BH3: =BG3+1 -> 6 | BI3: =BH3+1 -> 7 | BJ3: =BI3+1 -> 8 | BK3: =BJ3+1 -> 9 | ... CG3: =CF3+1 -> 31 | CH3: Calls | CI3: Avrg Calls | CK3: =NETWORKDAYS.INTL(EOMONTH(TODAY(),-1)+1,TODAY(),11) -> 13 | GM3: Legend | GN3: Mapping | GO3: 1 | GP3: =GO3+1 -> 2 | GQ3: =GP3+1 -> 3 | GR3: =GQ3+1 -> 4 | GS3: =GR3+1 -> 5 | GT3: =GS3+1 -> 6 | GU3: =GT3+1 -> 7 | GV3: =GU3+1 -> 8 | GW3: =GV3+1 -> 9 | ... HS3: =HR3+1 -> 31 | HT3: 1 | HU3: =HT3+1 -> 2 | HV3: =HU3+1 -> 3 | HW3: =HV3+1 -> 4 | HX3: =HW3+1 -> 5 | HY3: =HX3+1 -> 6 | HZ3: =HY3+1 -> 7 | IA3: =HZ3+1 -> 8 | IB3: =IA3+1 -> 9 | ... IX3: =IW3+1 -> 31
A4: SPO | B4: DO Team | C4: South-A | D4: Karachi-1 | E4: KHI-01 | F4: KHI01-FMCG01-SPO-01 | G4: 114001 | H4: SY. HUZAIFA ALI (KHI-01) | I4: SY. HUZAIFA ALI (KHI-01) | J4: NAZ + NORTH KHI | K4: STREET | L4: G1847 | M4: PRIME-HR | N4: 46127 | O4: 1 | P4: 0 | Q4: =IFERROR(IF(OR(AI4>0),1,0),0) -> 0 | R4: =IFERROR(IF(OR(BA4>0),1,0),0) -> 1 | S4: =IFERROR(IF(OR(BP4>0),1,0),0) -> 0 | T4: =IFERROR(IF(OR(CH4>0),1,0),0) -> 1 | U4: =IFERROR(IF(OR(BA4>0,CH4>0),1,0),0) -> 1 | V4: =GO4 -> 1 | W4: =GP4 -> 1 | X4: =GQ4 -> 0 | Y4: =GR4 -> 0 | Z4: =GS4 -> 1 | AA4: =GT4 -> 1 | AB4: =GU4 -> 1 | AC4: =GV4 -> 1 | ... AZ4: =HS4 -> 0 | BA4: =SUM(V4:AZ4) -> 10 | BB4: =IFERROR(BA4/$CK$3/(O4-P4),0) -> 0.76923077 | BC4: =HT4 -> 0 | BD4: =HU4 -> 0 | BE4: =HV4 -> 0 | BF4: =HW4 -> 0 | BG4: =HX4 -> 0 | BH4: =HY4 -> 17 | BI4: =HZ4 -> 29 | BJ4: =IA4 -> 26 | ... CG4: =IX4 -> 0 | CH4: =SUM(BC4:CG4) -> 166 | CI4: =IFERROR(CH4/$CK$3/(O4-P4),0) -> 12.769231 | GM4: Data | GN4: =F4 -> KHI01-FMCG01-SPO-01 | GO4: 1 | GP4: 1 | GQ4: 0 | GR4: 0 | GS4: 1 | GT4: 1 | GU4: 1 | GV4: 1 | GW4: 1 | GX4: 1 | GY4: 0 | GZ4: 1 | HA4: 1 | HB4: 0 | HT4: 0 | HU4: 0 | HV4: 0 | HW4: 0 | HX4: 0 | HY4: 17 | HZ4: 29 | IA4: 26 | IB4: 0 | IC4: 18 | ID4: 0 | IE4: 33 | IF4: 43 | IG4: 0
A5: SPO | B5: DO Team | C5: South-A | D5: Karachi-1 | E5: KHI-02 | F5: KHI01-FMCG01-SPO-02 | G5: 0114003 | H5: WAQASUDDIN (KHI-02) | I5: WAQASUDDIN (KHI-02) | J5: ORANGI TOWN-KHI | K5: STREET | L5: G1899 | M5: PRIME-HR | N5: 46220 | O5: 1 | P5: 0 | Q5: =IFERROR(IF(OR(AI5>0),1,0),0) -> 1 | R5: =IFERROR(IF(OR(BA5>0),1,0),0) -> 1 | S5: =IFERROR(IF(OR(BP5>0),1,0),0) -> 0 | T5: =IFERROR(IF(OR(CH5>0),1,0),0) -> 1 | U5: =IFERROR(IF(OR(BA5>0,CH5>0),1,0),0) -> 1 | V5: =GO5 -> 1 | W5: =GP5 -> 1 | X5: =GQ5 -> 1 | Y5: =GR5 -> 0 | Z5: =GS5 -> 1 | AA5: =GT5 -> 1 | AB5: =GU5 -> 1 | AC5: =GV5 -> 1 | ... AZ5: =HS5 -> 0 | BA5: =SUM(V5:AZ5) -> 12 | BB5: =IFERROR(BA5/$CK$3/(O5-P5),0) -> 0.92307692 | BC5: =HT5 -> 0 | BD5: =HU5 -> 0 | BE5: =HV5 -> 0 | BF5: =HW5 -> 0 | BG5: =HX5 -> 18 | BH5: =HY5 -> 29 | BI5: =HZ5 -> 26 | BJ5: =IA5 -> 0 | ... CG5: =IX5 -> 0 | CH5: =SUM(BC5:CG5) -> 146 | CI5: =IFERROR(CH5/$CK$3/(O5-P5),0) -> 11.230769 | GM5: Data | GN5: =F5 -> KHI01-FMCG01-SPO-02 | GO5: 1 | GP5: 1 | GQ5: 1 | GR5: 0 | GS5: 1 | GT5: 1 | GU5: 1 | GV5: 1 | GW5: 1 | GX5: 1 | GY5: 0 | GZ5: 1 | HA5: 1 | HB5: 1 | HT5: 0 | HU5: 0 | HV5: 0 | HW5: 0 | HX5: 18 | HY5: 29 | HZ5: 26 | IA5: 0 | IB5: 26 | IC5: 26 | ID5: 0 | IE5: 0 | IF5: 21 | IG5: 0
A6: SPO | B6: DO Team | C6: South-A | D6: Karachi-1 | E6: KHI-03 | F6: KHI01-FMCG01-SPO-03 | G6: 114005 | H6: SAMEER KHAN (KHI-03) | I6: SAMEER KHAN (KHI-03) | J6: F B AREA -KHI | K6: STREET | L6: G1676 | M6: PRIME-HR | N6: 45839 | O6: 1 | P6: 0 | Q6: =IFERROR(IF(OR(AI6>0),1,0),0) -> 1 | R6: =IFERROR(IF(OR(BA6>0),1,0),0) -> 1 | S6: =IFERROR(IF(OR(BP6>0),1,0),0) -> 0 | T6: =IFERROR(IF(OR(CH6>0),1,0),0) -> 1 | U6: =IFERROR(IF(OR(BA6>0,CH6>0),1,0),0) -> 1 | V6: =GO6 -> 1 | W6: =GP6 -> 1 | X6: =GQ6 -> 1 | Y6: =GR6 -> 0 | Z6: =GS6 -> 1 | AA6: =GT6 -> 1 | AB6: =GU6 -> 1 | AC6: =GV6 -> 1 | ... AZ6: =HS6 -> 0 | BA6: =SUM(V6:AZ6) -> 12 | BB6: =IFERROR(BA6/$CK$3/(O6-P6),0) -> 0.92307692 | BC6: =HT6 -> 19 | BD6: =HU6 -> 20 | BE6: =HV6 -> 26 | BF6: =HW6 -> 0 | BG6: =HX6 -> 52 | BH6: =HY6 -> 0 | BI6: =HZ6 -> 52 | BJ6: =IA6 -> 46 | ... CG6: =IX6 -> 0 | CH6: =SUM(BC6:CG6) -> 375 | CI6: =IFERROR(CH6/$CK$3/(O6-P6),0) -> 28.846154 | GM6: Data | GN6: =F6 -> KHI01-FMCG01-SPO-03 | GO6: 1 | GP6: 1 | GQ6: 1 | GR6: 0 | GS6: 1 | GT6: 1 | GU6: 1 | GV6: 1 | GW6: 1 | GX6: 1 | GY6: 0 | GZ6: 1 | HA6: 1 | HB6: 1 | HT6: 19 | HU6: 20 | HV6: 26 | HW6: 0 | HX6: 52 | HY6: 0 | HZ6: 52 | IA6: 46 | IB6: 46 | IC6: 41 | ID6: 0 | IE6: 29 | IF6: 44 | IG6: 0
A7: SPO | B7: DO Team | C7: South-A | D7: Karachi-1 | E7: KHI-04 | F7: KHI01-FMCG01-SPO-04 | G7: 0114006 | H7: M. QADEER ALAM (KHI-04) | I7: M. QADEER ALAM (KHI-04) | J7: NEW KHI-KHI | K7: STREET | L7: G1810 | M7: PRIME-HR | N7: 46038 | O7: 1 | P7: 0 | Q7: =IFERROR(IF(OR(AI7>0),1,0),0) -> 1 | R7: =IFERROR(IF(OR(BA7>0),1,0),0) -> 1 | S7: =IFERROR(IF(OR(BP7>0),1,0),0) -> 0 | T7: =IFERROR(IF(OR(CH7>0),1,0),0) -> 1 | U7: =IFERROR(IF(OR(BA7>0,CH7>0),1,0),0) -> 1 | V7: =GO7 -> 1 | W7: =GP7 -> 1 | X7: =GQ7 -> 1 | Y7: =GR7 -> 0 | Z7: =GS7 -> 1 | AA7: =GT7 -> 1 | AB7: =GU7 -> 1 | AC7: =GV7 -> 1 | ... AZ7: =HS7 -> 0 | BA7: =SUM(V7:AZ7) -> 12 | BB7: =IFERROR(BA7/$CK$3/(O7-P7),0) -> 0.92307692 | BC7: =HT7 -> 26 | BD7: =HU7 -> 27 | BE7: =HV7 -> 38 | BF7: =HW7 -> 0 | BG7: =HX7 -> 19 | BH7: =HY7 -> 24 | BI7: =HZ7 -> 29 | BJ7: =IA7 -> 26 | ... CG7: =IX7 -> 0 | CH7: =SUM(BC7:CG7) -> 319 | CI7: =IFERROR(CH7/$CK$3/(O7-P7),0) -> 24.538462 | GM7: Data | GN7: =F7 -> KHI01-FMCG01-SPO-04 | GO7: 1 | GP7: 1 | GQ7: 1 | GR7: 0 | GS7: 1 | GT7: 1 | GU7: 1 | GV7: 1 | GW7: 1 | GX7: 1 | GY7: 0 | GZ7: 1 | HA7: 1 | HB7: 1 | HT7: 26 | HU7: 27 | HV7: 38 | HW7: 0 | HX7: 19 | HY7: 24 | HZ7: 29 | IA7: 26 | IB7: 32 | IC7: 35 | ID7: 0 | IE7: 33 | IF7: 30 | IG7: 0
A8: SPO | B8: DO Team | C8: South-A | D8: Karachi-1 | E8: KHI-05 | F8: KHI01-FMCG01-SPO-05 | G8: 0115004 | H8: RIAZ (KHI-05) | I8: RIAZ (KHI-05) | J8: GULSHAN + JOHAR-KHI | K8: STREET | L8: G1854 | M8: PRIME-HR | N8: 46135 | O8: 1 | P8: 0 | Q8: =IFERROR(IF(OR(AI8>0),1,0),0) -> 1 | R8: =IFERROR(IF(OR(BA8>0),1,0),0) -> 1 | S8: =IFERROR(IF(OR(BP8>0),1,0),0) -> 0 | T8: =IFERROR(IF(OR(CH8>0),1,0),0) -> 1 | U8: =IFERROR(IF(OR(BA8>0,CH8>0),1,0),0) -> 1 | V8: =GO8 -> 1 | W8: =GP8 -> 1 | X8: =GQ8 -> 1 | Y8: =GR8 -> 0 | Z8: =GS8 -> 1 | AA8: =GT8 -> 1 | AB8: =GU8 -> 1 | AC8: =GV8 -> 1 | ... AZ8: =HS8 -> 0 | BA8: =SUM(V8:AZ8) -> 12 | BB8: =IFERROR(BA8/$CK$3/(O8-P8),0) -> 0.92307692 | BC8: =HT8 -> 0 | BD8: =HU8 -> 0 | BE8: =HV8 -> 25 | BF8: =HW8 -> 0 | BG8: =HX8 -> 38 | BH8: =HY8 -> 0 | BI8: =HZ8 -> 28 | BJ8: =IA8 -> 35 | ... CG8: =IX8 -> 0 | CH8: =SUM(BC8:CG8) -> 235 | CI8: =IFERROR(CH8/$CK$3/(O8-P8),0) -> 18.076923 | GM8: Data | GN8: =F8 -> KHI01-FMCG01-SPO-05 | GO8: 1 | GP8: 1 | GQ8: 1 | GR8: 0 | GS8: 1 | GT8: 1 | GU8: 1 | GV8: 1 | GW8: 1 | GX8: 1 | GY8: 0 | GZ8: 1 | HA8: 1 | HB8: 1 | HT8: 0 | HU8: 0 | HV8: 25 | HW8: 0 | HX8: 38 | HY8: 0 | HZ8: 28 | IA8: 35 | IB8: 0 | IC8: 39 | ID8: 0 | IE8: 41 | IF8: 29 | IG8: 0
A9: SPO Unmap | B9: DO Team | C9: South-A | D9: Karachi-1 | E9: Others | F9: KHI01-FMCG01-SPO-00 | G9: 0114008 | H9: FMCG UNMAPPED (KHI01) | I9: FMCG UNMAPPED (KHI01) | J9: KARACHI | K9: UN-DEFINED | L9: UN-DEFINED | M9: UN-DEFINED | N9: 45474 | O9: 0 | P9: 0 | Q9: =IFERROR(IF(OR(AI9>0),1,0),0) -> 0 | R9: =IFERROR(IF(OR(BA9>0),1,0),0) -> 0 | S9: =IFERROR(IF(OR(BP9>0),1,0),0) -> 0 | T9: =IFERROR(IF(OR(CH9>0),1,0),0) -> 0 | U9: =IFERROR(IF(OR(BA9>0,CH9>0),1,0),0) -> 0 | V9: =GO9 -> 0 | W9: =GP9 -> 0 | X9: =GQ9 -> 0 | Y9: =GR9 -> 0 | Z9: =GS9 -> 0 | AA9: =GT9 -> 0 | AB9: =GU9 -> 0 | AC9: =GV9 -> 0 | ... AZ9: =HS9 -> 0 | BA9: =SUM(V9:AZ9) -> 0 | BB9: =IFERROR(BA9/$CK$3/(O9-P9),0) -> 0 | BC9: =HT9 -> 0 | BD9: =HU9 -> 0 | BE9: =HV9 -> 0 | BF9: =HW9 -> 0 | BG9: =HX9 -> 0 | BH9: =HY9 -> 0 | BI9: =HZ9 -> 0 | BJ9: =IA9 -> 0 | ... CG9: =IX9 -> 0 | CH9: =SUM(BC9:CG9) -> 0 | CI9: =IFERROR(CH9/$CK$3/(O9-P9),0) -> 0 | GM9: Data | GN9: =F9 -> KHI01-FMCG01-SPO-00 | GO9: 0 | GP9: 0 | GQ9: 0 | GR9: 0 | GS9: 0 | GT9: 0 | GU9: 0 | GV9: 0 | GW9: 0 | GX9: 0 | GY9: 0 | GZ9: 0 | HA9: 0 | HB9: 0 | HT9: 0 | HU9: 0 | HV9: 0 | HW9: 0 | HX9: 0 | HY9: 0 | HZ9: 0 | IA9: 0 | IB9: 0 | IC9: 0 | ID9: 0 | IE9: 0 | IF9: 0 | IG9: 0
A10: ASM Unmap | B10: DO Team | C10: South-A | D10: Karachi-1 | E10: ST-KHI-1-DIR-PHR | F10: KHI01-FMCG01-ASM-01 | G10: 01140 | H10: M. WAQAR IQBAL | I10: M. WAQAR IQBAL | J10: KARACHI | K10: STREET | L10: E-02621 | M10: GSM-PR | N10: 45941 | O10: 0 | P10: 0 | Q10: =IFERROR(IF(OR(AI10>0),1,0),0) -> 0 | R10: =IFERROR(IF(OR(BA10>0),1,0),0) -> 0 | S10: =IFERROR(IF(OR(BP10>0),1,0),0) -> 0 | T10: =IFERROR(IF(OR(CH10>0),1,0),0) -> 0 | U10: =IFERROR(IF(OR(BA10>0,CH10>0),1,0),0) -> 0 | V10: =GO10 -> 0 | W10: =GP10 -> 0 | X10: =GQ10 -> 0 | Y10: =GR10 -> 0 | Z10: =GS10 -> 0 | AA10: =GT10 -> 0 | AB10: =GU10 -> 0 | AC10: =GV10 -> 0 | ... AZ10: =HS10 -> 0 | BA10: =SUM(V10:AZ10) -> 0 | BB10: =IFERROR(BA10/$CK$3/(O10-P10),0) -> 0 | BC10: =HT10 -> 0 | BD10: =HU10 -> 0 | BE10: =HV10 -> 0 | BF10: =HW10 -> 0 | BG10: =HX10 -> 0 | BH10: =HY10 -> 0 | BI10: =HZ10 -> 0 | BJ10: =IA10 -> 0 | ... CG10: =IX10 -> 0 | CH10: =SUM(BC10:CG10) -> 0 | CI10: =IFERROR(CH10/$CK$3/(O10-P10),0) -> 0 | GM10: Data | GN10: =F10 -> KHI01-FMCG01-ASM-01 | GO10: 0 | GP10: 0 | GQ10: 0 | GR10: 0 | GS10: 0 | GT10: 0 | GU10: 0 | GV10: 0 | GW10: 0 | GX10: 0 | GY10: 0 | GZ10: 0 | HA10: 0 | HB10: 0 | HT10: 0 | HU10: 0 | HV10: 0 | HW10: 0 | HX10: 0 | HY10: 0 | HZ10: 0 | IA10: 0 | IB10: 0 | IC10: 0 | ID10: 0 | IE10: 0 | IF10: 0 | IG10: 0
A11: ASM | B11: DO Team | C11: South-A | D11: Karachi-1 | E11: ST-KHI-1-DIR-PHR | F11: KHI01-FMCG01-ASM-01 | G11: 01140 | H11: M. WAQAR IQBAL | I11: M. WAQAR IQBAL | J11: KHI-1 | K11: SD+Street | L11: E-02621 | M11: GSM-PR | N11: 45941 | O11: =SUM(O4:O10) -> 5 | P11: =SUM(P4:P10) -> 0 | Q11: =IFERROR(IF(OR(AI11>0),1,0),0) -> 1 | R11: =SUM(R4:R10) -> 5 | S11: =SUM(S4:S10) -> 0 | T11: =SUM(T4:T10) -> 5 | U11: =SUM(U4:U10) -> 5 | V11: =SUM(V4:V10) -> 5 | W11: =SUM(W4:W10) -> 5 | X11: =SUM(X4:X10) -> 4 | Y11: =SUM(Y4:Y10) -> 0 | ... AZ11: =SUM(AZ4:AZ10) -> 0 | BA11: =SUM(V11:AZ11) -> 58 | BB11: =IFERROR(BA11/$CK$3/(O11-P11),0) -> 0.89230769 | BC11: =SUM(BC4:BC10) -> 45 | BD11: =SUM(BD4:BD10) -> 47 | BE11: =SUM(BE4:BE10) -> 89 | BF11: =SUM(BF4:BF10) -> 0 | BG11: =SUM(BG4:BG10) -> 127 | BH11: =SUM(BH4:BH10) -> 70 | BI11: =SUM(BI4:BI10) -> 164 | BJ11: =SUM(BJ4:BJ10) -> 133 | ... CG11: =SUM(CG4:CG10) -> 0 | CH11: =SUM(BC11:CG11) -> 1241 | CI11: =IFERROR(CH11/$CK$3/(O11-P11),0) -> 19.092308 | GM11: Formula | GN11: =F11 -> KHI01-FMCG01-ASM-01 | GO11: 0 | GP11: 0 | GQ11: 0 | GR11: 0 | GS11: 0 | GT11: 0 | GU11: 0 | GV11: 0 | GW11: 0 | GX11: 0 | GY11: 0 | GZ11: 0 | HA11: 0 | HB11: 0 | HT11: 0 | HU11: 0 | HV11: 0 | HW11: 0 | HX11: 0 | HY11: 0 | HZ11: 0 | IA11: 0 | IB11: 0 | IC11: 0 | ID11: 0 | IE11: 0 | IF11: 0 | IG11: 0
A12: SPO | B12: DO Team | C12: South-A | D12: KARACHI-2 | E12: KHI-06 | F12: KHI02-FMCG01-SPO-01 | G12: 0115002 | H12: ABDUL HASEEB (KHI-06) | I12: ABDUL HASEEB (KHI-06) | J12: OLD CITY + BALDIA-KHI | K12: STREET | L12: G1881 | M12: PRIME-HR | N12: 46202 | O12: 1 | P12: 0 | Q12: =IFERROR(IF(OR(AI12>0),1,0),0) -> 1 | R12: =IFERROR(IF(OR(BA12>0),1,0),0) -> 1 | S12: =IFERROR(IF(OR(BP12>0),1,0),0) -> 0 | T12: =IFERROR(IF(OR(CH12>0),1,0),0) -> 1 | U12: =IFERROR(IF(OR(BA12>0,CH12>0),1,0),0) -> 1 | V12: =GO12 -> 1 | W12: =GP12 -> 1 | X12: =GQ12 -> 1 | Y12: =GR12 -> 0 | Z12: =GS12 -> 1 | AA12: =GT12 -> 1 | AB12: =GU12 -> 1 | AC12: =GV12 -> 1 | ... AZ12: =HS12 -> 0 | BA12: =SUM(V12:AZ12) -> 12 | BB12: =IFERROR(BA12/$CK$3/(O12-P12),0) -> 0.92307692 | BC12: =HT12 -> 0 | BD12: =HU12 -> 0 | BE12: =HV12 -> 31 | BF12: =HW12 -> 0 | BG12: =HX12 -> 50 | BH12: =HY12 -> 0 | BI12: =HZ12 -> 0 | BJ12: =IA12 -> 36 | ... CG12: =IX12 -> 0 | CH12: =SUM(BC12:CG12) -> 227 | CI12: =IFERROR(CH12/$CK$3/(O12-P12),0) -> 17.461538 | GM12: Data | GN12: =F12 -> KHI02-FMCG01-SPO-01 | GO12: 1 | GP12: 1 | GQ12: 1 | GR12: 0 | GS12: 1 | GT12: 1 | GU12: 1 | GV12: 1 | GW12: 1 | GX12: 1 | GY12: 0 | GZ12: 1 | HA12: 1 | HB12: 1 | HT12: 0 | HU12: 0 | HV12: 31 | HW12: 0 | HX12: 50 | HY12: 0 | HZ12: 0 | IA12: 36 | IB12: 37 | IC12: 40 | ID12: 0 | IE12: 33 | IF12: 0 | IG12: 0
A13: SPO | B13: DO Team | C13: South-A | D13: KARACHI-2 | E13: KHI-07 | F13: KHI02-FMCG01-SPO-02 | G13: 0126007 | H13: SHAHID ABDUL QADIR (KHI-07) | I13: SHAHID ABDUL QADIR (KHI-07) | J13: KORANGI + DHA-KHI | K13: STREET | L13: G1768 | M13: PRIME-HR | N13: 45988 | O13: 1 | P13: 0 | Q13: =IFERROR(IF(OR(AI13>0),1,0),0) -> 1 | R13: =IFERROR(IF(OR(BA13>0),1,0),0) -> 1 | S13: =IFERROR(IF(OR(BP13>0),1,0),0) -> 0 | T13: =IFERROR(IF(OR(CH13>0),1,0),0) -> 1 | U13: =IFERROR(IF(OR(BA13>0,CH13>0),1,0),0) -> 1 | V13: =GO13 -> 1 | W13: =GP13 -> 1 | X13: =GQ13 -> 1 | Y13: =GR13 -> 0 | Z13: =GS13 -> 1 | AA13: =GT13 -> 1 | AB13: =GU13 -> 1 | AC13: =GV13 -> 1 | ... AZ13: =HS13 -> 0 | BA13: =SUM(V13:AZ13) -> 12 | BB13: =IFERROR(BA13/$CK$3/(O13-P13),0) -> 0.92307692 | BC13: =HT13 -> 37 | BD13: =HU13 -> 43 | BE13: =HV13 -> 37 | BF13: =HW13 -> 0 | BG13: =HX13 -> 46 | BH13: =HY13 -> 30 | BI13: =HZ13 -> 37 | BJ13: =IA13 -> 59 | ... CG13: =IX13 -> 0 | CH13: =SUM(BC13:CG13) -> 373 | CI13: =IFERROR(CH13/$CK$3/(O13-P13),0) -> 28.692308 | GM13: Data | GN13: =F13 -> KHI02-FMCG01-SPO-02 | GO13: 1 | GP13: 1 | GQ13: 1 | GR13: 0 | GS13: 1 | GT13: 1 | GU13: 1 | GV13: 1 | GW13: 1 | GX13: 1 | GY13: 0 | GZ13: 1 | HA13: 1 | HB13: 1 | HT13: 37 | HU13: 43 | HV13: 37 | HW13: 0 | HX13: 46 | HY13: 30 | HZ13: 37 | IA13: 59 | IB13: 34 | IC13: 0 | ID13: 0 | IE13: 15 | IF13: 35 | IG13: 0
A14: SPO | B14: DO Team | C14: South-A | D14: KARACHI-2 | E14: KHI-08 | F14: KHI02-FMCG01-SPO-03 | G14: 0115003 | H14: WAQAS HASSAM (KHI-08) | I14: WAQAS HASSAM (KHI-08) | J14: SADDAR-KHI | K14: STREET | L14: G1291 | M14: PRIME-HR | N14: 45190 | O14: 1 | P14: 0 | Q14: =IFERROR(IF(OR(AI14>0),1,0),0) -> 1 | R14: =IFERROR(IF(OR(BA14>0),1,0),0) -> 1 | S14: =IFERROR(IF(OR(BP14>0),1,0),0) -> 0 | T14: =IFERROR(IF(OR(CH14>0),1,0),0) -> 1 | U14: =IFERROR(IF(OR(BA14>0,CH14>0),1,0),0) -> 1 | V14: =GO14 -> 1 | W14: =GP14 -> 1 | X14: =GQ14 -> 1 | Y14: =GR14 -> 0 | Z14: =GS14 -> 1 | AA14: =GT14 -> 1 | AB14: =GU14 -> 1 | AC14: =GV14 -> 1 | ... AZ14: =HS14 -> 0 | BA14: =SUM(V14:AZ14) -> 12 | BB14: =IFERROR(BA14/$CK$3/(O14-P14),0) -> 0.92307692 | BC14: =HT14 -> 30 | BD14: =HU14 -> 33 | BE14: =HV14 -> 31 | BF14: =HW14 -> 0 | BG14: =HX14 -> 34 | BH14: =HY14 -> 45 | BI14: =HZ14 -> 35 | BJ14: =IA14 -> 29 | ... CG14: =IX14 -> 0 | CH14: =SUM(BC14:CG14) -> 390 | CI14: =IFERROR(CH14/$CK$3/(O14-P14),0) -> 30 | GM14: Data | GN14: =F14 -> KHI02-FMCG01-SPO-03 | GO14: 1 | GP14: 1 | GQ14: 1 | GR14: 0 | GS14: 1 | GT14: 1 | GU14: 1 | GV14: 1 | GW14: 1 | GX14: 1 | GY14: 0 | GZ14: 1 | HA14: 1 | HB14: 1 | HT14: 30 | HU14: 33 | HV14: 31 | HW14: 0 | HX14: 34 | HY14: 45 | HZ14: 35 | IA14: 29 | IB14: 41 | IC14: 31 | ID14: 0 | IE14: 37 | IF14: 44 | IG14: 0
A15: SPO | B15: DO Team | C15: South-A | D15: KARACHI-2 | E15: KHI-09 | F15: KHI02-FMCG01-SPO-04 | G15: 0114004 | H15: M. USMAN (KHI-09) | I15: M. USMAN (KHI-09) | J15: MALIR-KHI | K15: STREET | L15: G1877 | M15: PRIME-HR | N15: 46192 | O15: 1 | P15: 0 | Q15: =IFERROR(IF(OR(AI15>0),1,0),0) -> 1 | R15: =IFERROR(IF(OR(BA15>0),1,0),0) -> 1 | S15: =IFERROR(IF(OR(BP15>0),1,0),0) -> 0 | T15: =IFERROR(IF(OR(CH15>0),1,0),0) -> 1 | U15: =IFERROR(IF(OR(BA15>0,CH15>0),1,0),0) -> 1 | V15: =GO15 -> 1 | W15: =GP15 -> 1 | X15: =GQ15 -> 1 | Y15: =GR15 -> 0 | Z15: =GS15 -> 1 | AA15: =GT15 -> 1 | AB15: =GU15 -> 1 | AC15: =GV15 -> 1 | ... AZ15: =HS15 -> 0 | BA15: =SUM(V15:AZ15) -> 12 | BB15: =IFERROR(BA15/$CK$3/(O15-P15),0) -> 0.92307692 | BC15: =HT15 -> 41 | BD15: =HU15 -> 29 | BE15: =HV15 -> 36 | BF15: =HW15 -> 0 | BG15: =HX15 -> 40 | BH15: =HY15 -> 40 | BI15: =HZ15 -> 34 | BJ15: =IA15 -> 35 | ... CG15: =IX15 -> 0 | CH15: =SUM(BC15:CG15) -> 410 | CI15: =IFERROR(CH15/$CK$3/(O15-P15),0) -> 31.538462 | GM15: Data | GN15: =F15 -> KHI02-FMCG01-SPO-04 | GO15: 1 | GP15: 1 | GQ15: 1 | GR15: 0 | GS15: 1 | GT15: 1 | GU15: 1 | GV15: 1 | GW15: 1 | GX15: 1 | GY15: 0 | GZ15: 1 | HA15: 1 | HB15: 1 | HT15: 41 | HU15: 29 | HV15: 36 | HW15: 0 | HX15: 40 | HY15: 40 | HZ15: 34 | IA15: 35 | IB15: 42 | IC15: 39 | ID15: 0 | IE15: 34 | IF15: 40 | IG15: 0
A16: SPO | B16: DO Team | C16: South-A | D16: KARACHI-2 | E16: KHI-10 | F16: KHI02-FMCG01-SPO-05 | G16: 0115005 | H16: HAMMAD WASEEM (KHI-10) | I16: HAMMAD WASEEM (KHI-10) | J16: SADDAR-KHI | K16: STREET | L16: G1535 | M16: PRIME-HR | N16: 45519 | O16: 1 | P16: 0 | Q16: =IFERROR(IF(OR(AI16>0),1,0),0) -> 0 | R16: =IFERROR(IF(OR(BA16>0),1,0),0) -> 1 | S16: =IFERROR(IF(OR(BP16>0),1,0),0) -> 0 | T16: =IFERROR(IF(OR(CH16>0),1,0),0) -> 1 | U16: =IFERROR(IF(OR(BA16>0,CH16>0),1,0),0) -> 1 | V16: =GO16 -> 0 | W16: =GP16 -> 1 | X16: =GQ16 -> 1 | Y16: =GR16 -> 0 | Z16: =GS16 -> 1 | AA16: =GT16 -> 1 | AB16: =GU16 -> 1 | AC16: =GV16 -> 1 | ... AZ16: =HS16 -> 0 | BA16: =SUM(V16:AZ16) -> 10 | BB16: =IFERROR(BA16/$CK$3/(O16-P16),0) -> 0.76923077 | BC16: =HT16 -> 39 | BD16: =HU16 -> 40 | BE16: =HV16 -> 0 | BF16: =HW16 -> 0 | BG16: =HX16 -> 41 | BH16: =HY16 -> 43 | BI16: =HZ16 -> 0 | BJ16: =IA16 -> 45 | ... CG16: =IX16 -> 0 | CH16: =SUM(BC16:CG16) -> 301 | CI16: =IFERROR(CH16/$CK$3/(O16-P16),0) -> 23.153846 | GM16: Data | GN16: =F16 -> KHI02-FMCG01-SPO-05 | GO16: 0 | GP16: 1 | GQ16: 1 | GR16: 0 | GS16: 1 | GT16: 1 | GU16: 1 | GV16: 1 | GW16: 1 | GX16: 1 | GY16: 0 | GZ16: 1 | HA16: 1 | HB16: 0 | HT16: 39 | HU16: 40 | HV16: 0 | HW16: 0 | HX16: 41 | HY16: 43 | HZ16: 0 | IA16: 45 | IB16: 44 | IC16: 0 | ID16: 0 | IE16: 0 | IF16: 49 | IG16: 0
A17: SPO Unmap | B17: DO Team | C17: South-A | D17: KARACHI-2 | E17: Others | F17: KHI02-FMCG01-SPO-00 | G17: 0115008 | H17: FMCG UNMAPPED (KHI02) | I17: FMCG UNMAPPED (KHI02) | J17: KARACHI | K17: UN-DEFINED | L17: UN-DEFINED | M17: UN-DEFINED | N17: 45474 | O17: 0 | P17: 0 | Q17: =IFERROR(IF(OR(AI17>0),1,0),0) -> 0 | R17: =IFERROR(IF(OR(BA17>0),1,0),0) -> 0 | S17: =IFERROR(IF(OR(BP17>0),1,0),0) -> 0 | T17: =IFERROR(IF(OR(CH17>0),1,0),0) -> 0 | U17: =IFERROR(IF(OR(BA17>0,CH17>0),1,0),0) -> 0 | V17: =GO17 -> 0 | W17: =GP17 -> 0 | X17: =GQ17 -> 0 | Y17: =GR17 -> 0 | Z17: =GS17 -> 0 | AA17: =GT17 -> 0 | AB17: =GU17 -> 0 | AC17: =GV17 -> 0 | ... AZ17: =HS17 -> 0 | BA17: =SUM(V17:AZ17) -> 0 | BB17: =IFERROR(BA17/$CK$3/(O17-P17),0) -> 0 | BC17: =HT17 -> 0 | BD17: =HU17 -> 0 | BE17: =HV17 -> 0 | BF17: =HW17 -> 0 | BG17: =HX17 -> 0 | BH17: =HY17 -> 0 | BI17: =HZ17 -> 0 | BJ17: =IA17 -> 0 | ... CG17: =IX17 -> 0 | CH17: =SUM(BC17:CG17) -> 0 | CI17: =IFERROR(CH17/$CK$3/(O17-P17),0) -> 0 | GM17: Data | GN17: =F17 -> KHI02-FMCG01-SPO-00 | GO17: 0 | GP17: 0 | GQ17: 0 | GR17: 0 | GS17: 0 | GT17: 0 | GU17: 0 | GV17: 0 | GW17: 0 | GX17: 0 | GY17: 0 | GZ17: 0 | HA17: 0 | HB17: 0 | HT17: 0 | HU17: 0 | HV17: 0 | HW17: 0 | HX17: 0 | HY17: 0 | HZ17: 0 | IA17: 0 | IB17: 0 | IC17: 0 | ID17: 0 | IE17: 0 | IF17: 0 | IG17: 0
A18: ASM Unmap | B18: DO Team | C18: South-A | D18: KARACHI-2 | E18: ST-KHI-2-DIR-PHR | F18: KHI02-FMCG01-ASM-01 | G18: 01150 | H18: WAQAR ABDUL RASHEED | I18: WAQAR ABDUL RASHEED | J18: KARACHI | K18: STREET | L18: G0925 | M18: PRIME-HR | N18: 44215 | O18: 0 | P18: 0 | Q18: =IFERROR(IF(OR(AI18>0),1,0),0) -> 0 | R18: =IFERROR(IF(OR(BA18>0),1,0),0) -> 0 | S18: =IFERROR(IF(OR(BP18>0),1,0),0) -> 0 | T18: =IFERROR(IF(OR(CH18>0),1,0),0) -> 0 | U18: =IFERROR(IF(OR(BA18>0,CH18>0),1,0),0) -> 0 | V18: =GO18 -> 0 | W18: =GP18 -> 0 | X18: =GQ18 -> 0 | Y18: =GR18 -> 0 | Z18: =GS18 -> 0 | AA18: =GT18 -> 0 | AB18: =GU18 -> 0 | AC18: =GV18 -> 0 | ... AZ18: =HS18 -> 0 | BA18: =SUM(V18:AZ18) -> 0 | BB18: =IFERROR(BA18/$CK$3/(O18-P18),0) -> 0 | BC18: =HT18 -> 0 | BD18: =HU18 -> 0 | BE18: =HV18 -> 0 | BF18: =HW18 -> 0 | BG18: =HX18 -> 0 | BH18: =HY18 -> 0 | BI18: =HZ18 -> 0 | BJ18: =IA18 -> 0 | ... CG18: =IX18 -> 0 | CH18: =SUM(BC18:CG18) -> 0 | CI18: =IFERROR(CH18/$CK$3/(O18-P18),0) -> 0 | GM18: Data | GN18: =F18 -> KHI02-FMCG01-ASM-01 | GO18: 0 | GP18: 0 | GQ18: 0 | GR18: 0 | GS18: 0 | GT18: 0 | GU18: 0 | GV18: 0 | GW18: 0 | GX18: 0 | GY18: 0 | GZ18: 0 | HA18: 0 | HB18: 0 | HT18: 0 | HU18: 0 | HV18: 0 | HW18: 0 | HX18: 0 | HY18: 0 | HZ18: 0 | IA18: 0 | IB18: 0 | IC18: 0 | ID18: 0 | IE18: 0 | IF18: 0 | IG18: 0
A19: ASM | B19: DO Team | C19: South-A | D19: Karachi-2 | E19: ST-KHI-2-DIR-PHR | F19: KHI02-FMCG01-ASM-01 | G19: 01150 | H19: WAQAR ABDUL RASHEED | I19: WAQAR ABDUL RASHEED | J19: KHI-2 | K19: SD+Street | L19: G0925 | M19: Prime-HR | N19: 44215 | O19: =SUM(O12:O18) -> 5 | P19: =SUM(P12:P18) -> 0 | Q19: =IFERROR(IF(OR(AI19>0),1,0),0) -> 1 | R19: =SUM(R12:R18) -> 5 | S19: =SUM(S12:S18) -> 0 | T19: =SUM(T12:T18) -> 5 | U19: =SUM(U12:U18) -> 5 | V19: =SUM(V12:V18) -> 4 | W19: =SUM(W12:W18) -> 5 | X19: =SUM(X12:X18) -> 5 | Y19: =SUM(Y12:Y18) -> 0 | ... AZ19: =SUM(AZ12:AZ18) -> 0 | BA19: =SUM(V19:AZ19) -> 58 | BB19: =IFERROR(BA19/$CK$3/(O19-P19),0) -> 0.89230769 | BC19: =SUM(BC12:BC18) -> 147 | BD19: =SUM(BD12:BD18) -> 145 | BE19: =SUM(BE12:BE18) -> 135 | BF19: =SUM(BF12:BF18) -> 0 | BG19: =SUM(BG12:BG18) -> 211 | BH19: =SUM(BH12:BH18) -> 158 | BI19: =SUM(BI12:BI18) -> 106 | BJ19: =SUM(BJ12:BJ18) -> 204 | ... CG19: =SUM(CG12:CG18) -> 0 | CH19: =SUM(BC19:CG19) -> 1701 | CI19: =IFERROR(CH19/$CK$3/(O19-P19),0) -> 26.169231 | GM19: Formula | GN19: =F19 -> KHI02-FMCG01-ASM-01 | GO19: 0 | GP19: 0 | GQ19: 0 | GR19: 0 | GS19: 0 | GT19: 0 | GU19: 0 | GV19: 0 | GW19: 0 | GX19: 0 | GY19: 0 | GZ19: 0 | HA19: 0 | HB19: 0 | HT19: 0 | HU19: 0 | HV19: 0 | HW19: 0 | HX19: 0 | HY19: 0 | HZ19: 0 | IA19: 0 | IB19: 0 | IC19: 0 | ID19: 0 | IE19: 0 | IF19: 0 | IG19: 0
A20: SPO | B20: DO Team | C20: South-A | D20: KARACHI-3 | E20: T-KHI-01 | F20: KHI03-FMCG02-SPO-01 | G20: 0119001 | H20: SHAHID HAMEED (T-KHI-01) | I20: SHAHID HAMEED (T-KHI-01) | J20: ORANGI TOWN-KHI | K20: STREET | L20: G0364 | M20: PRIME-HR | N20: 42199 | O20: 1 | P20: 0 | Q20: =IFERROR(IF(OR(AI20>0),1,0),0) -> 1 | R20: =IFERROR(IF(OR(BA20>0),1,0),0) -> 1 | S20: =IFERROR(IF(OR(BP20>0),1,0),0) -> 0 | T20: =IFERROR(IF(OR(CH20>0),1,0),0) -> 1 | U20: =IFERROR(IF(OR(BA20>0,CH20>0),1,0),0) -> 1 | V20: =GO20 -> 1 | W20: =GP20 -> 1 | X20: =GQ20 -> 1 | Y20: =GR20 -> 0 | Z20: =GS20 -> 1 | AA20: =GT20 -> 1 | AB20: =GU20 -> 1 | AC20: =GV20 -> 1 | ... AZ20: =HS20 -> 0 | BA20: =SUM(V20:AZ20) -> 12 | BB20: =IFERROR(BA20/$CK$3/(O20-P20),0) -> 0.92307692 | BC20: =HT20 -> 24 | BD20: =HU20 -> 27 | BE20: =HV20 -> 27 | BF20: =HW20 -> 0 | BG20: =HX20 -> 41 | BH20: =HY20 -> 34 | BI20: =HZ20 -> 26 | BJ20: =IA20 -> 0 | ... CG20: =IX20 -> 0 | CH20: =SUM(BC20:CG20) -> 285 | CI20: =IFERROR(CH20/$CK$3/(O20-P20),0) -> 21.923077 | GM20: Data | GN20: =F20 -> KHI03-FMCG02-SPO-01 | GO20: 1 | GP20: 1 | GQ20: 1 | GR20: 0 | GS20: 1 | GT20: 1 | GU20: 1 | GV20: 1 | GW20: 1 | GX20: 1 | GY20: 0 | GZ20: 1 | HA20: 1 | HB20: 1 | HT20: 24 | HU20: 27 | HV20: 27 | HW20: 0 | HX20: 41 | HY20: 34 | HZ20: 26 | IA20: 0 | IB20: 28 | IC20: 22 | ID20: 0 | IE20: 22 | IF20: 34 | IG20: 0
A21: SPO | B21: DO Team | C21: South-A | D21: KARACHI-3 | E21: T-KHI-02 | F21: KHI03-FMCG02-SPO-02 | G21: 0119003 | H21: KHAWAR (T-KHI-02) | I21: KHAWAR (T-KHI-02) | J21: OLD CITY -BALDIA KHI | K21: STREET | L21: G1657 | M21: PRIME-HR | N21: 45794 | O21: 1 | P21: 0 | Q21: =IFERROR(IF(OR(AI21>0),1,0),0) -> 1 | R21: =IFERROR(IF(OR(BA21>0),1,0),0) -> 1 | S21: =IFERROR(IF(OR(BP21>0),1,0),0) -> 0 | T21: =IFERROR(IF(OR(CH21>0),1,0),0) -> 1 | U21: =IFERROR(IF(OR(BA21>0,CH21>0),1,0),0) -> 1 | V21: =GO21 -> 1 | W21: =GP21 -> 1 | X21: =GQ21 -> 1 | Y21: =GR21 -> 0 | Z21: =GS21 -> 1 | AA21: =GT21 -> 1 | AB21: =GU21 -> 1 | AC21: =GV21 -> 1 | ... AZ21: =HS21 -> 0 | BA21: =SUM(V21:AZ21) -> 12 | BB21: =IFERROR(BA21/$CK$3/(O21-P21),0) -> 0.92307692 | BC21: =HT21 -> 39 | BD21: =HU21 -> 32 | BE21: =HV21 -> 36 | BF21: =HW21 -> 0 | BG21: =HX21 -> 38 | BH21: =HY21 -> 38 | BI21: =HZ21 -> 50 | BJ21: =IA21 -> 40 | ... CG21: =IX21 -> 0 | CH21: =SUM(BC21:CG21) -> 434 | CI21: =IFERROR(CH21/$CK$3/(O21-P21),0) -> 33.384615 | GM21: Data | GN21: =F21 -> KHI03-FMCG02-SPO-02 | GO21: 1 | GP21: 1 | GQ21: 1 | GR21: 0 | GS21: 1 | GT21: 1 | GU21: 1 | GV21: 1 | GW21: 1 | GX21: 1 | GY21: 0 | GZ21: 1 | HA21: 1 | HB21: 1 | HT21: 39 | HU21: 32 | HV21: 36 | HW21: 0 | HX21: 38 | HY21: 38 | HZ21: 50 | IA21: 40 | IB21: 39 | IC21: 29 | ID21: 0 | IE21: 42 | IF21: 51 | IG21: 0
A22: SPO | B22: DO Team | C22: South-A | D22: KARACHI-3 | E22: T-KHI-03 | F22: KHI03-FMCG02-SPO-03 | G22: 0119004 | H22: M. JAMSHED (T-KHI-03) | I22: M. JAMSHED (T-KHI-03) | J22: F B AREA -KHI | K22: STREET | L22: G1257 | M22: PRIME-HR | N22: 45111 | O22: 1 | P22: 0 | Q22: =IFERROR(IF(OR(AI22>0),1,0),0) -> 1 | R22: =IFERROR(IF(OR(BA22>0),1,0),0) -> 1 | S22: =IFERROR(IF(OR(BP22>0),1,0),0) -> 0 | T22: =IFERROR(IF(OR(CH22>0),1,0),0) -> 1 | U22: =IFERROR(IF(OR(BA22>0,CH22>0),1,0),0) -> 1 | V22: =GO22 -> 1 | W22: =GP22 -> 1 | X22: =GQ22 -> 1 | Y22: =GR22 -> 0 | Z22: =GS22 -> 1 | AA22: =GT22 -> 1 | AB22: =GU22 -> 1 | AC22: =GV22 -> 1 | ... AZ22: =HS22 -> 0 | BA22: =SUM(V22:AZ22) -> 12 | BB22: =IFERROR(BA22/$CK$3/(O22-P22),0) -> 0.92307692 | BC22: =HT22 -> 18 | BD22: =HU22 -> 15 | BE22: =HV22 -> 12 | BF22: =HW22 -> 0 | BG22: =HX22 -> 27 | BH22: =HY22 -> 26 | BI22: =HZ22 -> 0 | BJ22: =IA22 -> 31 | ... CG22: =IX22 -> 0 | CH22: =SUM(BC22:CG22) -> 270 | CI22: =IFERROR(CH22/$CK$3/(O22-P22),0) -> 20.769231 | GM22: Data | GN22: =F22 -> KHI03-FMCG02-SPO-03 | GO22: 1 | GP22: 1 | GQ22: 1 | GR22: 0 | GS22: 1 | GT22: 1 | GU22: 1 | GV22: 1 | GW22: 1 | GX22: 1 | GY22: 0 | GZ22: 1 | HA22: 1 | HB22: 1 | HT22: 18 | HU22: 15 | HV22: 12 | HW22: 0 | HX22: 27 | HY22: 26 | HZ22: 0 | IA22: 31 | IB22: 22 | IC22: 31 | ID22: 0 | IE22: 49 | IF22: 39 | IG22: 0
A23: SPO | B23: DO Team | C23: South-A | D23: KARACHI-3 | E23: T-KHI-04 | F23: KHI03-FMCG02-SPO-04 | G23: 0119007 | H23: VACANT (T-KHI-04) | I23: FAIZ BIN SALEEM (T-KHI-04) | J23: NEW KHI-KHI | K23: STREET | L23: VACANT | M23: PRIME-HR | N23: Resigned | O23: 1 | P23: 1 | Q23: =IFERROR(IF(OR(AI23>0),1,0),0) -> 0 | R23: =IFERROR(IF(OR(BA23>0),1,0),0) -> 0 | S23: =IFERROR(IF(OR(BP23>0),1,0),0) -> 0 | T23: =IFERROR(IF(OR(CH23>0),1,0),0) -> 0 | U23: =IFERROR(IF(OR(BA23>0,CH23>0),1,0),0) -> 0 | V23: =GO23 -> 0 | W23: =GP23 -> 0 | X23: =GQ23 -> 0 | Y23: =GR23 -> 0 | Z23: =GS23 -> 0 | AA23: =GT23 -> 0 | AB23: =GU23 -> 0 | AC23: =GV23 -> 0 | ... AZ23: =HS23 -> 0 | BA23: =SUM(V23:AZ23) -> 0 | BB23: =IFERROR(BA23/$CK$3/(O23-P23),0) -> 0 | BC23: =HT23 -> 0 | BD23: =HU23 -> 0 | BE23: =HV23 -> 0 | BF23: =HW23 -> 0 | BG23: =HX23 -> 0 | BH23: =HY23 -> 0 | BI23: =HZ23 -> 0 | BJ23: =IA23 -> 0 | ... CG23: =IX23 -> 0 | CH23: =SUM(BC23:CG23) -> 0 | CI23: =IFERROR(CH23/$CK$3/(O23-P23),0) -> 0 | GM23: Data | GN23: =F23 -> KHI03-FMCG02-SPO-04 | GO23: 0 | GP23: 0 | GQ23: 0 | GR23: 0 | GS23: 0 | GT23: 0 | GU23: 0 | GV23: 0 | GW23: 0 | GX23: 0 | GY23: 0 | GZ23: 0 | HA23: 0 | HB23: 0 | HT23: 0 | HU23: 0 | HV23: 0 | HW23: 0 | HX23: 0 | HY23: 0 | HZ23: 0 | IA23: 0 | IB23: 0 | IC23: 0 | ID23: 0 | IE23: 0 | IF23: 0 | IG23: 0
A24: SPO | B24: DO Team | C24: South-A | D24: KARACHI-3 | E24: T-KHI-05 | F24: KHI03-FMCG02-SPO-05 | G24: 0126001 | H24: VACANT (T-KHI-05) | I24: SY. FARZAN ALI SHAH (T-KHI-05) | J24: NAZIMABAD- NORTH KHI | K24: STREET | L24: VACANT | M24: PRIME-HR | N24: Resigned | O24: 1 | P24: 1 | Q24: =IFERROR(IF(OR(AI24>0),1,0),0) -> 0 | R24: =IFERROR(IF(OR(BA24>0),1,0),0) -> 0 | S24: =IFERROR(IF(OR(BP24>0),1,0),0) -> 0 | T24: =IFERROR(IF(OR(CH24>0),1,0),0) -> 0 | U24: =IFERROR(IF(OR(BA24>0,CH24>0),1,0),0) -> 0 | V24: =GO24 -> 0 | W24: =GP24 -> 0 | X24: =GQ24 -> 0 | Y24: =GR24 -> 0 | Z24: =GS24 -> 0 | AA24: =GT24 -> 0 | AB24: =GU24 -> 0 | AC24: =GV24 -> 0 | ... AZ24: =HS24 -> 0 | BA24: =SUM(V24:AZ24) -> 0 | BB24: =IFERROR(BA24/$CK$3/(O24-P24),0) -> 0 | BC24: =HT24 -> 0 | BD24: =HU24 -> 0 | BE24: =HV24 -> 0 | BF24: =HW24 -> 0 | BG24: =HX24 -> 0 | BH24: =HY24 -> 0 | BI24: =HZ24 -> 0 | BJ24: =IA24 -> 0 | ... CG24: =IX24 -> 0 | CH24: =SUM(BC24:CG24) -> 0 | CI24: =IFERROR(CH24/$CK$3/(O24-P24),0) -> 0 | GM24: Data | GN24: =F24 -> KHI03-FMCG02-SPO-05 | GO24: 0 | GP24: 0 | GQ24: 0 | GR24: 0 | GS24: 0 | GT24: 0 | GU24: 0 | GV24: 0 | GW24: 0 | GX24: 0 | GY24: 0 | GZ24: 0 | HA24: 0 | HB24: 0 | HT24: 0 | HU24: 0 | HV24: 0 | HW24: 0 | HX24: 0 | HY24: 0 | HZ24: 0 | IA24: 0 | IB24: 0 | IC24: 0 | ID24: 0 | IE24: 0 | IF24: 0 | IG24: 0
A25: SPO | B25: DO Team | C25: South-A | D25: KARACHI-3 | E25: T-KHI-11 | F25: KHI03-FMCG02-SPO-06 | G25: 0126009 | H25: ABDULLAH QURESHI (T-KHI-11) | I25: VACANT (T-KHI-11) | J25: BALDIA | K25: STREET | L25: G1628 | M25: PRIME-HR | N25: 45742 | O25: 1 | P25: 0 | Q25: =IFERROR(IF(OR(AI25>0),1,0),0) -> 1 | R25: =IFERROR(IF(OR(BA25>0),1,0),0) -> 1 | S25: =IFERROR(IF(OR(BP25>0),1,0),0) -> 0 | T25: =IFERROR(IF(OR(CH25>0),1,0),0) -> 1 | U25: =IFERROR(IF(OR(BA25>0,CH25>0),1,0),0) -> 1 | V25: =GO25 -> 1 | W25: =GP25 -> 1 | X25: =GQ25 -> 1 | Y25: =GR25 -> 0 | Z25: =GS25 -> 1 | AA25: =GT25 -> 1 | AB25: =GU25 -> 1 | AC25: =GV25 -> 1 | ... AZ25: =HS25 -> 0 | BA25: =SUM(V25:AZ25) -> 12 | BB25: =IFERROR(BA25/$CK$3/(O25-P25),0) -> 0.92307692 | BC25: =HT25 -> 35 | BD25: =HU25 -> 42 | BE25: =HV25 -> 36 | BF25: =HW25 -> 0 | BG25: =HX25 -> 34 | BH25: =HY25 -> 28 | BI25: =HZ25 -> 33 | BJ25: =IA25 -> 35 | ... CG25: =IX25 -> 0 | CH25: =SUM(BC25:CG25) -> 362 | CI25: =IFERROR(CH25/$CK$3/(O25-P25),0) -> 27.846154 | GM25: Data | GN25: =F25 -> KHI03-FMCG02-SPO-06 | GO25: 1 | GP25: 1 | GQ25: 1 | GR25: 0 | GS25: 1 | GT25: 1 | GU25: 1 | GV25: 1 | GW25: 1 | GX25: 1 | GY25: 0 | GZ25: 1 | HA25: 1 | HB25: 1 | HT25: 35 | HU25: 42 | HV25: 36 | HW25: 0 | HX25: 34 | HY25: 28 | HZ25: 33 | IA25: 35 | IB25: 32 | IC25: 29 | ID25: 0 | IE25: 24 | IF25: 34 | IG25: 0
A26: SPO Unmap | B26: DO Team | C26: South-A | D26: KARACHI-3 | E26: Others | F26: KHI03-FMCG02-SPO-00 | G26: 0128001 | H26: FMCG UNMAPPED (KHI03) | I26: FMCG UNMAPPED (KHI03) | J26: KARACHI | K26: UN-DEFINED | L26: UN-DEFINED | M26: UN-DEFINED | N26: 45474 | O26: 0 | P26: 0 | Q26: =IFERROR(IF(OR(AI26>0),1,0),0) -> 0 | R26: =IFERROR(IF(OR(BA26>0),1,0),0) -> 0 | S26: =IFERROR(IF(OR(BP26>0),1,0),0) -> 0 | T26: =IFERROR(IF(OR(CH26>0),1,0),0) -> 0 | U26: =IFERROR(IF(OR(BA26>0,CH26>0),1,0),0) -> 0 | V26: =GO26 -> 0 | W26: =GP26 -> 0 | X26: =GQ26 -> 0 | Y26: =GR26 -> 0 | Z26: =GS26 -> 0 | AA26: =GT26 -> 0 | AB26: =GU26 -> 0 | AC26: =GV26 -> 0 | ... AZ26: =HS26 -> 0 | BA26: =SUM(V26:AZ26) -> 0 | BB26: =IFERROR(BA26/$CK$3/(O26-P26),0) -> 0 | BC26: =HT26 -> 0 | BD26: =HU26 -> 0 | BE26: =HV26 -> 0 | BF26: =HW26 -> 0 | BG26: =HX26 -> 0 | BH26: =HY26 -> 0 | BI26: =HZ26 -> 0 | BJ26: =IA26 -> 0 | ... CG26: =IX26 -> 0 | CH26: =SUM(BC26:CG26) -> 0 | CI26: =IFERROR(CH26/$CK$3/(O26-P26),0) -> 0 | GM26: Data | GN26: =F26 -> KHI03-FMCG02-SPO-00 | GO26: 0 | GP26: 0 | GQ26: 0 | GR26: 0 | GS26: 0 | GT26: 0 | GU26: 0 | GV26: 0 | GW26: 0 | GX26: 0 | GY26: 0 | GZ26: 0 | HA26: 0 | HB26: 0 | HT26: 0 | HU26: 0 | HV26: 0 | HW26: 0 | HX26: 0 | HY26: 0 | HZ26: 0 | IA26: 0 | IB26: 0 | IC26: 0 | ID26: 0 | IE26: 0 | IF26: 0 | IG26: 0
A27: ASM Unmap | B27: DO Team | C27: South-A | D27: KARACHI-3 | E27: TH-KHI-3-DIR-PHR | F27: KHI03-FMCG02-ASM-01 | G27: 01280 | H27: SABAHAT KHAN SOORI | I27: SABAHAT KHAN SOORI | J27: KARACHI | K27: STREET | L27: E-02623 | M27: GSM-PR | N27: 45941 | O27: 0 | P27: 0 | Q27: =IFERROR(IF(OR(AI27>0),1,0),0) -> 0 | R27: =IFERROR(IF(OR(BA27>0),1,0),0) -> 0 | S27: =IFERROR(IF(OR(BP27>0),1,0),0) -> 0 | T27: =IFERROR(IF(OR(CH27>0),1,0),0) -> 0 | U27: =IFERROR(IF(OR(BA27>0,CH27>0),1,0),0) -> 0 | V27: =GO27 -> 0 | W27: =GP27 -> 0 | X27: =GQ27 -> 0 | Y27: =GR27 -> 0 | Z27: =GS27 -> 0 | AA27: =GT27 -> 0 | AB27: =GU27 -> 0 | AC27: =GV27 -> 0 | ... AZ27: =HS27 -> 0 | BA27: =SUM(V27:AZ27) -> 0 | BB27: =IFERROR(BA27/$CK$3/(O27-P27),0) -> 0 | BC27: =HT27 -> 0 | BD27: =HU27 -> 0 | BE27: =HV27 -> 0 | BF27: =HW27 -> 0 | BG27: =HX27 -> 0 | BH27: =HY27 -> 0 | BI27: =HZ27 -> 0 | BJ27: =IA27 -> 0 | ... CG27: =IX27 -> 0 | CH27: =SUM(BC27:CG27) -> 0 | CI27: =IFERROR(CH27/$CK$3/(O27-P27),0) -> 0 | GM27: Data | GN27: =F27 -> KHI03-FMCG02-ASM-01 | GO27: 0 | GP27: 0 | GQ27: 0 | GR27: 0 | GS27: 0 | GT27: 0 | GU27: 0 | GV27: 0 | GW27: 0 | GX27: 0 | GY27: 0 | GZ27: 0 | HA27: 0 | HB27: 0 | HT27: 0 | HU27: 0 | HV27: 0 | HW27: 0 | HX27: 0 | HY27: 0 | HZ27: 0 | IA27: 0 | IB27: 0 | IC27: 0 | ID27: 0 | IE27: 0 | IF27: 0 | IG27: 0
A28: ASM | B28: DO Team | C28: South-A | D28: Karachi-3 | E28: TH-KHI-3-DIR-PHR | F28: KHI03-FMCG02-ASM-01 | G28: 01280 | H28: SABAHAT KHAN SOORI | I28: SABAHAT KHAN SOORI | J28: KHI-3 | K28: LMT+Street | L28: 45941 | M28: GSM-PR | N28: 45941 | O28: =SUM(O20:O27) -> 6 | P28: =SUM(P20:P27) -> 2 | Q28: =IFERROR(IF(OR(AI28>0),1,0),0) -> 1 | R28: =R27+R25+R24+R23+R22+R21+R20 -> 4 | S28: =S27+S25+S24+S23+S22+S21+S20 -> 0 | T28: =T27+T25+T24+T23+T22+T21+T20 -> 4 | U28: =U27+U25+U24+U23+U22+U21+U20 -> 4 | V28: =V27+V25+V24+V23+V22+V21+V20 -> 4 | W28: =W27+W25+W24+W23+W22+W21+W20 -> 4 | X28: =X27+X25+X24+X23+X22+X21+X20 -> 4 | Y28: =Y27+Y25+Y24+Y23+Y22+Y21+Y20 -> 0 | ... AZ28: =AZ27+AZ25+AZ24+AZ23+AZ22+AZ21+AZ20 -> 0 | BA28: =SUM(V28:AZ28) -> 48 | BB28: =IFERROR(BA28/$CK$3/(O28-P28),0) -> 0.92307692 | BC28: =BC27+BC25+BC24+BC23+BC22+BC21+BC20 -> 116 | BD28: =BD27+BD25+BD24+BD23+BD22+BD21+BD20 -> 116 | BE28: =BE27+BE25+BE24+BE23+BE22+BE21+BE20 -> 111 | BF28: =BF27+BF25+BF24+BF23+BF22+BF21+BF20 -> 0 | BG28: =BG27+BG25+BG24+BG23+BG22+BG21+BG20 -> 140 | BH28: =BH27+BH25+BH24+BH23+BH22+BH21+BH20 -> 126 | BI28: =BI27+BI25+BI24+BI23+BI22+BI21+BI20 -> 109 | BJ28: =BJ27+BJ25+BJ24+BJ23+BJ22+BJ21+BJ20 -> 106 | ... CG28: =CG27+CG25+CG24+CG23+CG22+CG21+CG20 -> 0 | CH28: =SUM(BC28:CG28) -> 1351 | CI28: =IFERROR(CH28/$CK$3/(O28-P28),0) -> 25.980769 | GM28: Formula | GN28: =F28 -> KHI03-FMCG02-ASM-01 | GO28: 0 | GP28: 0 | GQ28: 0 | GR28: 0 | GS28: 0 | GT28: 0 | GU28: 0 | GV28: 0 | GW28: 0 | GX28: 0 | GY28: 0 | GZ28: 0 | HA28: 0 | HB28: 0 | HT28: 0 | HU28: 0 | HV28: 0 | HW28: 0 | HX28: 0 | HY28: 0 | HZ28: 0 | IA28: 0 | IB28: 0 | IC28: 0 | ID28: 0 | IE28: 0 | IF28: 0 | IG28: 0
A29: SPO | B29: Touch Team | C29: South-A | D29: KARACHI-4 | E29: T-KHI-06 | F29: KHI04-FMCG02-SPO-01 | G29: 0126002 | H29: M. ASAD KHAN (T-KHI-06) | I29: M. ASAD KHAN (T-KHI-06) | J29: GULSHAN-JOHAR-KHI | K29: STREET | L29: G1149 | M29: PRIME-HR | N29: 44877 | O29: 1 | P29: 0 | Q29: =IFERROR(IF(OR(AI29>0),1,0),0) -> 1 | R29: =IFERROR(IF(OR(BA29>0),1,0),0) -> 1 | S29: =IFERROR(IF(OR(BP29>0),1,0),0) -> 0 | T29: =IFERROR(IF(OR(CH29>0),1,0),0) -> 1 | U29: =IFERROR(IF(OR(BA29>0,CH29>0),1,0),0) -> 1 | V29: =GO29 -> 1 | W29: =GP29 -> 1 | X29: =GQ29 -> 1 | Y29: =GR29 -> 0 | Z29: =GS29 -> 1 | AA29: =GT29 -> 1 | AB29: =GU29 -> 1 | AC29: =GV29 -> 1 | ... AZ29: =HS29 -> 0 | BA29: =SUM(V29:AZ29) -> 12 | BB29: =IFERROR(BA29/$CK$3/(O29-P29),0) -> 0.92307692 | BC29: =HT29 -> 0 | BD29: =HU29 -> 0 | BE29: =HV29 -> 0 | BF29: =HW29 -> 0 | BG29: =HX29 -> 0 | BH29: =HY29 -> 0 | BI29: =HZ29 -> 0 | BJ29: =IA29 -> 0 | ... CG29: =IX29 -> 0 | CH29: =SUM(BC29:CG29) -> 85 | CI29: =IFERROR(CH29/$CK$3/(O29-P29),0) -> 6.5384615 | GM29: Data | GN29: =F29 -> KHI04-FMCG02-SPO-01 | GO29: 1 | GP29: 1 | GQ29: 1 | GR29: 0 | GS29: 1 | GT29: 1 | GU29: 1 | GV29: 1 | GW29: 1 | GX29: 1 | GY29: 0 | GZ29: 1 | HA29: 1 | HB29: 1 | HT29: 0 | HU29: 0 | HV29: 0 | HW29: 0 | HX29: 0 | HY29: 0 | HZ29: 0 | IA29: 0 | IB29: 0 | IC29: 49 | ID29: 0 | IE29: 36 | IF29: 0 | IG29: 0
A30: SPO | B30: Touch Team | C30: South-A | D30: KARACHI-4 | E30: T-KHI-07 | F30: KHI04-FMCG02-SPO-02 | G30: 0126006 | H30: ABDUL RAFAY (T-KHI-07) | I30: ABDUL RAFAY (T-KHI-07) | J30: KORANGI-KHI | K30: STREET | L30: G0862 | M30: PRIME-HR | N30: 44014 | O30: 1 | P30: 0 | Q30: =IFERROR(IF(OR(AI30>0),1,0),0) -> 1 | R30: =IFERROR(IF(OR(BA30>0),1,0),0) -> 1 | S30: =IFERROR(IF(OR(BP30>0),1,0),0) -> 0 | T30: =IFERROR(IF(OR(CH30>0),1,0),0) -> 1 | U30: =IFERROR(IF(OR(BA30>0,CH30>0),1,0),0) -> 1 | V30: =GO30 -> 1 | W30: =GP30 -> 1 | X30: =GQ30 -> 1 | Y30: =GR30 -> 0 | Z30: =GS30 -> 1 | AA30: =GT30 -> 1 | AB30: =GU30 -> 1 | AC30: =GV30 -> 1 | ... AZ30: =HS30 -> 0 | BA30: =SUM(V30:AZ30) -> 12 | BB30: =IFERROR(BA30/$CK$3/(O30-P30),0) -> 0.92307692 | BC30: =HT30 -> 0 | BD30: =HU30 -> 0 | BE30: =HV30 -> 19 | BF30: =HW30 -> 0 | BG30: =HX30 -> 0 | BH30: =HY30 -> 37 | BI30: =HZ30 -> 19 | BJ30: =IA30 -> 0 | ... CG30: =IX30 -> 0 | CH30: =SUM(BC30:CG30) -> 157 | CI30: =IFERROR(CH30/$CK$3/(O30-P30),0) -> 12.076923 | GM30: Data | GN30: =F30 -> KHI04-FMCG02-SPO-02 | GO30: 1 | GP30: 1 | GQ30: 1 | GR30: 0 | GS30: 1 | GT30: 1 | GU30: 1 | GV30: 1 | GW30: 1 | GX30: 1 | GY30: 0 | GZ30: 1 | HA30: 1 | HB30: 1 | HT30: 0 | HU30: 0 | HV30: 19 | HW30: 0 | HX30: 0 | HY30: 37 | HZ30: 19 | IA30: 0 | IB30: 0 | IC30: 28 | ID30: 0 | IE30: 29 | IF30: 25 | IG30: 0
A31: SPO | B31: Touch Team | C31: South-A | D31: KARACHI-4 | E31: T-KHI-08 | F31: KHI04-FMCG02-SPO-03 | G31: 0126003 | H31: ASHAR UR REHMAN (T-KHI-08) | I31: ASHAR UR REHMAN (T-KHI-08) | J31: MALIR-KHI | K31: STREET | L31: G1108 | M31: PRIME-HR | N31: 44795 | O31: 1 | P31: 0 | Q31: =IFERROR(IF(OR(AI31>0),1,0),0) -> 1 | R31: =IFERROR(IF(OR(BA31>0),1,0),0) -> 1 | S31: =IFERROR(IF(OR(BP31>0),1,0),0) -> 0 | T31: =IFERROR(IF(OR(CH31>0),1,0),0) -> 1 | U31: =IFERROR(IF(OR(BA31>0,CH31>0),1,0),0) -> 1 | V31: =GO31 -> 1 | W31: =GP31 -> 1 | X31: =GQ31 -> 1 | Y31: =GR31 -> 0 | Z31: =GS31 -> 1 | AA31: =GT31 -> 1 | AB31: =GU31 -> 1 | AC31: =GV31 -> 1 | ... AZ31: =HS31 -> 0 | BA31: =SUM(V31:AZ31) -> 12 | BB31: =IFERROR(BA31/$CK$3/(O31-P31),0) -> 0.92307692 | BC31: =HT31 -> 29 | BD31: =HU31 -> 41 | BE31: =HV31 -> 43 | BF31: =HW31 -> 0 | BG31: =HX31 -> 39 | BH31: =HY31 -> 30 | BI31: =HZ31 -> 35 | BJ31: =IA31 -> 37 | ... CG31: =IX31 -> 0 | CH31: =SUM(BC31:CG31) -> 432 | CI31: =IFERROR(CH31/$CK$3/(O31-P31),0) -> 33.230769 | GM31: Data | GN31: =F31 -> KHI04-FMCG02-SPO-03 | GO31: 1 | GP31: 1 | GQ31: 1 | GR31: 0 | GS31: 1 | GT31: 1 | GU31: 1 | GV31: 1 | GW31: 1 | GX31: 1 | GY31: 0 | GZ31: 1 | HA31: 1 | HB31: 1 | HT31: 29 | HU31: 41 | HV31: 43 | HW31: 0 | HX31: 39 | HY31: 30 | HZ31: 35 | IA31: 37 | IB31: 33 | IC31: 39 | ID31: 0 | IE31: 51 | IF31: 55 | IG31: 0
A32: SPO | B32: Touch Team | C32: South-A | D32: KARACHI-4 | E32: T-KHI-09 | F32: KHI04-FMCG02-SPO-04 | G32: 0119002 | H32: SY. USAMA AHMED (T-KHI-09) | I32: SY. USAMA AHMED (T-KHI-09) | J32: LANDHI-KHI | K32: STREET | L32: G1205 | M32: PRIME-HR | N32: 44988 | O32: 1 | P32: 0 | Q32: =IFERROR(IF(OR(AI32>0),1,0),0) -> 1 | R32: =IFERROR(IF(OR(BA32>0),1,0),0) -> 1 | S32: =IFERROR(IF(OR(BP32>0),1,0),0) -> 0 | T32: =IFERROR(IF(OR(CH32>0),1,0),0) -> 1 | U32: =IFERROR(IF(OR(BA32>0,CH32>0),1,0),0) -> 1 | V32: =GO32 -> 1 | W32: =GP32 -> 1 | X32: =GQ32 -> 1 | Y32: =GR32 -> 0 | Z32: =GS32 -> 1 | AA32: =GT32 -> 1 | AB32: =GU32 -> 1 | AC32: =GV32 -> 1 | ... AZ32: =HS32 -> 0 | BA32: =SUM(V32:AZ32) -> 12 | BB32: =IFERROR(BA32/$CK$3/(O32-P32),0) -> 0.92307692 | BC32: =HT32 -> 41 | BD32: =HU32 -> 34 | BE32: =HV32 -> 44 | BF32: =HW32 -> 0 | BG32: =HX32 -> 44 | BH32: =HY32 -> 29 | BI32: =HZ32 -> 41 | BJ32: =IA32 -> 0 | ... CG32: =IX32 -> 0 | CH32: =SUM(BC32:CG32) -> 388 | CI32: =IFERROR(CH32/$CK$3/(O32-P32),0) -> 29.846154 | GM32: Data | GN32: =F32 -> KHI04-FMCG02-SPO-04 | GO32: 1 | GP32: 1 | GQ32: 1 | GR32: 0 | GS32: 1 | GT32: 1 | GU32: 1 | GV32: 1 | GW32: 1 | GX32: 1 | GY32: 0 | GZ32: 1 | HA32: 1 | HB32: 1 | HT32: 41 | HU32: 34 | HV32: 44 | HW32: 0 | HX32: 44 | HY32: 29 | HZ32: 41 | IA32: 0 | IB32: 30 | IC32: 44 | ID32: 0 | IE32: 37 | IF32: 44 | IG32: 0
A33: SPO | B33: Touch Team | C33: South-A | D33: KARACHI-4 | E33: T-KHI-10 | F33: KHI04-FMCG02-SPO-05 | G33: 0119005 | H33: SHAHROZ (T-KHI-10) | I33: SHAHROZ (T-KHI-10) | J33: DHA + CLIFTON-KHI | K33: STREET | L33: G1011 | M33: PRIME-HR | N33: 44498 | O33: 1 | P33: 0 | Q33: =IFERROR(IF(OR(AI33>0),1,0),0) -> 1 | R33: =IFERROR(IF(OR(BA33>0),1,0),0) -> 1 | S33: =IFERROR(IF(OR(BP33>0),1,0),0) -> 0 | T33: =IFERROR(IF(OR(CH33>0),1,0),0) -> 1 | U33: =IFERROR(IF(OR(BA33>0,CH33>0),1,0),0) -> 1 | V33: =GO33 -> 1 | W33: =GP33 -> 1 | X33: =GQ33 -> 1 | Y33: =GR33 -> 0 | Z33: =GS33 -> 1 | AA33: =GT33 -> 1 | AB33: =GU33 -> 1 | AC33: =GV33 -> 1 | ... AZ33: =HS33 -> 0 | BA33: =SUM(V33:AZ33) -> 12 | BB33: =IFERROR(BA33/$CK$3/(O33-P33),0) -> 0.92307692 | BC33: =HT33 -> 22 | BD33: =HU33 -> 23 | BE33: =HV33 -> 44 | BF33: =HW33 -> 0 | BG33: =HX33 -> 0 | BH33: =HY33 -> 26 | BI33: =HZ33 -> 35 | BJ33: =IA33 -> 30 | ... CG33: =IX33 -> 0 | CH33: =SUM(BC33:CG33) -> 276 | CI33: =IFERROR(CH33/$CK$3/(O33-P33),0) -> 21.230769 | GM33: Data | GN33: =F33 -> KHI04-FMCG02-SPO-05 | GO33: 1 | GP33: 1 | GQ33: 1 | GR33: 0 | GS33: 1 | GT33: 1 | GU33: 1 | GV33: 1 | GW33: 1 | GX33: 1 | GY33: 0 | GZ33: 1 | HA33: 1 | HB33: 1 | HT33: 22 | HU33: 23 | HV33: 44 | HW33: 0 | HX33: 0 | HY33: 26 | HZ33: 35 | IA33: 30 | IB33: 32 | IC33: 16 | ID33: 0 | IE33: 25 | IF33: 23 | IG33: 0
A34: SPO | B34: Touch Team | C34: South-A | D34: KARACHI-4 | E34: T-KHI-12 | F34: KHI04-FMCG02-SPO-06 | G34: 0126005 | H34: M. WASEM (T-KHI-12) | I34: M. WASEM (T-KHI-12) | J34: DHA + CLIFTON-KHI | K34: STREET | L34: 46230 | M34: VACANT | N34: 46230 | O34: 1 | P34: 0 | Q34: =IFERROR(IF(OR(AI34>0),1,0),0) -> 1 | R34: =IFERROR(IF(OR(BA34>0),1,0),0) -> 1 | S34: =IFERROR(IF(OR(BP34>0),1,0),0) -> 0 | T34: =IFERROR(IF(OR(CH34>0),1,0),0) -> 1 | U34: =IFERROR(IF(OR(BA34>0,CH34>0),1,0),0) -> 1 | V34: =GO34 -> 1 | W34: =GP34 -> 1 | X34: =GQ34 -> 1 | Y34: =GR34 -> 0 | Z34: =GS34 -> 1 | AA34: =GT34 -> 1 | AB34: =GU34 -> 1 | AC34: =GV34 -> 1 | ... AZ34: =HS34 -> 0 | BA34: =SUM(V34:AZ34) -> 12 | BB34: =IFERROR(BA34/$CK$3/(O34-P34),0) -> 0.92307692 | BC34: =HT34 -> 0 | BD34: =HU34 -> 38 | BE34: =HV34 -> 35 | BF34: =HW34 -> 0 | BG34: =HX34 -> 0 | BH34: =HY34 -> 37 | BI34: =HZ34 -> 63 | BJ34: =IA34 -> 36 | ... CG34: =IX34 -> 0 | CH34: =SUM(BC34:CG34) -> 369 | CI34: =IFERROR(CH34/$CK$3/(O34-P34),0) -> 28.384615 | GM34: Data | GN34: =F34 -> KHI04-FMCG02-SPO-06 | GO34: 1 | GP34: 1 | GQ34: 1 | GR34: 0 | GS34: 1 | GT34: 1 | GU34: 1 | GV34: 1 | GW34: 1 | GX34: 1 | GY34: 0 | GZ34: 1 | HA34: 1 | HB34: 1 | HT34: 0 | HU34: 38 | HV34: 35 | HW34: 0 | HX34: 0 | HY34: 37 | HZ34: 63 | IA34: 36 | IB34: 38 | IC34: 48 | ID34: 0 | IE34: 37 | IF34: 37 | IG34: 0
A35: SPO Unmap | B35: Touch Team | C35: South-A | D35: KARACHI-4 | E35: Others | F35: KHI04-FMCG02-SPO-00 | G35: 0119006 | H35: FMCG UNMAPPED (KHI04) | I35: FMCG UNMAPPED (KHI04) | J35: KARACHI | K35: UN-DEFINED | L35: UN-DEFINED | M35: UN-DEFINED | N35: 45474 | O35: 0 | P35: 0 | Q35: =IFERROR(IF(OR(AI35>0),1,0),0) -> 0 | R35: =IFERROR(IF(OR(BA35>0),1,0),0) -> 0 | S35: =IFERROR(IF(OR(BP35>0),1,0),0) -> 0 | T35: =IFERROR(IF(OR(CH35>0),1,0),0) -> 0 | U35: =IFERROR(IF(OR(BA35>0,CH35>0),1,0),0) -> 0 | V35: =GO35 -> 0 | W35: =GP35 -> 0 | X35: =GQ35 -> 0 | Y35: =GR35 -> 0 | Z35: =GS35 -> 0 | AA35: =GT35 -> 0 | AB35: =GU35 -> 0 | AC35: =GV35 -> 0 | ... AZ35: =HS35 -> 0 | BA35: =SUM(V35:AZ35) -> 0 | BB35: =IFERROR(BA35/$CK$3/(O35-P35),0) -> 0 | BC35: =HT35 -> 0 | BD35: =HU35 -> 0 | BE35: =HV35 -> 0 | BF35: =HW35 -> 0 | BG35: =HX35 -> 0 | BH35: =HY35 -> 0 | BI35: =HZ35 -> 0 | BJ35: =IA35 -> 0 | ... CG35: =IX35 -> 0 | CH35: =SUM(BC35:CG35) -> 0 | CI35: =IFERROR(CH35/$CK$3/(O35-P35),0) -> 0 | GM35: Data | GN35: =F35 -> KHI04-FMCG02-SPO-00 | GO35: 0 | GP35: 0 | GQ35: 0 | GR35: 0 | GS35: 0 | GT35: 0 | GU35: 0 | GV35: 0 | GW35: 0 | GX35: 0 | GY35: 0 | GZ35: 0 | HA35: 0 | HB35: 0 | HT35: 0 | HU35: 0 | HV35: 0 | HW35: 0 | HX35: 0 | HY35: 0 | HZ35: 0 | IA35: 0 | IB35: 0 | IC35: 0 | ID35: 0 | IE35: 0 | IF35: 0 | IG35: 0
A36: ASM Unmap | B36: Touch Team | C36: South-A | D36: KARACHI-4 | E36: TH-KHI-4-DIR-PHR | F36: KHI04-FMCG02-ASM-01 | G36: 01190 | H36: M. DANISH | I36: M. DANISH | J36: KARACHI | K36: STREET | L36: E-01708 | M36: GSM-PR | N36: 45139 | O36: 0 | P36: 0 | Q36: =IFERROR(IF(OR(AI36>0),1,0),0) -> 0 | R36: =IFERROR(IF(OR(BA36>0),1,0),0) -> 0 | S36: =IFERROR(IF(OR(BP36>0),1,0),0) -> 0 | T36: =IFERROR(IF(OR(CH36>0),1,0),0) -> 0 | U36: =IFERROR(IF(OR(BA36>0,CH36>0),1,0),0) -> 0 | V36: =GO36 -> 0 | W36: =GP36 -> 0 | X36: =GQ36 -> 0 | Y36: =GR36 -> 0 | Z36: =GS36 -> 0 | AA36: =GT36 -> 0 | AB36: =GU36 -> 0 | AC36: =GV36 -> 0 | ... AZ36: =HS36 -> 0 | BA36: =SUM(V36:AZ36) -> 0 | BB36: =IFERROR(BA36/$CK$3/(O36-P36),0) -> 0 | BC36: =HT36 -> 0 | BD36: =HU36 -> 0 | BE36: =HV36 -> 0 | BF36: =HW36 -> 0 | BG36: =HX36 -> 0 | BH36: =HY36 -> 0 | BI36: =HZ36 -> 0 | BJ36: =IA36 -> 0 | ... CG36: =IX36 -> 0 | CH36: =SUM(BC36:CG36) -> 0 | CI36: =IFERROR(CH36/$CK$3/(O36-P36),0) -> 0 | GM36: Data | GN36: =F36 -> KHI04-FMCG02-ASM-01 | GO36: 0 | GP36: 0 | GQ36: 0 | GR36: 0 | GS36: 0 | GT36: 0 | GU36: 0 | GV36: 0 | GW36: 0 | GX36: 0 | GY36: 0 | GZ36: 0 | HA36: 0 | HB36: 0 | HT36: 0 | HU36: 0 | HV36: 0 | HW36: 0 | HX36: 0 | HY36: 0 | HZ36: 0 | IA36: 0 | IB36: 0 | IC36: 0 | ID36: 0 | IE36: 0 | IF36: 0 | IG36: 0
A37: ASM | B37: Touch Team | C37: South-A | D37: Karachi-4 | E37: TH-KHI-4-DIR-PHR | F37: KHI04-FMCG02-ASM-01 | G37: 01190 | H37: M. DANISH | I37: M. DANISH | J37: KHI-4 | K37: SD+Street | L37: E-01708 | M37: GSM-PR | N37: 45139 | O37: =O35+O33+O32+O31+O30+O29+O34 -> 6 | P37: =P35+P33+P32+P31+P30+P29+P34 -> 0 | Q37: =Q35+Q33+Q32+Q31+Q30+Q29+Q34 -> 6 | R37: =R35+R33+R32+R31+R30+R29+R34 -> 6 | S37: =S35+S33+S32+S31+S30+S29+S34 -> 0 | T37: =T35+T33+T32+T31+T30+T29+T34 -> 6 | U37: =U35+U33+U32+U31+U30+U29+U34 -> 6 | V37: =V35+V33+V32+V31+V30+V29+V34 -> 6 | ... AZ37: =AZ35+AZ33+AZ32+AZ31+AZ30+AZ29+AZ34 -> 0 | BA37: =SUM(V37:AZ37) -> 72 | BB37: =IFERROR(BA37/$CK$3/(O37-P37),0) -> 0.92307692 | BC37: =BC35+BC33+BC32+BC31+BC30+BC29+BC34 -> 92 | BD37: =BD35+BD33+BD32+BD31+BD30+BD29+BD34 -> 136 | BE37: =BE35+BE33+BE32+BE31+BE30+BE29+BE34 -> 185 | BF37: =BF35+BF33+BF32+BF31+BF30+BF29+BF34 -> 0 | BG37: =BG35+BG33+BG32+BG31+BG30+BG29+BG34 -> 83 | BH37: =BH35+BH33+BH32+BH31+BH30+BH29+BH34 -> 159 | BI37: =BI35+BI33+BI32+BI31+BI30+BI29+BI34 -> 193 | BJ37: =BJ35+BJ33+BJ32+BJ31+BJ30+BJ29+BJ34 -> 103 | ... CG37: =CG35+CG33+CG32+CG31+CG30+CG29+CG34 -> 0 | CH37: =SUM(BC37:CG37) -> 1707 | CI37: =IFERROR(CH37/$CK$3/(O37-P37),0) -> 21.884615 | GM37: Formula | GN37: =F37 -> KHI04-FMCG02-ASM-01 | GO37: 0 | GP37: 0 | GQ37: 0 | GR37: 0 | GS37: 0 | GT37: 0 | GU37: 0 | GV37: 0 | GW37: 0 | GX37: 0 | GY37: 0 | GZ37: 0 | HA37: 0 | HB37: 0 | HT37: 0 | HU37: 0 | HV37: 0 | HW37: 0 | HX37: 0 | HY37: 0 | HZ37: 0 | IA37: 0 | IB37: 0 | IC37: 0 | ID37: 0 | IE37: 0 | IF37: 0 | IG37: 0
A38: SPO | B38: Touch Team | C38: South-A | D38: KARACHI-5 | E38: B-KHI-01 | F38: KHI05-FMCG03-SPO-01 | G38: 0114007 | H38: VACANT (B-KHI-01) | I38: M. AYYAN (B-KHI-01) | J38: GULSHAN-JOHAR-KHI | K38: STREET | L38: - | M38: VACANT | N38: 46202 | O38: 1 | P38: 1 | Q38: =IFERROR(IF(OR(AI38>0),1,0),0) -> 0 | R38: =IFERROR(IF(OR(BA38>0),1,0),0) -> 0 | S38: =IFERROR(IF(OR(BP38>0),1,0),0) -> 0 | T38: =IFERROR(IF(OR(CH38>0),1,0),0) -> 0 | U38: =IFERROR(IF(OR(BA38>0,CH38>0),1,0),0) -> 0 | V38: =GO38 -> 0 | W38: =GP38 -> 0 | X38: =GQ38 -> 0 | Y38: =GR38 -> 0 | Z38: =GS38 -> 0 | AA38: =GT38 -> 0 | AB38: =GU38 -> 0 | AC38: =GV38 -> 0 | ... AZ38: =HS38 -> 0 | BA38: =SUM(V38:AZ38) -> 0 | BB38: =IFERROR(BA38/$CK$3/(O38-P38),0) -> 0 | BC38: =HT38 -> 0 | BD38: =HU38 -> 0 | BE38: =HV38 -> 0 | BF38: =HW38 -> 0 | BG38: =HX38 -> 0 | BH38: =HY38 -> 0 | BI38: =HZ38 -> 0 | BJ38: =IA38 -> 0 | ... CG38: =IX38 -> 0 | CH38: =SUM(BC38:CG38) -> 0 | CI38: =IFERROR(CH38/$CK$3/(O38-P38),0) -> 0 | GM38: Data | GN38: =F38 -> KHI05-FMCG03-SPO-01 | GO38: 0 | GP38: 0 | GQ38: 0 | GR38: 0 | GS38: 0 | GT38: 0 | GU38: 0 | GV38: 0 | GW38: 0 | GX38: 0 | GY38: 0 | GZ38: 0 | HA38: 0 | HB38: 0 | HT38: 0 | HU38: 0 | HV38: 0 | HW38: 0 | HX38: 0 | HY38: 0 | HZ38: 0 | IA38: 0 | IB38: 0 | IC38: 0 | ID38: 0 | IE38: 0 | IF38: 0 | IG38: 0
A39: SPO | B39: Touch Team | C39: South-A | D39: KARACHI-5 | E39: B-KHI-02 | F39: KHI05-FMCG03-SPO-02 | G39: 0126008 | H39: ABDUL HADI (B-KHI-02) | I39: M. AYYAN (B-KHI-02) | J39: DHA + CLIFTON-KORANGI LANDHI KHI | K39: STREET | L39: G1894 | M39: PRIME-HR | N39: 46216 | O39: 1 | P39: 0 | Q39: =IFERROR(IF(OR(AI39>0),1,0),0) -> 1 | R39: =IFERROR(IF(OR(BA39>0),1,0),0) -> 1 | S39: =IFERROR(IF(OR(BP39>0),1,0),0) -> 0 | T39: =IFERROR(IF(OR(CH39>0),1,0),0) -> 1 | U39: =IFERROR(IF(OR(BA39>0,CH39>0),1,0),0) -> 1 | V39: =GO39 -> 1 | W39: =GP39 -> 1 | X39: =GQ39 -> 1 | Y39: =GR39 -> 0 | Z39: =GS39 -> 1 | AA39: =GT39 -> 1 | AB39: =GU39 -> 1 | AC39: =GV39 -> 1 | ... AZ39: =HS39 -> 0 | BA39: =SUM(V39:AZ39) -> 12 | BB39: =IFERROR(BA39/$CK$3/(O39-P39),0) -> 0.92307692 | BC39: =HT39 -> 13 | BD39: =HU39 -> 0 | BE39: =HV39 -> 0 | BF39: =HW39 -> 10 | BG39: =HX39 -> 16 | BH39: =HY39 -> 20 | BI39: =HZ39 -> 9 | BJ39: =IA39 -> 21 | ... CG39: =IX39 -> 0 | CH39: =SUM(BC39:CG39) -> 127 | CI39: =IFERROR(CH39/$CK$3/(O39-P39),0) -> 9.7692308 | GM39: Data | GN39: =F39 -> KHI05-FMCG03-SPO-02 | GO39: 1 | GP39: 1 | GQ39: 1 | GR39: 0 | GS39: 1 | GT39: 1 | GU39: 1 | GV39: 1 | GW39: 1 | GX39: 1 | GY39: 0 | GZ39: 1 | HA39: 1 | HB39: 1 | HT39: 13 | HU39: 0 | HV39: 0 | HW39: 10 | HX39: 16 | HY39: 20 | HZ39: 9 | IA39: 21 | IB39: 15 | IC39: 0 | ID39: 0 | IE39: 10 | IF39: 13 | IG39: 0
A40: SPO | B40: Touch Team | C40: South-A | D40: KARACHI-5 | E40: B-KHI-03 | F40: KHI05-FMCG03-SPO-03 | G40: 0114002 | H40: MUHAMAMD FURQAN (B-KHI-03) | I40: MUHAMAMD FURQAN (B-KHI-03) | J40: NAZIMABAD- NORTH KHI | K40: STREET | L40: G1892 | M40: PRIME-HR | N40: 46216 | O40: 1 | P40: 0 | Q40: =IFERROR(IF(OR(AI40>0),1,0),0) -> 1 | R40: =IFERROR(IF(OR(BA40>0),1,0),0) -> 1 | S40: =IFERROR(IF(OR(BP40>0),1,0),0) -> 0 | T40: =IFERROR(IF(OR(CH40>0),1,0),0) -> 1 | U40: =IFERROR(IF(OR(BA40>0,CH40>0),1,0),0) -> 1 | V40: =GO40 -> 1 | W40: =GP40 -> 1 | X40: =GQ40 -> 1 | Y40: =GR40 -> 0 | Z40: =GS40 -> 1 | AA40: =GT40 -> 1 | AB40: =GU40 -> 1 | AC40: =GV40 -> 1 | ... AZ40: =HS40 -> 0 | BA40: =SUM(V40:AZ40) -> 12 | BB40: =IFERROR(BA40/$CK$3/(O40-P40),0) -> 0.92307692 | BC40: =HT40 -> 0 | BD40: =HU40 -> 0 | BE40: =HV40 -> 0 | BF40: =HW40 -> 0 | BG40: =HX40 -> 0 | BH40: =HY40 -> 0 | BI40: =HZ40 -> 0 | BJ40: =IA40 -> 12 | ... CG40: =IX40 -> 0 | CH40: =SUM(BC40:CG40) -> 17 | CI40: =IFERROR(CH40/$CK$3/(O40-P40),0) -> 1.3076923 | GM40: Data | GN40: =F40 -> KHI05-FMCG03-SPO-03 | GO40: 1 | GP40: 1 | GQ40: 1 | GR40: 0 | GS40: 1 | GT40: 1 | GU40: 1 | GV40: 1 | GW40: 1 | GX40: 1 | GY40: 0 | GZ40: 1 | HA40: 1 | HB40: 1 | HT40: 0 | HU40: 0 | HV40: 0 | HW40: 0 | HX40: 0 | HY40: 0 | HZ40: 0 | IA40: 12 | IB40: 5 | IC40: 0 | ID40: 0 | IE40: 0 | IF40: 0 | IG40: 0
...

Sheet Managment Print
A1: ='Master File FMCG Team'!A2 -> FMCG Team – IKON MTD Call Performance Summary Till 14-Oct-2026 | H1: Attendance | M1: Calls + Exception Other Calls | T1: Comments
H2: 46309 | M2: =H2 -> 46309
A3: ='Master File FMCG Team'!A3 -> Legend | B3: ='Master File FMCG Team'!C3 -> Zone | C3: ='Master File FMCG Team'!D3 -> Region | D3: F.F Name | E3: ='Master File FMCG Team'!O3 -> Reps | F3: ='Master File FMCG Team'!P3 -> # Of Vacant | G3: Not Used IKON Today | H3: # of Attn Yesterday | I3: Active SPOs Today | J3: # of Attn MTD | K3: Active SPOs MTD | L3: Averg P/Rep/Day | M3: # of Calls Yesterday | N3: # of Calls Today | O3: Active SPOs Today | P3: # of Calls MTD | Q3: Active SPOs MTD | R3: Averg P/Rep/Day | S3: Status Calls
A4: ='Master File FMCG Team'!A11 -> ASM | B4: ='Master File FMCG Team'!C11 -> South-A | C4: ='Master File FMCG Team'!D11 -> Karachi-1 | D4: ='Master File FMCG Team'!H11 -> M. WAQAR IQBAL | E4: ='Master File FMCG Team'!O11 -> 5 | F4: ='Master File FMCG Team'!P11 -> 0 | G4: =E4-I4-F4 -> 1 | H4: ='Master File FMCG Team'!AH11 -> 5 | I4: ='Master File FMCG Team'!AI11 -> 4 | J4: ='Master File FMCG Team'!BA11 -> 58 | K4: ='Master File FMCG Team'!R11 -> 5 | L4: ='Master File FMCG Team'!BB11 -> 0.89230769 | M4: ='Master File FMCG Team'!BO11 -> 167 | N4: ='Master File FMCG Team'!BP11 -> 0 | O4: ='Master File FMCG Team'!S11 -> 0 | P4: ='Master File FMCG Team'!CH11 -> 1241 | Q4: ='Master File FMCG Team'!T11 -> 5 | R4: ='Master File FMCG Team'!CI11 -> 19.092308 | S4: =IF(R4>=30,"🟢 Excellent",IF(R4>=15,"🟡 Needs Improvement","🔴 Critical")) -> 🟡 Needs Improvement | U4: =P4/E4/13 -> 19.092308 | V4: =U4-R4 -> 0
A5: ='Master File FMCG Team'!A19 -> ASM | B5: ='Master File FMCG Team'!C19 -> South-A | C5: ='Master File FMCG Team'!D19 -> Karachi-2 | D5: ='Master File FMCG Team'!H19 -> WAQAR ABDUL RASHEED | E5: ='Master File FMCG Team'!O19 -> 5 | F5: ='Master File FMCG Team'!P19 -> 0 | G5: =E5-I5-F5 -> 1 | H5: ='Master File FMCG Team'!AH19 -> 5 | I5: ='Master File FMCG Team'!AI19 -> 4 | J5: ='Master File FMCG Team'!BA19 -> 58 | K5: ='Master File FMCG Team'!R19 -> 5 | L5: ='Master File FMCG Team'!BB19 -> 0.89230769 | M5: ='Master File FMCG Team'!BO19 -> 168 | N5: ='Master File FMCG Team'!BP19 -> 0 | O5: ='Master File FMCG Team'!S19 -> 0 | P5: ='Master File FMCG Team'!CH19 -> 1701 | Q5: ='Master File FMCG Team'!T19 -> 5 | R5: ='Master File FMCG Team'!CI19 -> 26.169231 | S5: =IF(R5>=30,"🟢 Excellent",IF(R5>=15,"🟡 Needs Improvement","🔴 Critical")) -> 🟡 Needs Improvement
A6: ='Master File FMCG Team'!A28 -> ASM | B6: ='Master File FMCG Team'!C28 -> South-A | C6: ='Master File FMCG Team'!D28 -> Karachi-3 | D6: ='Master File FMCG Team'!H28 -> SABAHAT KHAN SOORI | E6: ='Master File FMCG Team'!O28 -> 6 | F6: ='Master File FMCG Team'!P28 -> 2 | G6: =E6-I6-F6 -> 0 | H6: ='Master File FMCG Team'!AH28 -> 4 | I6: ='Master File FMCG Team'!AI28 -> 4 | J6: ='Master File FMCG Team'!BA28 -> 48 | K6: ='Master File FMCG Team'!R28 -> 4 | L6: ='Master File FMCG Team'!BB28 -> 0.92307692 | M6: ='Master File FMCG Team'!BO28 -> 158 | N6: ='Master File FMCG Team'!BP28 -> 0 | O6: ='Master File FMCG Team'!S28 -> 0 | P6: ='Master File FMCG Team'!CH28 -> 1351 | Q6: ='Master File FMCG Team'!T28 -> 4 | R6: ='Master File FMCG Team'!CI28 -> 25.980769 | S6: =IF(R6>=30,"🟢 Excellent",IF(R6>=15,"🟡 Needs Improvement","🔴 Critical")) -> 🟡 Needs Improvement
A7: ='Master File FMCG Team'!A37 -> ASM | B7: ='Master File FMCG Team'!C37 -> South-A | C7: ='Master File FMCG Team'!D37 -> Karachi-4 | D7: ='Master File FMCG Team'!H37 -> M. DANISH | E7: ='Master File FMCG Team'!O37 -> 6 | F7: ='Master File FMCG Team'!P37 -> 0 | G7: =E7-I7-F7 -> 0 | H7: ='Master File FMCG Team'!AH37 -> 6 | I7: ='Master File FMCG Team'!AI37 -> 6 | J7: ='Master File FMCG Team'!BA37 -> 72 | K7: ='Master File FMCG Team'!R37 -> 6 | L7: ='Master File FMCG Team'!BB37 -> 0.92307692 | M7: ='Master File FMCG Team'!BO37 -> 184 | N7: ='Master File FMCG Team'!BP37 -> 0 | O7: ='Master File FMCG Team'!S37 -> 0 | P7: ='Master File FMCG Team'!CH37 -> 1707 | Q7: ='Master File FMCG Team'!T37 -> 6 | R7: ='Master File FMCG Team'!CI37 -> 21.884615 | S7: =IF(R7>=30,"🟢 Excellent",IF(R7>=15,"🟡 Needs Improvement","🔴 Critical")) -> 🟡 Needs Improvement
A8: ='Master File FMCG Team'!A45 -> ASM | B8: ='Master File FMCG Team'!C45 -> South-A | C8: ='Master File FMCG Team'!D45 -> KARACHI-5 | D8: ='Master File FMCG Team'!H45 -> SY. HASSAN IQBAL ZAIDI | E8: ='Master File FMCG Team'!O45 -> 5 | F8: ='Master File FMCG Team'!P45 -> 1 | G8: =E8-I8-F8 -> 0 | H8: ='Master File FMCG Team'!AH45 -> 4 | I8: ='Master File FMCG Team'!AI45 -> 4 | J8: ='Master File FMCG Team'!BA45 -> 39 | K8: ='Master File FMCG Team'!R45 -> 4 | L8: ='Master File FMCG Team'!BB45 -> 0.75 | M8: ='Master File FMCG Team'!BO45 -> 13 | N8: ='Master File FMCG Team'!BP45 -> 0 | O8: ='Master File FMCG Team'!S45 -> 0 | P8: ='Master File FMCG Team'!CH45 -> 155 | Q8: ='Master File FMCG Team'!T45 -> 3 | R8: ='Master File FMCG Team'!CI45 -> 2.9807692 | S8: =IF(R8>=30,"🟢 Excellent",IF(R8>=15,"🟡 Needs Improvement","🔴 Critical")) -> 🔴 Critical
A9: ='Master File FMCG Team'!A46 -> CM | B9: ='Master File FMCG Team'!C46 -> South-A | C9: ='Master File FMCG Team'!D46 -> Karachi-6 | D9: ='Master File FMCG Team'!H46 -> OWAIS ABID (CM-KHI-01) | E9: ='Master File FMCG Team'!O46 -> 1 | F9: ='Master File FMCG Team'!P46 -> 0 | G9: =E9-I9-F9 -> 1 | H9: ='Master File FMCG Team'!AH46 -> 0 | I9: ='Master File FMCG Team'!AI46 -> 0 | J9: ='Master File FMCG Team'!BA46 -> 0 | K9: ='Master File FMCG Team'!R46 -> 0 | L9: ='Master File FMCG Team'!BB46 -> 0 | M9: ='Master File FMCG Team'!BO46 -> 0 | N9: ='Master File FMCG Team'!BP46 -> 0 | O9: ='Master File FMCG Team'!S46 -> 0 | P9: ='Master File FMCG Team'!CH46 -> 0 | Q9: ='Master File FMCG Team'!T46 -> 0 | R9: ='Master File FMCG Team'!CI46 -> 0 | S9: =IF(R9>=30,"🟢 Excellent",IF(R9>=15,"🟡 Needs Improvement","🔴 Critical")) -> 🔴 Critical
A10: ='Master File FMCG Team'!A47 -> TE | B10: ='Master File FMCG Team'!C47 -> South-A | C10: ='Master File FMCG Team'!D47 -> Karachi-7 | D10: ='Master File FMCG Team'!H47 -> M. AMEEN (TE-KHI-01) | E10: ='Master File FMCG Team'!O47 -> 1 | F10: ='Master File FMCG Team'!P47 -> 0 | G10: =E10-I10-F10 -> 1 | H10: ='Master File FMCG Team'!AH47 -> 1 | I10: ='Master File FMCG Team'!AI47 -> 0 | J10: ='Master File FMCG Team'!BA47 -> 11 | K10: ='Master File FMCG Team'!R47 -> 1 | L10: ='Master File FMCG Team'!BB47 -> 0.84615385 | M10: ='Master File FMCG Team'!BO47 -> 0 | N10: ='Master File FMCG Team'!BP47 -> 0 | O10: ='Master File FMCG Team'!S47 -> 0 | P10: ='Master File FMCG Team'!CH47 -> 0 | Q10: ='Master File FMCG Team'!T47 -> 0 | R10: ='Master File FMCG Team'!CI47 -> 0 | S10: =IF(R10>=30,"🟢 Excellent",IF(R10>=15,"🟡 Needs Improvement","🔴 Critical")) -> 🔴 Critical
