Workbook
Name a: #REF!
Name a: #REF!
Name a: #REF!
Name a: #REF!
Name aa: #REF!
Name aa: #REF!
Name aa: #REF!
Name aa: #REF!
Name aaaa: #REF!
Name ABC_1: '[1]3_2'!$A$11:$G$179
Name abc_18: [2]mfg!$A$10:$G$103
Name abc_20: [2]mfg!$A$10:$G$103
Name abc_21: [2]mfg!$A$10:$G$103
Name ABC_4: '[3]3_2'!$A$11:$G$179
Name ABC_7: '[3]3_2'!$A$11:$G$179
Name ABC_8: '[3]3_2'!$A$11:$G$179
Name Actual: (PeriodInActual*(#REF!>0))*PeriodInPlan
Name ActualBeyond: PeriodInActual*(#REF!>0)
Name Admin: '[4]Range Page'!$A$21
Name admin_cross: '[5]admin cross'!$A$1:$J$34
Name admin_cross_1: '[6]admin cross'!$A$1:$J$34
Name adminfee: #REF!
Name adminfee: #REF!
Name adminfee: #REF!
Name adminfee: #REF!
Name AJK: '[7]UC demographics'!$G$6918,'[7]UC demographics'!$G$6919
Name all.Regions: [8]Data!$B$4:$B$219
Name as: '[9]Travel by employee'!$J$4:$J$15
Name b: #REF!
Name b: #REF!
Name b: #REF!
Name b: #REF!
Name Bal: [10]Budget!$R$3
Name BUDGET: [11]CRITERIA13!$B$13
Name BUDGETCURRENCYCODE1: [11]CRITERIA1!$B$16
Name BUDGETCURRENCYCODE12: [11]CRITERIA12!$B$16
Name BUDGETCURRENCYCODE13: [11]CRITERIA13!$B$16
Name BUDGETCURRENCYCODE2: [11]CRITERIA2!$B$16
Name BUDGETCURRENCYCODE3: [11]CRITERIA3!$B$16
Name BUDGETCURRENCYCODE4: [11]CRITERIA4!$B$16
Name BUDGETCURRENCYCODE5: [11]CRITERIA5!$B$16
Name BUDGETCURRENCYCODE6: [11]CRITERIA6!$B$16
Name BUDGETNAME1: [11]CRITERIA1!$B$13
Name BUDGETNAME12: [11]CRITERIA12!$B$13
Name BUDGETNAME13: [11]CRITERIA13!$B$13
Name BUDGETNAME2: [11]CRITERIA2!$B$13
Name BUDGETNAME3: [11]CRITERIA3!$B$13
Name BUDGETNAME4: [11]CRITERIA4!$B$13
Name BUDGETNAME5: [11]CRITERIA5!$B$13
Name BUDGETNAME6: [11]CRITERIA6!$B$13
Name BUDGETORG1: [11]CRITERIA1!$B$14
Name BUDGETORG12: [11]CRITERIA12!$B$14
Name BUDGETORG13: [11]CRITERIA13!$B$14
Name BUDGETORG2: [11]CRITERIA2!$B$14
Name BUDGETORG3: [11]CRITERIA3!$B$14
Name BUDGETORG4: [11]CRITERIA4!$B$14
Name BUDGETORG5: [11]CRITERIA5!$B$14
Name BUDGETORG6: [11]CRITERIA6!$B$14
Name bus_catg: [12]Keys!$E$2:$E$5
Name Category: '[13]General Assumption(final)'!$I$10:$I$12

Sheet Pharma
JL1: 2 | JM1: =JL1+1 -> 3 | JN1: =JM1+1 -> 4 | JP1: =JN1+1 -> 5 | JQ1: =JP1+1 -> 6 | JR1: =JQ1+1 -> 7 | JS1: =JR1+1 -> 8 | JT1: =JS1+1 -> 9 | JU1: =JT1+1 -> 10 | JW1: =JU1+1 -> 11 | JX1: =JW1+1 -> 12 | JY1: =JX1+1 -> 13 | JZ1: =JY1+1 -> 14 | KA1: =JZ1+1 -> 15 | KB1: =KA1+1 -> 16 | KD1: =KB1+1 -> 17 | KE1: =KD1+1 -> 18 | KF1: =KE1+1 -> 19 | KG1: =KF1+1 -> 20 | KH1: =KG1+1 -> 21 | KI1: =KH1+1 -> 22 | KK1: =KI1+1 -> 23 | KL1: =KK1+1 -> 24 | KM1: =KL1+1 -> 25 | KN1: =KM1+1 -> 26 | KO1: =KN1+1 -> 27 | KP1: =KO1+1 -> 28 | KQ1: 2 | KR1: =KQ1+1 -> 3 | KS1: =KR1+1 -> 4 | KU1: =KS1+1 -> 5 | KV1: =KU1+1 -> 6 | KW1: =KV1+1 -> 7 | KX1: =KW1+1 -> 8 | KY1: =KX1+1 -> 9 | KZ1: =KY1+1 -> 10 | LB1: =KZ1+1 -> 11 | LC1: =LB1+1 -> 12 | LD1: =LC1+1 -> 13 | LE1: =LD1+1 -> 14 | LF1: =LE1+1 -> 15 | LG1: =LF1+1 -> 16 | LI1: =LG1+1 -> 17 | LJ1: =LI1+1 -> 18 | LK1: =LJ1+1 -> 19 | LL1: =LK1+1 -> 20 | LM1: =LL1+1 -> 21 | LN1: =LM1+1 -> 22 | LP1: =LN1+1 -> 23 | LQ1: =LP1+1 -> 24 | LR1: =LQ1+1 -> 25 | LS1: =LR1+1 -> 26 | LT1: =LS1+1 -> 27 | LU1: =LT1+1 -> 28
A2: PHARMA Team – IKON MTD Call Performance Summary Till 14-OCT-2026 | Q2: Attendance (OCT-2026) | AX2: Calls + Other Exceptions (OCT-2026) | CF2: =NETWORKDAYS.INTL(EOMONTH(TODAY(),-1)+1,TODAY(),11) -> 13 | JJ2: IKON | JL2: Attendance | KQ2: Calls
A3: Desig | B3: Zone | C3: PHR Region | D3: Position_Code | E3: SAS ID | F3: F.F Name | G3: Emp. Code | H3: DOJ | I3: Base Town | J3: Reps | K3: # Of Vacant | L3: Day Att Used | M3: MTD Att Use | N3: Day Call Used | O3: MTD Calls Use | P3: IKON Used | Q3: 1 | R3: =Q3+1 -> 2 | S3: =R3+1 -> 3 | T3: =S3+1 -> 4 | U3: =T3+1 -> 5 | V3: =U3+1 -> 6 | W3: =V3+1 -> 7 | X3: =W3+1 -> 8 | Y3: =X3+1 -> 9 | ... AU3: =AT3+1 -> 31 | AV3: Attendance | AW3: Avrg Atten | AX3: 1 | AY3: =AX3+1 -> 2 | AZ3: =AY3+1 -> 3 | BA3: =AZ3+1 -> 4 | BB3: =BA3+1 -> 5 | BC3: =BB3+1 -> 6 | BD3: =BC3+1 -> 7 | BE3: =BD3+1 -> 8 | BF3: =BE3+1 -> 9 | ... CB3: =CA3+1 -> 31 | CC3: Calls | CD3: Avrg Calls | JJ3: Legend | JK3: Mapping | JL3: 1 | JM3: =JL3+1 -> 2 | JN3: =JM3+1 -> 3 | JO3: =JN3+1 -> 4 | JP3: =JO3+1 -> 5 | JQ3: =JP3+1 -> 6 | JR3: =JQ3+1 -> 7 | JS3: =JR3+1 -> 8 | JT3: =JS3+1 -> 9 | ... KP3: =KO3+1 -> 31 | KQ3: 1 | KR3: =KQ3+1 -> 2 | KS3: =KR3+1 -> 3 | KT3: =KS3+1 -> 4 | KU3: =KT3+1 -> 5 | KV3: =KU3+1 -> 6 | KW3: =KV3+1 -> 7 | KX3: =KW3+1 -> 8 | KY3: =KX3+1 -> 9 | ... LU3: =LT3+1 -> 31
A4: MIO | B4: South | C4: Karachi-1 | D4: KHI01-PHR-MIO-01 | E4: 0310001 | F4: VACANT (PHR-KHI-01) | G4: VACANT | H4: RESIGNED | I4: FB Area, Liaquatabad, Nazimabad, Sohrab Goth, Gadap | J4: 1 | K4: 1 | L4: =IFERROR(IF(OR(AD4>0),1,0),0) -> 0 | M4: =IFERROR(IF(OR(AV4>0),1,0),0) -> 0 | N4: =IFERROR(IF(OR(BK4>0),1,0),0) -> 0 | O4: =IFERROR(IF(OR(CC4>0),1,0),0) -> 0 | P4: =IFERROR(IF(OR(AV4>0,CC4>0),1,0),0) -> 0 | Q4: =JL4 -> 0 | R4: =JM4 -> 0 | S4: =JN4 -> 0 | T4: =JO4 -> 0 | U4: =JP4 -> 0 | V4: =JQ4 -> 0 | W4: =JR4 -> 0 | X4: =JS4 -> 0 | ... AU4: =KP4 -> 0 | AV4: =SUM(Q4:AU4) -> 0 | AW4: =IFERROR(AV4/$CF$2/(J4-K4),0) -> 0 | AX4: =KQ4 -> 0 | AY4: =KR4 -> 0 | AZ4: =KS4 -> 0 | BA4: =KT4 -> 0 | BB4: =KU4 -> 0 | BC4: =KV4 -> 0 | BD4: =KW4 -> 0 | BE4: =KX4 -> 0 | ... CB4: =LU4 -> 0 | CC4: =SUM(AX4:CB4) -> 0 | CD4: =IFERROR(CC4/$CF$2/(J4-K4),0) -> 0 | JJ4: Formula | JK4: =D4 -> KHI01-PHR-MIO-01 | JL4: 0 | JM4: 0 | JN4: 0 | JO4: 0 | JP4: 0 | JQ4: 0 | JR4: 0 | JS4: 0 | JT4: 0 | JU4: 0 | JV4: 0 | JW4: 0 | JX4: 0 | JY4: 0 | KQ4: 0 | KR4: 0 | KS4: 0 | KT4: 0 | KU4: 0 | KV4: 0 | KW4: 0 | KX4: 0 | KY4: 0 | KZ4: 0 | LA4: 0 | LB4: 0 | LC4: 0 | LD4: 0
A5: MIO | B5: South | C5: Karachi-1 | D5: KHI01-PHR-MIO-02 | E5: 0310002 | F5: VACANT (PHR-KHI-02) | G5: E-02280 | H5: 45349 | I5: Baldia, Turbat, Orangi. | J5: 1 | K5: 1 | L5: =IFERROR(IF(OR(AD5>0),1,0),0) -> 0 | M5: =IFERROR(IF(OR(AV5>0),1,0),0) -> 0 | N5: =IFERROR(IF(OR(BK5>0),1,0),0) -> 0 | O5: =IFERROR(IF(OR(CC5>0),1,0),0) -> 0 | P5: =IFERROR(IF(OR(AV5>0,CC5>0),1,0),0) -> 0 | Q5: =JL5 -> 0 | R5: =JM5 -> 0 | S5: =JN5 -> 0 | T5: =JO5 -> 0 | U5: =JP5 -> 0 | V5: =JQ5 -> 0 | W5: =JR5 -> 0 | X5: =JS5 -> 0 | ... AU5: =KP5 -> 0 | AV5: =SUM(Q5:AU5) -> 0 | AW5: =IFERROR(AV5/$CF$2/(J5-K5),0) -> 0 | AX5: =KQ5 -> 0 | AY5: =KR5 -> 0 | AZ5: =KS5 -> 0 | BA5: =KT5 -> 0 | BB5: =KU5 -> 0 | BC5: =KV5 -> 0 | BD5: =KW5 -> 0 | BE5: =KX5 -> 0 | ... CB5: =LU5 -> 0 | CC5: =SUM(AX5:CB5) -> 0 | CD5: =IFERROR(CC5/$CF$2/(J5-K5),0) -> 0 | JJ5: Formula | JK5: =D5 -> KHI01-PHR-MIO-02 | JL5: 0 | JM5: 0 | JN5: 0 | JO5: 0 | JP5: 0 | JQ5: 0 | JR5: 0 | JS5: 0 | JT5: 0 | JU5: 0 | JV5: 0 | JW5: 0 | JX5: 0 | JY5: 0 | KQ5: 0 | KR5: 0 | KS5: 0 | KT5: 0 | KU5: 0 | KV5: 0 | KW5: 0 | KX5: 0 | KY5: 0 | KZ5: 0 | LA5: 0 | LB5: 0 | LC5: 0 | LD5: 0
A6: MIO | B6: South | C6: Karachi-1 | D6: KHI01-PHR-MIO-03 | E6: 0310003 | F6: MR.VACANT (PHR-KHI-03) | G6: VACANT | H6: RESIGNED | I6: Garden, Soldier Bazar, Lee Market, Kemari. | J6: 1 | K6: 1 | L6: =IFERROR(IF(OR(AD6>0),1,0),0) -> 0 | M6: =IFERROR(IF(OR(AV6>0),1,0),0) -> 0 | N6: =IFERROR(IF(OR(BK6>0),1,0),0) -> 0 | O6: =IFERROR(IF(OR(CC6>0),1,0),0) -> 0 | P6: =IFERROR(IF(OR(AV6>0,CC6>0),1,0),0) -> 0 | Q6: =JL6 -> 0 | R6: =JM6 -> 0 | S6: =JN6 -> 0 | T6: =JO6 -> 0 | U6: =JP6 -> 0 | V6: =JQ6 -> 0 | W6: =JR6 -> 0 | X6: =JS6 -> 0 | ... AU6: =KP6 -> 0 | AV6: =SUM(Q6:AU6) -> 0 | AW6: =IFERROR(AV6/$CF$2/(J6-K6),0) -> 0 | AX6: =KQ6 -> 0 | AY6: =KR6 -> 0 | AZ6: =KS6 -> 0 | BA6: =KT6 -> 0 | BB6: =KU6 -> 0 | BC6: =KV6 -> 0 | BD6: =KW6 -> 0 | BE6: =KX6 -> 0 | ... CB6: =LU6 -> 0 | CC6: =SUM(AX6:CB6) -> 0 | CD6: =IFERROR(CC6/$CF$2/(J6-K6),0) -> 0 | JJ6: Formula | JK6: =D6 -> KHI01-PHR-MIO-03 | JL6: 0 | JM6: 0 | JN6: 0 | JO6: 0 | JP6: 0 | JQ6: 0 | JR6: 0 | JS6: 0 | JT6: 0 | JU6: 0 | JV6: 0 | JW6: 0 | JX6: 0 | JY6: 0 | KQ6: 0 | KR6: 0 | KS6: 0 | KT6: 0 | KU6: 0 | KV6: 0 | KW6: 0 | KX6: 0 | KY6: 0 | KZ6: 0 | LA6: 0 | LB6: 0 | LC6: 0 | LD6: 0
A7: MIO | B7: South | C7: Karachi-1 | D7: KHI01-PHR-MIO-04 | E7: 9051701 | F7: VACANT (PHR-KHI-04) | G7: VACANT | H7: RESIGNED | I7: Gulshan, Jauhar, Society | J7: 1 | K7: 1 | L7: =IFERROR(IF(OR(AD7>0),1,0),0) -> 0 | M7: =IFERROR(IF(OR(AV7>0),1,0),0) -> 0 | N7: =IFERROR(IF(OR(BK7>0),1,0),0) -> 0 | O7: =IFERROR(IF(OR(CC7>0),1,0),0) -> 0 | P7: =IFERROR(IF(OR(AV7>0,CC7>0),1,0),0) -> 0 | Q7: =JL7 -> 0 | R7: =JM7 -> 0 | S7: =JN7 -> 0 | T7: =JO7 -> 0 | U7: =JP7 -> 0 | V7: =JQ7 -> 0 | W7: =JR7 -> 0 | X7: =JS7 -> 0 | ... AU7: =KP7 -> 0 | AV7: =SUM(Q7:AU7) -> 0 | AW7: =IFERROR(AV7/$CF$2/(J7-K7),0) -> 0 | AX7: =KQ7 -> 0 | AY7: =KR7 -> 0 | AZ7: =KS7 -> 0 | BA7: =KT7 -> 0 | BB7: =KU7 -> 0 | BC7: =KV7 -> 0 | BD7: =KW7 -> 0 | BE7: =KX7 -> 0 | ... CB7: =LU7 -> 0 | CC7: =SUM(AX7:CB7) -> 0 | CD7: =IFERROR(CC7/$CF$2/(J7-K7),0) -> 0 | JJ7: Formula | JK7: =D7 -> KHI01-PHR-MIO-04 | JL7: 0 | JM7: 0 | JN7: 0 | JO7: 0 | JP7: 0 | JQ7: 0 | JR7: 0 | JS7: 0 | JT7: 0 | JU7: 0 | JV7: 0 | JW7: 0 | JX7: 0 | JY7: 0 | KQ7: 0 | KR7: 0 | KS7: 0 | KT7: 0 | KU7: 0 | KV7: 0 | KW7: 0 | KX7: 0 | KY7: 0 | KZ7: 0 | LA7: 0 | LB7: 0 | LC7: 0 | LD7: 0
A8: MIO | B8: South | C8: Karachi-2 | D8: KHI01-PHR-PS-01 | E8: 0320005 | F8: MS. TASLEEM KHAN (PS-KHI-01) | G8: E-02558 | H8: 45721 | I8: North Nazimabad, North Khi, New Khi, Tesar Town, Maymar | J8: 1 | K8: 0 | L8: =IFERROR(IF(OR(AD8>0),1,0),0) -> 0 | M8: =IFERROR(IF(OR(AV8>0),1,0),0) -> 1 | N8: =IFERROR(IF(OR(BK8>0),1,0),0) -> 0 | O8: =IFERROR(IF(OR(CC8>0),1,0),0) -> 1 | P8: =IFERROR(IF(OR(AV8>0,CC8>0),1,0),0) -> 1 | Q8: =JL8 -> 1 | R8: =JM8 -> 1 | S8: =JN8 -> 1 | T8: =JO8 -> 0 | U8: =JP8 -> 1 | V8: =JQ8 -> 1 | W8: =JR8 -> 1 | X8: =JS8 -> 1 | ... AU8: =KP8 -> 0 | AV8: =SUM(Q8:AU8) -> 10 | AW8: =IFERROR(AV8/$CF$2/(J8-K8),0) -> 0.76923077 | AX8: =KQ8 -> 10 | AY8: =KR8 -> 9 | AZ8: =KS8 -> 6 | BA8: =KT8 -> 0 | BB8: =KU8 -> 5 | BC8: =KV8 -> 7 | BD8: =KW8 -> 12 | BE8: =KX8 -> 0 | ... CB8: =LU8 -> 0 | CC8: =SUM(AX8:CB8) -> 58 | CD8: =IFERROR(CC8/$CF$2/(J8-K8),0) -> 4.4615385 | JJ8: Formula | JK8: =D8 -> KHI01-PHR-PS-01 | JL8: 1 | JM8: 1 | JN8: 1 | JO8: 0 | JP8: 1 | JQ8: 1 | JR8: 1 | JS8: 1 | JT8: 1 | JU8: 1 | JV8: 0 | JW8: 1 | JX8: 0 | JY8: 0 | KQ8: 10 | KR8: 9 | KS8: 6 | KT8: 0 | KU8: 5 | KV8: 7 | KW8: 12 | KX8: 0 | KY8: 9 | KZ8: 0 | LA8: 0 | LB8: 0 | LC8: 0 | LD8: 0
A9: MIO Unmap | B9: South | C9: Karachi-1 | D9: KHI01-PHR-MIO-00 | E9: 0310007 | F9: KHI01 - PHR UNMAPPED | G9: UN-DEFINED | H9: UN-DEFINED | I9: Karachi 1 | J9: 0 | K9: 0 | L9: =IFERROR(IF(OR(AD9>0),1,0),0) -> 0 | M9: =IFERROR(IF(OR(AV9>0),1,0),0) -> 0 | N9: =IFERROR(IF(OR(BK9>0),1,0),0) -> 0 | O9: =IFERROR(IF(OR(CC9>0),1,0),0) -> 0 | P9: =IFERROR(IF(OR(AV9>0,CC9>0),1,0),0) -> 0 | Q9: =JL9 -> 0 | R9: =JM9 -> 0 | S9: =JN9 -> 0 | T9: =JO9 -> 0 | U9: =JP9 -> 0 | V9: =JQ9 -> 0 | W9: =JR9 -> 0 | X9: =JS9 -> 0 | ... AU9: =KP9 -> 0 | AV9: =SUM(Q9:AU9) -> 0 | AW9: =IFERROR(AV9/$CF$2/(J9-K9),0) -> 0 | AX9: =KQ9 -> 0 | AY9: =KR9 -> 0 | AZ9: =KS9 -> 0 | BA9: =KT9 -> 0 | BB9: =KU9 -> 0 | BC9: =KV9 -> 0 | BD9: =KW9 -> 0 | BE9: =KX9 -> 0 | ... CB9: =LU9 -> 0 | CC9: =SUM(AX9:CB9) -> 0 | CD9: =IFERROR(CC9/$CF$2/(J9-K9),0) -> 0 | JJ9: Formula | JK9: =D9 -> KHI01-PHR-MIO-00 | JL9: 0 | JM9: 0 | JN9: 0 | JO9: 0 | JP9: 0 | JQ9: 0 | JR9: 0 | JS9: 0 | JT9: 0 | JU9: 0 | JV9: 0 | JW9: 0 | JX9: 0 | JY9: 0 | KQ9: 0 | KR9: 0 | KS9: 0 | KT9: 0 | KU9: 0 | KV9: 0 | KW9: 0 | KX9: 0 | KY9: 0 | KZ9: 0 | LA9: 0 | LB9: 0 | LC9: 0 | LD9: 0
A10: ASM | B10: South | C10: Karachi-1 | D10: KHI01-PHR-ASM-01 | E10: 03100 | F10: VACANT ASM KHI-01 | G10: VACANT | H10: RESIGNED | I10: Karachi 1 | J10: 5 | K10: =SUM(K4:K9) -> 4 | L10: =SUM(L4:L9) -> 0 | M10: =SUM(M4:M9) -> 1 | N10: =SUM(N4:N9) -> 0 | O10: =SUM(O4:O9) -> 1 | P10: =SUM(P4:P9) -> 1 | Q10: =SUM(Q4:Q9) -> 1 | R10: =SUM(R4:R9) -> 1 | ... AU10: =SUM(AU4:AU9) -> 0 | AV10: =SUM(Q10:AU10) -> 10 | AW10: =IFERROR(AV10/$CF$2/(J10-K10),0) -> 0.76923077 | AX10: =SUM(AX4:AX9) -> 10 | AY10: =SUM(AY4:AY9) -> 9 | AZ10: =SUM(AZ4:AZ9) -> 6 | BA10: =SUM(BA4:BA9) -> 0 | BB10: =SUM(BB4:BB9) -> 5 | BC10: =SUM(BC4:BC9) -> 7 | BD10: =SUM(BD4:BD9) -> 12 | BE10: =SUM(BE4:BE9) -> 0 | ... CB10: =SUM(CB4:CB9) -> 0 | CC10: =SUM(AX10:CB10) -> 58 | CD10: =IFERROR(CC10/$CF$2/(J10-K10),0) -> 4.4615385 | JJ10: Formula | JK10: =D10 -> KHI01-PHR-ASM-01 | JL10: 0 | JM10: 0 | JN10: 0 | JO10: 0 | JP10: 0 | JQ10: 0 | JR10: 0 | JS10: 0 | JT10: 0 | JU10: 0 | JV10: 0 | JW10: 0 | JX10: 0 | JY10: 0 | KQ10: 0 | KR10: 0 | KS10: 0 | KT10: 0 | KU10: 0 | KV10: 0 | KW10: 0 | KX10: 0 | KY10: 0 | KZ10: 0 | LA10: 0 | LB10: 0 | LC10: 0 | LD10: 0
A11: MIO | B11: South | C11: Karachi-2 | D11: KHI02-PHR-MIO-01 | E11: 0310004 | F11: MR. NOMAN ANSARI (PHR-KHI-05) | G11: E-02511 | H11: 45627 | I11: Defence, Clifton, Delhi Colony, Neelum Colony, Shree Jinah Colony, Mehmoodabad | J11: 1 | K11: 0 | L11: =IFERROR(IF(OR(AD11>0),1,0),0) -> 1 | M11: =IFERROR(IF(OR(AV11>0),1,0),0) -> 1 | N11: =IFERROR(IF(OR(BK11>0),1,0),0) -> 0 | O11: =IFERROR(IF(OR(CC11>0),1,0),0) -> 1 | P11: =IFERROR(IF(OR(AV11>0,CC11>0),1,0),0) -> 1 | Q11: =JL11 -> 1 | R11: =JM11 -> 1 | S11: =JN11 -> 1 | T11: =JO11 -> 0 | U11: =JP11 -> 1 | V11: =JQ11 -> 1 | W11: =JR11 -> 1 | X11: =JS11 -> 1 | ... AU11: =KP11 -> 0 | AV11: =SUM(Q11:AU11) -> 12 | AW11: =IFERROR(AV11/$CF$2/(J11-K11),0) -> 0.92307692 | AX11: =KQ11 -> 0 | AY11: =KR11 -> 11 | AZ11: =KS11 -> 1 | BA11: =KT11 -> 0 | BB11: =KU11 -> 5 | BC11: =KV11 -> 11 | BD11: =KW11 -> 10 | BE11: =KX11 -> 11 | ... CB11: =LU11 -> 0 | CC11: =SUM(AX11:CB11) -> 80 | CD11: =IFERROR(CC11/$CF$2/(J11-K11),0) -> 6.1538462 | JJ11: Formula | JK11: =D11 -> KHI02-PHR-MIO-01 | JL11: 1 | JM11: 1 | JN11: 1 | JO11: 0 | JP11: 1 | JQ11: 1 | JR11: 1 | JS11: 1 | JT11: 1 | JU11: 1 | JV11: 0 | JW11: 1 | JX11: 1 | JY11: 1 | KQ11: 0 | KR11: 11 | KS11: 1 | KT11: 0 | KU11: 5 | KV11: 11 | KW11: 10 | KX11: 11 | KY11: 11 | KZ11: 7 | LA11: 0 | LB11: 0 | LC11: 13 | LD11: 0
A12: MIO | B12: South | C12: Karachi-2 | D12: KHI02-PHR-MIO-02 | E12: 0310005 | F12: VACANT (PHR-KHI-06) | G12: VACANT | H12: RESIGNED | I12: Malir, Shah Faisal Colony, Saudabad. | J12: 1 | K12: 1 | L12: =IFERROR(IF(OR(AD12>0),1,0),0) -> 0 | M12: =IFERROR(IF(OR(AV12>0),1,0),0) -> 0 | N12: =IFERROR(IF(OR(BK12>0),1,0),0) -> 0 | O12: =IFERROR(IF(OR(CC12>0),1,0),0) -> 0 | P12: =IFERROR(IF(OR(AV12>0,CC12>0),1,0),0) -> 0 | Q12: =JL12 -> 0 | R12: =JM12 -> 0 | S12: =JN12 -> 0 | T12: =JO12 -> 0 | U12: =JP12 -> 0 | V12: =JQ12 -> 0 | W12: =JR12 -> 0 | X12: =JS12 -> 0 | ... AU12: =KP12 -> 0 | AV12: =SUM(Q12:AU12) -> 0 | AW12: =IFERROR(AV12/$CF$2/(J12-K12),0) -> 0 | AX12: =KQ12 -> 0 | AY12: =KR12 -> 0 | AZ12: =KS12 -> 0 | BA12: =KT12 -> 0 | BB12: =KU12 -> 0 | BC12: =KV12 -> 0 | BD12: =KW12 -> 0 | BE12: =KX12 -> 0 | ... CB12: =LU12 -> 0 | CC12: =SUM(AX12:CB12) -> 0 | CD12: =IFERROR(CC12/$CF$2/(J12-K12),0) -> 0 | JJ12: Formula | JK12: =D12 -> KHI02-PHR-MIO-02 | JL12: 0 | JM12: 0 | JN12: 0 | JO12: 0 | JP12: 0 | JQ12: 0 | JR12: 0 | JS12: 0 | JT12: 0 | JU12: 0 | JV12: 0 | JW12: 0 | JX12: 0 | JY12: 0 | KQ12: 0 | KR12: 0 | KS12: 0 | KT12: 0 | KU12: 0 | KV12: 0 | KW12: 0 | KX12: 0 | KY12: 0 | KZ12: 0 | LA12: 0 | LB12: 0 | LC12: 0 | LD12: 0
A13: MIO | B13: South | C13: Karachi-2 | D13: KHI02-PHR-MIO-03 | E13: 9051702 | F13: MS. MEHWISH KANWAL (PHR-KHI-07) | G13: E-02559 | H13: 45721 | I13: Landhi, Korangi | J13: 1 | K13: 0 | L13: =IFERROR(IF(OR(AD13>0),1,0),0) -> 1 | M13: =IFERROR(IF(OR(AV13>0),1,0),0) -> 1 | N13: =IFERROR(IF(OR(BK13>0),1,0),0) -> 1 | O13: =IFERROR(IF(OR(CC13>0),1,0),0) -> 1 | P13: =IFERROR(IF(OR(AV13>0,CC13>0),1,0),0) -> 1 | Q13: =JL13 -> 1 | R13: =JM13 -> 1 | S13: =JN13 -> 1 | T13: =JO13 -> 0 | U13: =JP13 -> 1 | V13: =JQ13 -> 1 | W13: =JR13 -> 1 | X13: =JS13 -> 1 | ... AU13: =KP13 -> 0 | AV13: =SUM(Q13:AU13) -> 12 | AW13: =IFERROR(AV13/$CF$2/(J13-K13),0) -> 0.92307692 | AX13: =KQ13 -> 11 | AY13: =KR13 -> 11 | AZ13: =KS13 -> 12 | BA13: =KT13 -> 0 | BB13: =KU13 -> 10 | BC13: =KV13 -> 13 | BD13: =KW13 -> 12 | BE13: =KX13 -> 9 | ... CB13: =LU13 -> 0 | CC13: =SUM(AX13:CB13) -> 119 | CD13: =IFERROR(CC13/$CF$2/(J13-K13),0) -> 9.1538462 | JJ13: Formula | JK13: =D13 -> KHI02-PHR-MIO-03 | JL13: 1 | JM13: 1 | JN13: 1 | JO13: 0 | JP13: 1 | JQ13: 1 | JR13: 1 | JS13: 1 | JT13: 1 | JU13: 1 | JV13: 0 | JW13: 1 | JX13: 1 | JY13: 1 | KQ13: 11 | KR13: 11 | KS13: 12 | KT13: 0 | KU13: 10 | KV13: 13 | KW13: 12 | KX13: 9 | KY13: 10 | KZ13: 8 | LA13: 0 | LB13: 13 | LC13: 9 | LD13: 1
A14: MIO | B14: South | C14: Karachi-2 | D14: KHI02-PHR-MIO-04 | E14: 0311208 | F14: MS. SAIMA PARVEEN (PHR-KHI-08) | G14: E-02548 | H14: 45798 | I14: Thatta | J14: 1 | K14: 0 | L14: =IFERROR(IF(OR(AD14>0),1,0),0) -> 0 | M14: =IFERROR(IF(OR(AV14>0),1,0),0) -> 1 | N14: =IFERROR(IF(OR(BK14>0),1,0),0) -> 0 | O14: =IFERROR(IF(OR(CC14>0),1,0),0) -> 1 | P14: =IFERROR(IF(OR(AV14>0,CC14>0),1,0),0) -> 1 | Q14: =JL14 -> 1 | R14: =JM14 -> 1 | S14: =JN14 -> 1 | T14: =JO14 -> 0 | U14: =JP14 -> 1 | V14: =JQ14 -> 0 | W14: =JR14 -> 1 | X14: =JS14 -> 0 | ... AU14: =KP14 -> 0 | AV14: =SUM(Q14:AU14) -> 8 | AW14: =IFERROR(AV14/$CF$2/(J14-K14),0) -> 0.61538462 | AX14: =KQ14 -> 8 | AY14: =KR14 -> 3 | AZ14: =KS14 -> 0 | BA14: =KT14 -> 0 | BB14: =KU14 -> 8 | BC14: =KV14 -> 8 | BD14: =KW14 -> 11 | BE14: =KX14 -> 0 | ... CB14: =LU14 -> 0 | CC14: =SUM(AX14:CB14) -> 64 | CD14: =IFERROR(CC14/$CF$2/(J14-K14),0) -> 4.9230769 | JJ14: Formula | JK14: =D14 -> KHI02-PHR-MIO-04 | JL14: 1 | JM14: 1 | JN14: 1 | JO14: 0 | JP14: 1 | JQ14: 0 | JR14: 1 | JS14: 0 | JT14: 0 | JU14: 1 | JV14: 0 | JW14: 1 | JX14: 1 | JY14: 0 | KQ14: 8 | KR14: 3 | KS14: 0 | KT14: 0 | KU14: 8 | KV14: 8 | KW14: 11 | KX14: 0 | KY14: 0 | KZ14: 6 | LA14: 0 | LB14: 10 | LC14: 10 | LD14: 0
A15: MIO Unmap | B15: South | C15: Karachi-2 | D15: KHI02-PHR-MIO-00 | E15: 0320003 | F15: KHI02 - PHR UNMAPPED | G15: UN-DEFINED | H15: UN-DEFINED | I15: Karachi 2 | J15: 0 | K15: 0 | L15: =IFERROR(IF(OR(AD15>0),1,0),0) -> 0 | M15: =IFERROR(IF(OR(AV15>0),1,0),0) -> 0 | N15: =IFERROR(IF(OR(BK15>0),1,0),0) -> 0 | O15: =IFERROR(IF(OR(CC15>0),1,0),0) -> 0 | P15: =IFERROR(IF(OR(AV15>0,CC15>0),1,0),0) -> 0 | Q15: =JL15 -> 0 | R15: =JM15 -> 0 | S15: =JN15 -> 0 | T15: =JO15 -> 0 | U15: =JP15 -> 0 | V15: =JQ15 -> 0 | W15: =JR15 -> 0 | X15: =JS15 -> 0 | ... AU15: =KP15 -> 0 | AV15: =SUM(Q15:AU15) -> 0 | AW15: =IFERROR(AV15/$CF$2/(J15-K15),0) -> 0 | AX15: =KQ15 -> 0 | AY15: =KR15 -> 0 | AZ15: =KS15 -> 0 | BA15: =KT15 -> 0 | BB15: =KU15 -> 0 | BC15: =KV15 -> 0 | BD15: =KW15 -> 0 | BE15: =KX15 -> 0 | ... CB15: =LU15 -> 0 | CC15: =SUM(AX15:CB15) -> 0 | CD15: =IFERROR(CC15/$CF$2/(J15-K15),0) -> 0 | JJ15: Formula | JK15: =D15 -> KHI02-PHR-MIO-00 | JL15: 0 | JM15: 0 | JN15: 0 | JO15: 0 | JP15: 0 | JQ15: 0 | JR15: 0 | JS15: 0 | JT15: 0 | JU15: 0 | JV15: 0 | JW15: 0 | JX15: 0 | JY15: 0 | KQ15: 0 | KR15: 0 | KS15: 0 | KT15: 0 | KU15: 0 | KV15: 0 | KW15: 0 | KX15: 0 | KY15: 0 | KZ15: 0 | LA15: 0 | LB15: 0 | LC15: 0 | LD15: 0
A16: ASM | B16: South | C16: Karachi-2 | D16: KHI02-PHR-ASM-01 | E16: 03200 | F16: M. ALI ANIS | G16: E-03125 | H16: 46108 | I16: Karachi 2 | J16: 4 | K16: =SUM(K11:K15) -> 1 | L16: =SUM(L11:L15) -> 2 | M16: =SUM(M11:M15) -> 3 | N16: =SUM(N11:N15) -> 1 | O16: =SUM(O11:O15) -> 3 | P16: =SUM(P11:P15) -> 3 | Q16: =SUM(Q11:Q15) -> 3 | R16: =SUM(R11:R15) -> 3 | ... AU16: =SUM(AU11:AU15) -> 0 | AV16: =SUM(Q16:AU16) -> 32 | AW16: =IFERROR(AV16/$CF$2/(J16-K16),0) -> 0.82051282 | AX16: =SUM(AX11:AX15) -> 19 | AY16: =SUM(AY11:AY15) -> 25 | AZ16: =SUM(AZ11:AZ15) -> 13 | BA16: =SUM(BA11:BA15) -> 0 | BB16: =SUM(BB11:BB15) -> 23 | BC16: =SUM(BC11:BC15) -> 32 | BD16: =SUM(BD11:BD15) -> 33 | BE16: =SUM(BE11:BE15) -> 20 | ... CB16: =SUM(CB11:CB15) -> 0 | CC16: =SUM(AX16:CB16) -> 263 | CD16: =IFERROR(CC16/$CF$2/(J16-K16),0) -> 6.7435897 | JJ16: Formula | JK16: =D16 -> KHI02-PHR-ASM-01 | JL16: 0 | JM16: 0 | JN16: 0 | JO16: 0 | JP16: 0 | JQ16: 0 | JR16: 0 | JS16: 0 | JT16: 0 | JU16: 0 | JV16: 0 | JW16: 0 | JX16: 0 | JY16: 0 | KQ16: 0 | KR16: 0 | KS16: 0 | KT16: 0 | KU16: 0 | KV16: 0 | KW16: 0 | KX16: 0 | KY16: 0 | KZ16: 0 | LA16: 0 | LB16: 0 | LC16: 0 | LD16: 0
A17: MIO | B17: South | C17: Hyderabad | D17: HYD01-PHR-MIO-01 | E17: 0311002 | F17: IMRAN RAUF (PHR-HYD-01) | G17: E-01751 | H17: 45171 | I17: LMCH, Saddar, Sanghar | J17: 1 | K17: 0 | L17: =IFERROR(IF(OR(AD17>0),1,0),0) -> 1 | M17: =IFERROR(IF(OR(AV17>0),1,0),0) -> 1 | N17: =IFERROR(IF(OR(BK17>0),1,0),0) -> 0 | O17: =IFERROR(IF(OR(CC17>0),1,0),0) -> 1 | P17: =IFERROR(IF(OR(AV17>0,CC17>0),1,0),0) -> 1 | Q17: =JL17 -> 1 | R17: =JM17 -> 1 | S17: =JN17 -> 1 | T17: =JO17 -> 0 | U17: =JP17 -> 1 | V17: =JQ17 -> 1 | W17: =JR17 -> 1 | X17: =JS17 -> 1 | ... AU17: =KP17 -> 0 | AV17: =SUM(Q17:AU17) -> 12 | AW17: =IFERROR(AV17/$CF$2/(J17-K17),0) -> 0.92307692 | AX17: =KQ17 -> 12 | AY17: =KR17 -> 15 | AZ17: =KS17 -> 16 | BA17: =KT17 -> 0 | BB17: =KU17 -> 16 | BC17: =KV17 -> 15 | BD17: =KW17 -> 14 | BE17: =KX17 -> 14 | ... CB17: =LU17 -> 0 | CC17: =SUM(AX17:CB17) -> 140 | CD17: =IFERROR(CC17/$CF$2/(J17-K17),0) -> 10.769231 | JJ17: Formula | JK17: =D17 -> HYD01-PHR-MIO-01 | JL17: 1 | JM17: 1 | JN17: 1 | JO17: 0 | JP17: 1 | JQ17: 1 | JR17: 1 | JS17: 1 | JT17: 1 | JU17: 1 | JV17: 0 | JW17: 1 | JX17: 1 | JY17: 1 | KQ17: 12 | KR17: 15 | KS17: 16 | KT17: 0 | KU17: 16 | KV17: 15 | KW17: 14 | KX17: 14 | KY17: 13 | KZ17: 11 | LA17: 0 | LB17: 14 | LC17: 0 | LD17: 0
A18: MIO | B18: South | C18: Hyderabad | D18: HYD01-PHR-MIO-02 | E18: 0311202 | F18: SAJIDA PARVEEN (PHR-HYD-02) | G18: E-02589 | H18: 45799 | I18: Nawabshah, Daur, Hospital Road | J18: 1 | K18: 0 | L18: =IFERROR(IF(OR(AD18>0),1,0),0) -> 1 | M18: =IFERROR(IF(OR(AV18>0),1,0),0) -> 1 | N18: =IFERROR(IF(OR(BK18>0),1,0),0) -> 0 | O18: =IFERROR(IF(OR(CC18>0),1,0),0) -> 1 | P18: =IFERROR(IF(OR(AV18>0,CC18>0),1,0),0) -> 1 | Q18: =JL18 -> 1 | R18: =JM18 -> 1 | S18: =JN18 -> 0 | T18: =JO18 -> 0 | U18: =JP18 -> 1 | V18: =JQ18 -> 1 | W18: =JR18 -> 1 | X18: =JS18 -> 1 | ... AU18: =KP18 -> 0 | AV18: =SUM(Q18:AU18) -> 11 | AW18: =IFERROR(AV18/$CF$2/(J18-K18),0) -> 0.84615385 | AX18: =KQ18 -> 13 | AY18: =KR18 -> 15 | AZ18: =KS18 -> 0 | BA18: =KT18 -> 0 | BB18: =KU18 -> 14 | BC18: =KV18 -> 16 | BD18: =KW18 -> 12 | BE18: =KX18 -> 14 | ... CB18: =LU18 -> 0 | CC18: =SUM(AX18:CB18) -> 131 | CD18: =IFERROR(CC18/$CF$2/(J18-K18),0) -> 10.076923 | JJ18: Formula | JK18: =D18 -> HYD01-PHR-MIO-02 | JL18: 1 | JM18: 1 | JN18: 0 | JO18: 0 | JP18: 1 | JQ18: 1 | JR18: 1 | JS18: 1 | JT18: 1 | JU18: 1 | JV18: 0 | JW18: 1 | JX18: 1 | JY18: 1 | KQ18: 13 | KR18: 15 | KS18: 0 | KT18: 0 | KU18: 14 | KV18: 16 | KW18: 12 | KX18: 14 | KY18: 16 | KZ18: 2 | LA18: 0 | LB18: 12 | LC18: 17 | LD18: 0
A19: MIO | B19: South | C19: Hyderabad | D19: HYD01-PHR-MIO-03 | E19: 0311005 | F19: M. RAHEEL (PHR-HYD-03) | G19: VACANT | H19: RESIGNED | I19: Badin/Tando M. Khan/Jamshoro/Qasimabad | J19: 1 | K19: 0 | L19: =IFERROR(IF(OR(AD19>0),1,0),0) -> 1 | M19: =IFERROR(IF(OR(AV19>0),1,0),0) -> 1 | N19: =IFERROR(IF(OR(BK19>0),1,0),0) -> 1 | O19: =IFERROR(IF(OR(CC19>0),1,0),0) -> 1 | P19: =IFERROR(IF(OR(AV19>0,CC19>0),1,0),0) -> 1 | Q19: =JL19 -> 1 | R19: =JM19 -> 1 | S19: =JN19 -> 1 | T19: =JO19 -> 0 | U19: =JP19 -> 1 | V19: =JQ19 -> 1 | W19: =JR19 -> 1 | X19: =JS19 -> 1 | ... AU19: =KP19 -> 0 | AV19: =SUM(Q19:AU19) -> 12 | AW19: =IFERROR(AV19/$CF$2/(J19-K19),0) -> 0.92307692 | AX19: =KQ19 -> 0 | AY19: =KR19 -> 10 | AZ19: =KS19 -> 4 | BA19: =KT19 -> 0 | BB19: =KU19 -> 14 | BC19: =KV19 -> 7 | BD19: =KW19 -> 9 | BE19: =KX19 -> 7 | ... CB19: =LU19 -> 0 | CC19: =SUM(AX19:CB19) -> 82 | CD19: =IFERROR(CC19/$CF$2/(J19-K19),0) -> 6.3076923 | JJ19: Formula | JK19: =D19 -> HYD01-PHR-MIO-03 | JL19: 1 | JM19: 1 | JN19: 1 | JO19: 0 | JP19: 1 | JQ19: 1 | JR19: 1 | JS19: 1 | JT19: 1 | JU19: 1 | JV19: 0 | JW19: 1 | JX19: 1 | JY19: 1 | KQ19: 0 | KR19: 10 | KS19: 4 | KT19: 0 | KU19: 14 | KV19: 7 | KW19: 9 | KX19: 7 | KY19: 10 | KZ19: 3 | LA19: 0 | LB19: 9 | LC19: 6 | LD19: 3
A20: MIO | B20: South | C20: Hyderabad | D20: HYD01-PHR-MIO-04 | E20: 0311003 | F20: M. AAMIR (PHR-HYD-04) | G20: E-02492 | H20: 45575 | I20: Tando Allahyar, Hyderabad, Phulleli , Paretabad | J20: 1 | K20: 0 | L20: =IFERROR(IF(OR(AD20>0),1,0),0) -> 1 | M20: =IFERROR(IF(OR(AV20>0),1,0),0) -> 1 | N20: =IFERROR(IF(OR(BK20>0),1,0),0) -> 0 | O20: =IFERROR(IF(OR(CC20>0),1,0),0) -> 1 | P20: =IFERROR(IF(OR(AV20>0,CC20>0),1,0),0) -> 1 | Q20: =JL20 -> 1 | R20: =JM20 -> 1 | S20: =JN20 -> 1 | T20: =JO20 -> 0 | U20: =JP20 -> 1 | V20: =JQ20 -> 1 | W20: =JR20 -> 1 | X20: =JS20 -> 1 | ... AU20: =KP20 -> 0 | AV20: =SUM(Q20:AU20) -> 12 | AW20: =IFERROR(AV20/$CF$2/(J20-K20),0) -> 0.92307692 | AX20: =KQ20 -> 6 | AY20: =KR20 -> 5 | AZ20: =KS20 -> 2 | BA20: =KT20 -> 0 | BB20: =KU20 -> 2 | BC20: =KV20 -> 4 | BD20: =KW20 -> 5 | BE20: =KX20 -> 5 | ... CB20: =LU20 -> 0 | CC20: =SUM(AX20:CB20) -> 43 | CD20: =IFERROR(CC20/$CF$2/(J20-K20),0) -> 3.3076923 | JJ20: Formula | JK20: =D20 -> HYD01-PHR-MIO-04 | JL20: 1 | JM20: 1 | JN20: 1 | JO20: 0 | JP20: 1 | JQ20: 1 | JR20: 1 | JS20: 1 | JT20: 1 | JU20: 1 | JV20: 0 | JW20: 1 | JX20: 1 | JY20: 1 | KQ20: 6 | KR20: 5 | KS20: 2 | KT20: 0 | KU20: 2 | KV20: 4 | KW20: 5 | KX20: 5 | KY20: 4 | KZ20: 2 | LA20: 0 | LB20: 3 | LC20: 5 | LD20: 0
A21: MIO | B21: South | C21: Hyderabad | D21: HYD01-PHR-MIO-05 | E21: 0311004 | F21: IMTIAZ ALI (PHR-HYD-05) | G21: E-02494 | H21: 45173 | I21: Mirpukhas, Umerkot, Khipro | J21: 1 | K21: 0 | L21: =IFERROR(IF(OR(AD21>0),1,0),0) -> 1 | M21: =IFERROR(IF(OR(AV21>0),1,0),0) -> 1 | N21: =IFERROR(IF(OR(BK21>0),1,0),0) -> 0 | O21: =IFERROR(IF(OR(CC21>0),1,0),0) -> 1 | P21: =IFERROR(IF(OR(AV21>0,CC21>0),1,0),0) -> 1 | Q21: =JL21 -> 1 | R21: =JM21 -> 1 | S21: =JN21 -> 1 | T21: =JO21 -> 0 | U21: =JP21 -> 1 | V21: =JQ21 -> 1 | W21: =JR21 -> 1 | X21: =JS21 -> 1 | ... AU21: =KP21 -> 0 | AV21: =SUM(Q21:AU21) -> 12 | AW21: =IFERROR(AV21/$CF$2/(J21-K21),0) -> 0.92307692 | AX21: =KQ21 -> 4 | AY21: =KR21 -> 12 | AZ21: =KS21 -> 9 | BA21: =KT21 -> 0 | BB21: =KU21 -> 5 | BC21: =KV21 -> 14 | BD21: =KW21 -> 5 | BE21: =KX21 -> 4 | ... CB21: =LU21 -> 0 | CC21: =SUM(AX21:CB21) -> 76 | CD21: =IFERROR(CC21/$CF$2/(J21-K21),0) -> 5.8461538 | JJ21: Formula | JK21: =D21 -> HYD01-PHR-MIO-05 | JL21: 1 | JM21: 1 | JN21: 1 | JO21: 0 | JP21: 1 | JQ21: 1 | JR21: 1 | JS21: 1 | JT21: 1 | JU21: 1 | JV21: 0 | JW21: 1 | JX21: 1 | JY21: 1 | KQ21: 4 | KR21: 12 | KS21: 9 | KT21: 0 | KU21: 5 | KV21: 14 | KW21: 5 | KX21: 4 | KY21: 11 | KZ21: 6 | LA21: 0 | LB21: 0 | LC21: 6 | LD21: 0
A22: MIO | B22: South | C22: Hyderabad | D22: HYD01-PHR-MIO-06 | E22: 0311006 | F22: VACANT (PHR-HYD-06) | G22: E-03008 | H22: 46066 | I22: Nawab Shah, Qazi Ahmed, Sakrand, Morro | J22: 1 | K22: 1 | L22: =IFERROR(IF(OR(AD22>0),1,0),0) -> 0 | M22: =IFERROR(IF(OR(AV22>0),1,0),0) -> 0 | N22: =IFERROR(IF(OR(BK22>0),1,0),0) -> 0 | O22: =IFERROR(IF(OR(CC22>0),1,0),0) -> 0 | P22: =IFERROR(IF(OR(AV22>0,CC22>0),1,0),0) -> 0 | Q22: =JL22 -> 0 | R22: =JM22 -> 0 | S22: =JN22 -> 0 | T22: =JO22 -> 0 | U22: =JP22 -> 0 | V22: =JQ22 -> 0 | W22: =JR22 -> 0 | X22: =JS22 -> 0 | ... AU22: =KP22 -> 0 | AV22: =SUM(Q22:AU22) -> 0 | AW22: =IFERROR(AV22/$CF$2/(J22-K22),0) -> 0 | AX22: =KQ22 -> 0 | AY22: =KR22 -> 0 | AZ22: =KS22 -> 0 | BA22: =KT22 -> 0 | BB22: =KU22 -> 0 | BC22: =KV22 -> 0 | BD22: =KW22 -> 0 | BE22: =KX22 -> 0 | ... CB22: =LU22 -> 0 | CC22: =SUM(AX22:CB22) -> 0 | CD22: =IFERROR(CC22/$CF$2/(J22-K22),0) -> 0 | JJ22: Formula | JK22: =D22 -> HYD01-PHR-MIO-06 | JL22: 0 | JM22: 0 | JN22: 0 | JO22: 0 | JP22: 0 | JQ22: 0 | JR22: 0 | JS22: 0 | JT22: 0 | JU22: 0 | JV22: 0 | JW22: 0 | JX22: 0 | JY22: 0 | KQ22: 0 | KR22: 0 | KS22: 0 | KT22: 0 | KU22: 0 | KV22: 0 | KW22: 0 | KX22: 0 | KY22: 0 | KZ22: 0 | LA22: 0 | LB22: 0 | LC22: 0 | LD22: 0
A23: MIO Unmap | B23: South | C23: Hyderabad | D23: HYD01-PHR-MIO-00 | E23: 0311001 | F23: HYD01 - PHR UNMAPPED | G23: UN-DEFINED | H23: UN-DEFINED | I23: Hyderabad | J23: 0 | K23: 0 | L23: =IFERROR(IF(OR(AD23>0),1,0),0) -> 0 | M23: =IFERROR(IF(OR(AV23>0),1,0),0) -> 0 | N23: =IFERROR(IF(OR(BK23>0),1,0),0) -> 0 | O23: =IFERROR(IF(OR(CC23>0),1,0),0) -> 0 | P23: =IFERROR(IF(OR(AV23>0,CC23>0),1,0),0) -> 0 | Q23: =JL23 -> 0 | R23: =JM23 -> 0 | S23: =JN23 -> 0 | T23: =JO23 -> 0 | U23: =JP23 -> 0 | V23: =JQ23 -> 0 | W23: =JR23 -> 0 | X23: =JS23 -> 0 | ... AU23: =KP23 -> 0 | AV23: =SUM(Q23:AU23) -> 0 | AW23: =IFERROR(AV23/$CF$2/(J23-K23),0) -> 0 | AX23: =KQ23 -> 0 | AY23: =KR23 -> 0 | AZ23: =KS23 -> 0 | BA23: =KT23 -> 0 | BB23: =KU23 -> 0 | BC23: =KV23 -> 0 | BD23: =KW23 -> 0 | BE23: =KX23 -> 0 | ... CB23: =LU23 -> 0 | CC23: =SUM(AX23:CB23) -> 0 | CD23: =IFERROR(CC23/$CF$2/(J23-K23),0) -> 0 | JJ23: Formula | JK23: =D23 -> HYD01-PHR-MIO-00 | JL23: 0 | JM23: 0 | JN23: 0 | JO23: 0 | JP23: 0 | JQ23: 0 | JR23: 0 | JS23: 0 | JT23: 0 | JU23: 0 | JV23: 0 | JW23: 0 | JX23: 0 | JY23: 0 | KQ23: 0 | KR23: 0 | KS23: 0 | KT23: 0 | KU23: 0 | KV23: 0 | KW23: 0 | KX23: 0 | KY23: 0 | KZ23: 0 | LA23: 0 | LB23: 0 | LC23: 0 | LD23: 0
A24: ASM | B24: South | C24: Hyderabad | D24: HYD01-PHR-ASM-01 | E24: 03110 | F24: IMRAN QURESHI | G24: E-01752 | H24: 45171 | I24: Hyderabad | J24: 6 | K24: =SUM(K17:K23) -> 1 | L24: =SUM(L17:L23) -> 5 | M24: =SUM(M17:M23) -> 5 | N24: =SUM(N17:N23) -> 1 | O24: =SUM(O17:O23) -> 5 | P24: =SUM(P17:P23) -> 5 | Q24: =SUM(Q17:Q23) -> 5 | R24: =SUM(R17:R23) -> 5 | ... AU24: =SUM(AU17:AU23) -> 0 | AV24: =SUM(Q24:AU24) -> 59 | AW24: =IFERROR(AV24/$CF$2/(J24-K24),0) -> 0.90769231 | AX24: =SUM(AX17:AX23) -> 35 | AY24: =SUM(AY17:AY23) -> 57 | AZ24: =SUM(AZ17:AZ23) -> 31 | BA24: =SUM(BA17:BA23) -> 0 | BB24: =SUM(BB17:BB23) -> 51 | BC24: =SUM(BC17:BC23) -> 56 | BD24: =SUM(BD17:BD23) -> 45 | BE24: =SUM(BE17:BE23) -> 44 | ... CB24: =SUM(CB17:CB23) -> 0 | CC24: =SUM(AX24:CB24) -> 472 | CD24: =IFERROR(CC24/$CF$2/(J24-K24),0) -> 7.2615385 | JJ24: Formula | JK24: =D24 -> HYD01-PHR-ASM-01 | JL24: 0 | JM24: 0 | JN24: 0 | JO24: 0 | JP24: 0 | JQ24: 0 | JR24: 0 | JS24: 0 | JT24: 0 | JU24: 0 | JV24: 0 | JW24: 0 | JX24: 0 | JY24: 0 | KQ24: 0 | KR24: 0 | KS24: 0 | KT24: 0 | KU24: 0 | KV24: 0 | KW24: 0 | KX24: 0 | KY24: 0 | KZ24: 0 | LA24: 0 | LB24: 0 | LC24: 0 | LD24: 0
A25: MIO | B25: South | C25: Sukkur | D25: SUK01-PHR-MIO-01 | E25: 0311204 | F25: MR. HASNAIN RAZA (PHR-SUK-01) | G25: New | H25: 46230 | I25: Sukkur Ghotki/Civil/Stadium Rd | J25: 1 | K25: 0 | L25: =IFERROR(IF(OR(AD25>0),1,0),0) -> 0 | M25: =IFERROR(IF(OR(AV25>0),1,0),0) -> 1 | N25: =IFERROR(IF(OR(BK25>0),1,0),0) -> 0 | O25: =IFERROR(IF(OR(CC25>0),1,0),0) -> 1 | P25: =IFERROR(IF(OR(AV25>0,CC25>0),1,0),0) -> 1 | Q25: =JL25 -> 1 | R25: =JM25 -> 1 | S25: =JN25 -> 1 | T25: =JO25 -> 0 | U25: =JP25 -> 1 | V25: =JQ25 -> 1 | W25: =JR25 -> 1 | X25: =JS25 -> 1 | ... AU25: =KP25 -> 0 | AV25: =SUM(Q25:AU25) -> 11 | AW25: =IFERROR(AV25/$CF$2/(J25-K25),0) -> 0.84615385 | AX25: =KQ25 -> 1 | AY25: =KR25 -> 11 | AZ25: =KS25 -> 0 | BA25: =KT25 -> 0 | BB25: =KU25 -> 7 | BC25: =KV25 -> 7 | BD25: =KW25 -> 10 | BE25: =KX25 -> 1 | ... CB25: =LU25 -> 0 | CC25: =SUM(AX25:CB25) -> 58 | CD25: =IFERROR(CC25/$CF$2/(J25-K25),0) -> 4.4615385 | JJ25: Formula | JK25: =D25 -> SUK01-PHR-MIO-01 | JL25: 1 | JM25: 1 | JN25: 1 | JO25: 0 | JP25: 1 | JQ25: 1 | JR25: 1 | JS25: 1 | JT25: 1 | JU25: 1 | JV25: 0 | JW25: 1 | JX25: 1 | JY25: 0 | KQ25: 1 | KR25: 11 | KS25: 0 | KT25: 0 | KU25: 7 | KV25: 7 | KW25: 10 | KX25: 1 | KY25: 9 | KZ25: 1 | LA25: 0 | LB25: 10 | LC25: 1 | LD25: 0
A26: MIO | B26: South | C26: Sukkur | D26: SUK01-PHR-MIO-02 | E26: 0311205 | F26: MR. VACANT (PHR-SUK-02) | G26: VACANT | H26: RESIGNED | I26: Sukkur Gharibabad/Kharipur/Barrage Rd | J26: 1 | K26: 1 | L26: =IFERROR(IF(OR(AD26>0),1,0),0) -> 0 | M26: =IFERROR(IF(OR(AV26>0),1,0),0) -> 0 | N26: =IFERROR(IF(OR(BK26>0),1,0),0) -> 0 | O26: =IFERROR(IF(OR(CC26>0),1,0),0) -> 1 | P26: =IFERROR(IF(OR(AV26>0,CC26>0),1,0),0) -> 1 | Q26: =JL26 -> 0 | R26: =JM26 -> 0 | S26: =JN26 -> 0 | T26: =JO26 -> 0 | U26: =JP26 -> 0 | V26: =JQ26 -> 0 | W26: =JR26 -> 0 | X26: =JS26 -> 0 | ... AU26: =KP26 -> 0 | AV26: =SUM(Q26:AU26) -> 0 | AW26: =IFERROR(AV26/$CF$2/(J26-K26),0) -> 0 | AX26: =KQ26 -> 0 | AY26: =KR26 -> 0 | AZ26: =KS26 -> 0 | BA26: =KT26 -> 0 | BB26: =KU26 -> 0 | BC26: =KV26 -> 0 | BD26: =KW26 -> 1 | BE26: =KX26 -> 0 | ... CB26: =LU26 -> 0 | CC26: =SUM(AX26:CB26) -> 1 | CD26: =IFERROR(CC26/$CF$2/(J26-K26),0) -> 0 | JJ26: Formula | JK26: =D26 -> SUK01-PHR-MIO-02 | JL26: 0 | JM26: 0 | JN26: 0 | JO26: 0 | JP26: 0 | JQ26: 0 | JR26: 0 | JS26: 0 | JT26: 0 | JU26: 0 | JV26: 0 | JW26: 0 | JX26: 0 | JY26: 0 | KQ26: 0 | KR26: 0 | KS26: 0 | KT26: 0 | KU26: 0 | KV26: 0 | KW26: 1 | KX26: 0 | KY26: 0 | KZ26: 0 | LA26: 0 | LB26: 0 | LC26: 0 | LD26: 0
A27: MIO | B27: South | C27: Sukkur | D27: SUK01-PHR-MIO-03 | E27: 0311207 | F27: MR. ZULFIQAR AHMED (PHR-SUK-03) | G27: E-01301 | H27: 44566 | I27: Larkana, Shahdadkot, Qambar, Ratto Dero , Nau Dero | J27: 1 | K27: 0 | L27: =IFERROR(IF(OR(AD27>0),1,0),0) -> 1 | M27: =IFERROR(IF(OR(AV27>0),1,0),0) -> 1 | N27: =IFERROR(IF(OR(BK27>0),1,0),0) -> 1 | O27: =IFERROR(IF(OR(CC27>0),1,0),0) -> 1 | P27: =IFERROR(IF(OR(AV27>0,CC27>0),1,0),0) -> 1 | Q27: =JL27 -> 1 | R27: =JM27 -> 1 | S27: =JN27 -> 1 | T27: =JO27 -> 0 | U27: =JP27 -> 1 | V27: =JQ27 -> 1 | W27: =JR27 -> 1 | X27: =JS27 -> 1 | ... AU27: =KP27 -> 0 | AV27: =SUM(Q27:AU27) -> 12 | AW27: =IFERROR(AV27/$CF$2/(J27-K27),0) -> 0.92307692 | AX27: =KQ27 -> 10 | AY27: =KR27 -> 7 | AZ27: =KS27 -> 8 | BA27: =KT27 -> 0 | BB27: =KU27 -> 5 | BC27: =KV27 -> 10 | BD27: =KW27 -> 1 | BE27: =KX27 -> 6 | ... CB27: =LU27 -> 0 | CC27: =SUM(AX27:CB27) -> 81 | CD27: =IFERROR(CC27/$CF$2/(J27-K27),0) -> 6.2307692 | JJ27: Formula | JK27: =D27 -> SUK01-PHR-MIO-03 | JL27: 1 | JM27: 1 | JN27: 1 | JO27: 0 | JP27: 1 | JQ27: 1 | JR27: 1 | JS27: 1 | JT27: 1 | JU27: 1 | JV27: 0 | JW27: 1 | JX27: 1 | JY27: 1 | KQ27: 10 | KR27: 7 | KS27: 8 | KT27: 0 | KU27: 5 | KV27: 10 | KW27: 1 | KX27: 6 | KY27: 4 | KZ27: 9 | LA27: 0 | LB27: 7 | LC27: 11 | LD27: 3
A28: MIO | B28: South | C28: Sukkur | D28: SUK01-PHR-MIO-04 | E28: 0311203 | F28: MR. AKHTIAR (PHR-SUK-04) | G28: E-01428 | H28: 44776 | I28: E-01428 | J28: 1 | K28: 0 | L28: =IFERROR(IF(OR(AD28>0),1,0),0) -> 1 | M28: =IFERROR(IF(OR(AV28>0),1,0),0) -> 1 | N28: =IFERROR(IF(OR(BK28>0),1,0),0) -> 0 | O28: =IFERROR(IF(OR(CC28>0),1,0),0) -> 1 | P28: =IFERROR(IF(OR(AV28>0,CC28>0),1,0),0) -> 1 | Q28: =JL28 -> 1 | R28: =JM28 -> 1 | S28: =JN28 -> 1 | T28: =JO28 -> 0 | U28: =JP28 -> 1 | V28: =JQ28 -> 1 | W28: =JR28 -> 1 | X28: =JS28 -> 1 | ... AU28: =KP28 -> 0 | AV28: =SUM(Q28:AU28) -> 12 | AW28: =IFERROR(AV28/$CF$2/(J28-K28),0) -> 0.92307692 | AX28: =KQ28 -> 11 | AY28: =KR28 -> 12 | AZ28: =KS28 -> 8 | BA28: =KT28 -> 0 | BB28: =KU28 -> 11 | BC28: =KV28 -> 12 | BD28: =KW28 -> 12 | BE28: =KX28 -> 16 | ... CB28: =LU28 -> 0 | CC28: =SUM(AX28:CB28) -> 126 | CD28: =IFERROR(CC28/$CF$2/(J28-K28),0) -> 9.6923077 | JJ28: Formula | JK28: =D28 -> SUK01-PHR-MIO-04 | JL28: 1 | JM28: 1 | JN28: 1 | JO28: 0 | JP28: 1 | JQ28: 1 | JR28: 1 | JS28: 1 | JT28: 1 | JU28: 1 | JV28: 0 | JW28: 1 | JX28: 1 | JY28: 1 | KQ28: 11 | KR28: 12 | KS28: 8 | KT28: 0 | KU28: 11 | KV28: 12 | KW28: 12 | KX28: 16 | KY28: 12 | KZ28: 8 | LA28: 0 | LB28: 12 | LC28: 12 | LD28: 0
A29: MIO | B29: South | C29: Sukkur | D29: SUK01-PHR-MIO-05 | E29: 0311201 | F29: MR. ASIF ALI SOOMRO (PHR-SUK-05) | G29: E-02495 | H29: 45173 | I29: Shikarpur, Kandhkot, Kashmore, Thull | J29: 1 | K29: 0 | L29: =IFERROR(IF(OR(AD29>0),1,0),0) -> 1 | M29: =IFERROR(IF(OR(AV29>0),1,0),0) -> 1 | N29: =IFERROR(IF(OR(BK29>0),1,0),0) -> 0 | O29: =IFERROR(IF(OR(CC29>0),1,0),0) -> 1 | P29: =IFERROR(IF(OR(AV29>0,CC29>0),1,0),0) -> 1 | Q29: =JL29 -> 1 | R29: =JM29 -> 1 | S29: =JN29 -> 1 | T29: =JO29 -> 0 | U29: =JP29 -> 1 | V29: =JQ29 -> 1 | W29: =JR29 -> 1 | X29: =JS29 -> 1 | ... AU29: =KP29 -> 0 | AV29: =SUM(Q29:AU29) -> 10 | AW29: =IFERROR(AV29/$CF$2/(J29-K29),0) -> 0.76923077 | AX29: =KQ29 -> 1 | AY29: =KR29 -> 3 | AZ29: =KS29 -> 0 | BA29: =KT29 -> 0 | BB29: =KU29 -> 11 | BC29: =KV29 -> 0 | BD29: =KW29 -> 1 | BE29: =KX29 -> 4 | ... CB29: =LU29 -> 0 | CC29: =SUM(AX29:CB29) -> 22 | CD29: =IFERROR(CC29/$CF$2/(J29-K29),0) -> 1.6923077 | JJ29: Formula | JK29: =D29 -> SUK01-PHR-MIO-05 | JL29: 1 | JM29: 1 | JN29: 1 | JO29: 0 | JP29: 1 | JQ29: 1 | JR29: 1 | JS29: 1 | JT29: 0 | JU29: 0 | JV29: 0 | JW29: 1 | JX29: 1 | JY29: 1 | KQ29: 1 | KR29: 3 | KS29: 0 | KT29: 0 | KU29: 11 | KV29: 0 | KW29: 1 | KX29: 4 | KY29: 0 | KZ29: 0 | LA29: 0 | LB29: 2 | LC29: 0 | LD29: 0
A30: MIO | B30: South | C30: Sukkur | D30: SUK01-PHR-MIO-06 | E30: 0311206 | F30: M. PUNHAL PATHAN (PHR-SUK-06) | G30: E-02496 | H30: 45208 | I30: Jacobabad, Dera Murad Jamali, Dera Allahyar, Usta Mohd | J30: 1 | K30: 0 | L30: =IFERROR(IF(OR(AD30>0),1,0),0) -> 1 | M30: =IFERROR(IF(OR(AV30>0),1,0),0) -> 1 | N30: =IFERROR(IF(OR(BK30>0),1,0),0) -> 0 | O30: =IFERROR(IF(OR(CC30>0),1,0),0) -> 1 | P30: =IFERROR(IF(OR(AV30>0,CC30>0),1,0),0) -> 1 | Q30: =JL30 -> 1 | R30: =JM30 -> 1 | S30: =JN30 -> 1 | T30: =JO30 -> 0 | U30: =JP30 -> 1 | V30: =JQ30 -> 1 | W30: =JR30 -> 1 | X30: =JS30 -> 1 | ... AU30: =KP30 -> 0 | AV30: =SUM(Q30:AU30) -> 12 | AW30: =IFERROR(AV30/$CF$2/(J30-K30),0) -> 0.92307692 | AX30: =KQ30 -> 9 | AY30: =KR30 -> 6 | AZ30: =KS30 -> 2 | BA30: =KT30 -> 0 | BB30: =KU30 -> 0 | BC30: =KV30 -> 4 | BD30: =KW30 -> 0 | BE30: =KX30 -> 0 | ... CB30: =LU30 -> 0 | CC30: =SUM(AX30:CB30) -> 38 | CD30: =IFERROR(CC30/$CF$2/(J30-K30),0) -> 2.9230769 | JJ30: Formula | JK30: =D30 -> SUK01-PHR-MIO-06 | JL30: 1 | JM30: 1 | JN30: 1 | JO30: 0 | JP30: 1 | JQ30: 1 | JR30: 1 | JS30: 1 | JT30: 1 | JU30: 1 | JV30: 0 | JW30: 1 | JX30: 1 | JY30: 1 | KQ30: 9 | KR30: 6 | KS30: 2 | KT30: 0 | KU30: 0 | KV30: 4 | KW30: 0 | KX30: 0 | KY30: 2 | KZ30: 4 | LA30: 0 | LB30: 11 | LC30: 0 | LD30: 0
A31: MIO Unmap | B31: South | C31: Sukkur | D31: SUK01-PHR-MIO-00 | E31: 0311209 | F31: SUK01 - PHR UNMAPPED | G31: UN-DEFINED | H31: UN-DEFINED | I31: Sukkur | J31: 0 | K31: 0 | L31: =IFERROR(IF(OR(AD31>0),1,0),0) -> 0 | M31: =IFERROR(IF(OR(AV31>0),1,0),0) -> 0 | N31: =IFERROR(IF(OR(BK31>0),1,0),0) -> 0 | O31: =IFERROR(IF(OR(CC31>0),1,0),0) -> 0 | P31: =IFERROR(IF(OR(AV31>0,CC31>0),1,0),0) -> 0 | Q31: =JL31 -> 0 | R31: =JM31 -> 0 | S31: =JN31 -> 0 | T31: =JO31 -> 0 | U31: =JP31 -> 0 | V31: =JQ31 -> 0 | W31: =JR31 -> 0 | X31: =JS31 -> 0 | ... AU31: =KP31 -> 0 | AV31: =SUM(Q31:AU31) -> 0 | AW31: =IFERROR(AV31/$CF$2/(J31-K31),0) -> 0 | AX31: =KQ31 -> 0 | AY31: =KR31 -> 0 | AZ31: =KS31 -> 0 | BA31: =KT31 -> 0 | BB31: =KU31 -> 0 | BC31: =KV31 -> 0 | BD31: =KW31 -> 0 | BE31: =KX31 -> 0 | ... CB31: =LU31 -> 0 | CC31: =SUM(AX31:CB31) -> 0 | CD31: =IFERROR(CC31/$CF$2/(J31-K31),0) -> 0 | JJ31: Formula | JK31: =D31 -> SUK01-PHR-MIO-00 | JL31: 0 | JM31: 0 | JN31: 0 | JO31: 0 | JP31: 0 | JQ31: 0 | JR31: 0 | JS31: 0 | JT31: 0 | JU31: 0 | JV31: 0 | JW31: 0 | JX31: 0 | JY31: 0 | KQ31: 0 | KR31: 0 | KS31: 0 | KT31: 0 | KU31: 0 | KV31: 0 | KW31: 0 | KX31: 0 | KY31: 0 | KZ31: 0 | LA31: 0 | LB31: 0 | LC31: 0 | LD31: 0
A32: ASM | B32: South | C32: Sukkur | D32: SUK01-PHR-ASM-01 | E32: 03120 | F32: TAHIR HUSSAIN | G32: E-01684 | H32: 45112 | I32: Sukkur | J32: 6 | K32: =SUM(K25:K31) -> 1 | L32: =SUM(L25:L31) -> 4 | M32: =SUM(M25:M31) -> 5 | N32: =SUM(N25:N31) -> 1 | O32: =SUM(O25:O31) -> 6 | P32: =SUM(P25:P31) -> 6 | Q32: =SUM(Q25:Q31) -> 5 | R32: =SUM(R25:R31) -> 5 | ... AU32: =SUM(AU25:AU31) -> 0 | AV32: =SUM(Q32:AU32) -> 57 | AW32: =IFERROR(AV32/$CF$2/(J32-K32),0) -> 0.87692308 | AX32: =SUM(AX25:AX31) -> 32 | AY32: =SUM(AY25:AY31) -> 39 | AZ32: =SUM(AZ25:AZ31) -> 18 | BA32: =SUM(BA25:BA31) -> 0 | BB32: =SUM(BB25:BB31) -> 34 | BC32: =SUM(BC25:BC31) -> 33 | BD32: =SUM(BD25:BD31) -> 25 | BE32: =SUM(BE25:BE31) -> 27 | ... CB32: =SUM(CB25:CB31) -> 0 | CC32: =SUM(AX32:CB32) -> 326 | CD32: =IFERROR(CC32/$CF$2/(J32-K32),0) -> 5.0153846 | JJ32: Formula | JK32: =D32 -> SUK01-PHR-ASM-01 | JL32: 0 | JM32: 0 | JN32: 0 | JO32: 0 | JP32: 0 | JQ32: 0 | JR32: 0 | JS32: 0 | JT32: 0 | JU32: 0 | JV32: 0 | JW32: 0 | JX32: 0 | JY32: 0 | KQ32: 0 | KR32: 0 | KS32: 0 | KT32: 0 | KU32: 0 | KV32: 0 | KW32: 0 | KX32: 0 | KY32: 0 | KZ32: 0 | LA32: 0 | LB32: 0 | LC32: 0 | LD32: 0
A33: RSM | B33: South | C33: Karachi | D33: STH-PHR-DGM-01 | E33: 03 | F33: Mr. Zahid Ali Shah | G33: VACANT | H33: RESIGNED | I33: Karachi | J33: 21 | K33: =K32+K24+K16+K10 -> 7 | L33: =L32+L24+L16+L10 -> 11 | M33: =M32+M24+M16+M10 -> 14 | N33: =N32+N24+N16+N10 -> 3 | O33: =O32+O24+O16+O10 -> 15 | P33: =P32+P24+P16+P10 -> 15 | Q33: =Q32+Q24+Q16+Q10 -> 14 | R33: =R32+R24+R16+R10 -> 14 | ... AU33: =AU32+AU24+AU16+AU10 -> 0 | AV33: =SUM(Q33:AU33) -> 158 | AW33: =IFERROR(AV33/$CF$2/(J33-K33),0) -> 0.86813187 | AX33: =AX32+AX24+AX16+AX10 -> 96 | AY33: =AY32+AY24+AY16+AY10 -> 130 | AZ33: =AZ32+AZ24+AZ16+AZ10 -> 68 | BA33: =BA32+BA24+BA16+BA10 -> 0 | BB33: =BB32+BB24+BB16+BB10 -> 113 | BC33: =BC32+BC24+BC16+BC10 -> 128 | BD33: =BD32+BD24+BD16+BD10 -> 115 | BE33: =BE32+BE24+BE16+BE10 -> 91 | ... CB33: =CB32+CB24+CB16+CB10 -> 0 | CC33: =SUM(AX33:CB33) -> 1119 | CD33: =IFERROR(CC33/$CF$2/(J33-K33),0) -> 6.1483516 | JJ33: Formula | JK33: =D33 -> STH-PHR-DGM-01 | JL33: 0 | JM33: 0 | JN33: 0 | JO33: 0 | JP33: 0 | JQ33: 0 | JR33: 0 | JS33: 0 | JT33: 0 | JU33: 0 | JV33: 0 | JW33: 0 | JX33: 0 | JY33: 0 | KQ33: 0 | KR33: 0 | KS33: 0 | KT33: 0 | KU33: 0 | KV33: 0 | KW33: 0 | KX33: 0 | KY33: 0 | KZ33: 0 | LA33: 0 | LB33: 0 | LC33: 0 | LD33: 0
A34: MIO | B34: Central | C34: Lahore-1 | D34: LHR01-PHR-MIO-01 | E34: 0411004 | F34: MR. VACANT (PHR-LHR-01) | G34: VACANT | H34: RESIGNED | I34: Lahore 1 | J34: 1 | K34: 1 | L34: =IFERROR(IF(OR(AD34>0),1,0),0) -> 0 | M34: =IFERROR(IF(OR(AV34>0),1,0),0) -> 0 | N34: =IFERROR(IF(OR(BK34>0),1,0),0) -> 0 | O34: =IFERROR(IF(OR(CC34>0),1,0),0) -> 0 | P34: =IFERROR(IF(OR(AV34>0,CC34>0),1,0),0) -> 0 | Q34: =JL34 -> 0 | R34: =JM34 -> 0 | S34: =JN34 -> 0 | T34: =JO34 -> 0 | U34: =JP34 -> 0 | V34: =JQ34 -> 0 | W34: =JR34 -> 0 | X34: =JS34 -> 0 | ... AU34: =KP34 -> 0 | AV34: =SUM(Q34:AU34) -> 0 | AW34: =IFERROR(AV34/$CF$2/(J34-K34),0) -> 0 | AX34: =KQ34 -> 0 | AY34: =KR34 -> 0 | AZ34: =KS34 -> 0 | BA34: =KT34 -> 0 | BB34: =KU34 -> 0 | BC34: =KV34 -> 0 | BD34: =KW34 -> 0 | BE34: =KX34 -> 0 | ... CB34: =LU34 -> 0 | CC34: =SUM(AX34:CB34) -> 0 | CD34: =IFERROR(CC34/$CF$2/(J34-K34),0) -> 0 | JJ34: Formula | JK34: =D34 -> LHR01-PHR-MIO-01 | JL34: 0 | JM34: 0 | JN34: 0 | JO34: 0 | JP34: 0 | JQ34: 0 | JR34: 0 | JS34: 0 | JT34: 0 | JU34: 0 | JV34: 0 | JW34: 0 | JX34: 0 | JY34: 0 | KQ34: 0 | KR34: 0 | KS34: 0 | KT34: 0 | KU34: 0 | KV34: 0 | KW34: 0 | KX34: 0 | KY34: 0 | KZ34: 0 | LA34: 0 | LB34: 0 | LC34: 0 | LD34: 0
A35: MIO | B35: Central | C35: Lahore-1 | D35: LHR01-PHR-MIO-02 | E35: 0411007 | F35: MS. SAMINA KAUSAR (PHR-LHR-02) | G35: E-00651 | H35: 43652 | I35: Kasur | J35: 1 | K35: 0 | L35: =IFERROR(IF(OR(AD35>0),1,0),0) -> 1 | M35: =IFERROR(IF(OR(AV35>0),1,0),0) -> 1 | N35: =IFERROR(IF(OR(BK35>0),1,0),0) -> 1 | O35: =IFERROR(IF(OR(CC35>0),1,0),0) -> 1 | P35: =IFERROR(IF(OR(AV35>0,CC35>0),1,0),0) -> 1 | Q35: =JL35 -> 1 | R35: =JM35 -> 1 | S35: =JN35 -> 1 | T35: =JO35 -> 0 | U35: =JP35 -> 1 | V35: =JQ35 -> 1 | W35: =JR35 -> 1 | X35: =JS35 -> 1 | ... AU35: =KP35 -> 0 | AV35: =SUM(Q35:AU35) -> 12 | AW35: =IFERROR(AV35/$CF$2/(J35-K35),0) -> 0.92307692 | AX35: =KQ35 -> 9 | AY35: =KR35 -> 9 | AZ35: =KS35 -> 8 | BA35: =KT35 -> 0 | BB35: =KU35 -> 10 | BC35: =KV35 -> 10 | BD35: =KW35 -> 10 | BE35: =KX35 -> 6 | ... CB35: =LU35 -> 0 | CC35: =SUM(AX35:CB35) -> 101 | CD35: =IFERROR(CC35/$CF$2/(J35-K35),0) -> 7.7692308 | JJ35: Formula | JK35: =D35 -> LHR01-PHR-MIO-02 | JL35: 1 | JM35: 1 | JN35: 1 | JO35: 0 | JP35: 1 | JQ35: 1 | JR35: 1 | JS35: 1 | JT35: 1 | JU35: 1 | JV35: 0 | JW35: 1 | JX35: 1 | JY35: 1 | KQ35: 9 | KR35: 9 | KS35: 8 | KT35: 0 | KU35: 10 | KV35: 10 | KW35: 10 | KX35: 6 | KY35: 8 | KZ35: 8 | LA35: 0 | LB35: 11 | LC35: 11 | LD35: 1
A36: MIO | B36: Central | C36: Lahore-1 | D36: LHR01-PHR-MIO-04 | E36: 0411006 | F36: MR. KHURRAM SHAHZAD KHAN (PHR-LHR-03) | G36: P-00952 | H36: 39611 | I36: Sahiwal | J36: 1 | K36: 0 | L36: =IFERROR(IF(OR(AD36>0),1,0),0) -> 1 | M36: =IFERROR(IF(OR(AV36>0),1,0),0) -> 1 | N36: =IFERROR(IF(OR(BK36>0),1,0),0) -> 1 | O36: =IFERROR(IF(OR(CC36>0),1,0),0) -> 1 | P36: =IFERROR(IF(OR(AV36>0,CC36>0),1,0),0) -> 1 | Q36: =JL36 -> 1 | R36: =JM36 -> 1 | S36: =JN36 -> 1 | T36: =JO36 -> 0 | U36: =JP36 -> 1 | V36: =JQ36 -> 1 | W36: =JR36 -> 1 | X36: =JS36 -> 1 | ... AU36: =KP36 -> 0 | AV36: =SUM(Q36:AU36) -> 12 | AW36: =IFERROR(AV36/$CF$2/(J36-K36),0) -> 0.92307692 | AX36: =KQ36 -> 12 | AY36: =KR36 -> 11 | AZ36: =KS36 -> 11 | BA36: =KT36 -> 0 | BB36: =KU36 -> 12 | BC36: =KV36 -> 10 | BD36: =KW36 -> 12 | BE36: =KX36 -> 11 | ... CB36: =LU36 -> 0 | CC36: =SUM(AX36:CB36) -> 134 | CD36: =IFERROR(CC36/$CF$2/(J36-K36),0) -> 10.307692 | JJ36: Formula | JK36: =D36 -> LHR01-PHR-MIO-04 | JL36: 1 | JM36: 1 | JN36: 1 | JO36: 0 | JP36: 1 | JQ36: 1 | JR36: 1 | JS36: 1 | JT36: 1 | JU36: 1 | JV36: 0 | JW36: 1 | JX36: 1 | JY36: 1 | KQ36: 12 | KR36: 11 | KS36: 11 | KT36: 0 | KU36: 12 | KV36: 10 | KW36: 12 | KX36: 11 | KY36: 12 | KZ36: 10 | LA36: 0 | LB36: 13 | LC36: 14 | LD36: 6
A37: MIO | B37: Central | C37: Lahore-1 | D37: LHR01-PHR-MIO-05 | E37: 0411005 | F37: MR. ABID ALI (PHR-LHR-04) | G37: E-03005 | H37: 46059 | I37: Okara | J37: 1 | K37: 0 | L37: =IFERROR(IF(OR(AD37>0),1,0),0) -> 1 | M37: =IFERROR(IF(OR(AV37>0),1,0),0) -> 1 | N37: =IFERROR(IF(OR(BK37>0),1,0),0) -> 1 | O37: =IFERROR(IF(OR(CC37>0),1,0),0) -> 1 | P37: =IFERROR(IF(OR(AV37>0,CC37>0),1,0),0) -> 1 | Q37: =JL37 -> 1 | R37: =JM37 -> 0 | S37: =JN37 -> 1 | T37: =JO37 -> 0 | U37: =JP37 -> 1 | V37: =JQ37 -> 1 | W37: =JR37 -> 1 | X37: =JS37 -> 0 | ... AU37: =KP37 -> 0 | AV37: =SUM(Q37:AU37) -> 10 | AW37: =IFERROR(AV37/$CF$2/(J37-K37),0) -> 0.76923077 | AX37: =KQ37 -> 11 | AY37: =KR37 -> 12 | AZ37: =KS37 -> 7 | BA37: =KT37 -> 0 | BB37: =KU37 -> 9 | BC37: =KV37 -> 13 | BD37: =KW37 -> 11 | BE37: =KX37 -> 11 | ... CB37: =LU37 -> 0 | CC37: =SUM(AX37:CB37) -> 126 | CD37: =IFERROR(CC37/$CF$2/(J37-K37),0) -> 9.6923077 | JJ37: Formula | JK37: =D37 -> LHR01-PHR-MIO-05 | JL37: 1 | JM37: 0 | JN37: 1 | JO37: 0 | JP37: 1 | JQ37: 1 | JR37: 1 | JS37: 0 | JT37: 1 | JU37: 1 | JV37: 0 | JW37: 1 | JX37: 1 | JY37: 1 | KQ37: 11 | KR37: 12 | KS37: 7 | KT37: 0 | KU37: 9 | KV37: 13 | KW37: 11 | KX37: 11 | KY37: 11 | KZ37: 11 | LA37: 0 | LB37: 12 | LC37: 12 | LD37: 6
A38: MIO | B38: Central | C38: Lahore-2 | D38: LHR01-PHR-PS-01 | E38: 0411010 | F38: M ASIM (PS-LHR-02) | G38: E-01769 | H38: 45216 | I38: LHR/Mall Rd/Ravi /Rd/Shadbagh/Samanabad/Mayo Hosp | J38: 1 | K38: 0 | L38: =IFERROR(IF(OR(AD38>0),1,0),0) -> 0 | M38: =IFERROR(IF(OR(AV38>0),1,0),0) -> 1 | N38: =IFERROR(IF(OR(BK38>0),1,0),0) -> 0 | O38: =IFERROR(IF(OR(CC38>0),1,0),0) -> 1 | P38: =IFERROR(IF(OR(AV38>0,CC38>0),1,0),0) -> 1 | Q38: =JL38 -> 0 | R38: =JM38 -> 0 | S38: =JN38 -> 1 | T38: =JO38 -> 0 | U38: =JP38 -> 1 | V38: =JQ38 -> 1 | W38: =JR38 -> 0 | X38: =JS38 -> 1 | ... AU38: =KP38 -> 0 | AV38: =SUM(Q38:AU38) -> 8 | AW38: =IFERROR(AV38/$CF$2/(J38-K38),0) -> 0.61538462 | AX38: =KQ38 -> 10 | AY38: =KR38 -> 0 | AZ38: =KS38 -> 8 | BA38: =KT38 -> 0 | BB38: =KU38 -> 0 | BC38: =KV38 -> 9 | BD38: =KW38 -> 9 | BE38: =KX38 -> 0 | ... CB38: =LU38 -> 0 | CC38: =SUM(AX38:CB38) -> 57 | CD38: =IFERROR(CC38/$CF$2/(J38-K38),0) -> 4.3846154 | JJ38: Formula | JK38: =D38 -> LHR01-PHR-PS-01 | JL38: 0 | JM38: 0 | JN38: 1 | JO38: 0 | JP38: 1 | JQ38: 1 | JR38: 0 | JS38: 1 | JT38: 1 | JU38: 1 | JV38: 0 | JW38: 1 | JX38: 1 | JY38: 0 | KQ38: 10 | KR38: 0 | KS38: 8 | KT38: 0 | KU38: 0 | KV38: 9 | KW38: 9 | KX38: 0 | KY38: 9 | KZ38: 0 | LA38: 0 | LB38: 12 | LC38: 0 | LD38: 0
A39: MIO Unmap | B39: Central | C39: Lahore-1 | D39: LHR01-PHR-MIO-00 | E39: 0413001 | F39: LHR01 - PHR UNMAPPED | G39: UN-DEFINED | H39: UN-DEFINED | I39: Lahore 1 | J39: 0 | K39: 0 | L39: =IFERROR(IF(OR(AD39>0),1,0),0) -> 0 | M39: =IFERROR(IF(OR(AV39>0),1,0),0) -> 0 | N39: =IFERROR(IF(OR(BK39>0),1,0),0) -> 0 | O39: =IFERROR(IF(OR(CC39>0),1,0),0) -> 0 | P39: =IFERROR(IF(OR(AV39>0,CC39>0),1,0),0) -> 0 | Q39: =JL39 -> 0 | R39: =JM39 -> 0 | S39: =JN39 -> 0 | T39: =JO39 -> 0 | U39: =JP39 -> 0 | V39: =JQ39 -> 0 | W39: =JR39 -> 0 | X39: =JS39 -> 0 | ... AU39: =KP39 -> 0 | AV39: =SUM(Q39:AU39) -> 0 | AW39: =IFERROR(AV39/$CF$2/(J39-K39),0) -> 0 | AX39: =KQ39 -> 0 | AY39: =KR39 -> 0 | AZ39: =KS39 -> 0 | BA39: =KT39 -> 0 | BB39: =KU39 -> 0 | BC39: =KV39 -> 0 | BD39: =KW39 -> 0 | BE39: =KX39 -> 0 | ... CB39: =LU39 -> 0 | CC39: =SUM(AX39:CB39) -> 0 | CD39: =IFERROR(CC39/$CF$2/(J39-K39),0) -> 0 | JJ39: Formula | JK39: =D39 -> LHR01-PHR-MIO-00 | JL39: 0 | JM39: 0 | JN39: 0 | JO39: 0 | JP39: 0 | JQ39: 0 | JR39: 0 | JS39: 0 | JT39: 0 | JU39: 0 | JV39: 0 | JW39: 0 | JX39: 0 | JY39: 0 | KQ39: 0 | KR39: 0 | KS39: 0 | KT39: 0 | KU39: 0 | KV39: 0 | KW39: 0 | KX39: 0 | KY39: 0 | KZ39: 0 | LA39: 0 | LB39: 0 | LC39: 0 | LD39: 0
A40: ASM | B40: Central | C40: Lahore-1 | D40: LHR01-PHR-ASM-01 | E40: 04130 | F40: SHAHID SULTAN | G40: E-01750 | H40: 45170 | I40: Lahore 1 | J40: 5 | K40: =SUM(K34:K39) -> 1 | L40: =SUM(L34:L39) -> 3 | M40: =SUM(M34:M39) -> 4 | N40: =SUM(N34:N39) -> 3 | O40: =SUM(O34:O39) -> 4 | P40: =SUM(P34:P39) -> 4 | Q40: =SUM(Q34:Q39) -> 3 | R40: =SUM(R34:R39) -> 2 | ... AU40: =SUM(AU34:AU39) -> 0 | AV40: =SUM(Q40:AU40) -> 42 | AW40: =IFERROR(AV40/$CF$2/(J40-K40),0) -> 0.80769231 | AX40: =SUM(AX34:AX39) -> 42 | AY40: =SUM(AY34:AY39) -> 32 | AZ40: =SUM(AZ34:AZ39) -> 34 | BA40: =SUM(BA34:BA39) -> 0 | BB40: =SUM(BB34:BB39) -> 31 | BC40: =SUM(BC34:BC39) -> 42 | BD40: =SUM(BD34:BD39) -> 42 | BE40: =SUM(BE34:BE39) -> 28 | ... CB40: =SUM(CB34:CB39) -> 0 | CC40: =SUM(AX40:CB40) -> 418 | CD40: =IFERROR(CC40/$CF$2/(J40-K40),0) -> 8.0384615 | JJ40: Formula | JK40: =D40 -> LHR01-PHR-ASM-01 | JL40: 0 | JM40: 0 | JN40: 0 | JO40: 0 | JP40: 0 | JQ40: 0 | JR40: 0 | JS40: 0 | JT40: 0 | JU40: 0 | JV40: 0 | JW40: 0 | JX40: 0 | JY40: 0 | KQ40: 0 | KR40: 0 | KS40: 0 | KT40: 0 | KU40: 0 | KV40: 0 | KW40: 0 | KX40: 0 | KY40: 0 | KZ40: 0 | LA40: 0 | LB40: 0 | LC40: 0 | LD40: 0
...

Sheet ASM RSM
A1: =Pharma!A2 -> PHARMA Team – IKON MTD Call Performance Summary Till 14-OCT-2026 | I1: Attendance | N1: Calls + Other Exceptions | U1: Comments | Y1: Pharma Team | MIO IKON MTD Performance Report (Till 29 Jul-2026, 01:35PM)
I2: 46309 | N2: =I2 -> 46309
A3: =Pharma!A3 -> Desig | B3: =Pharma!B3 -> Zone | C3: =Pharma!C3 -> PHR Region | D3: =Pharma!F3 -> F.F Name | E3: =Pharma!J3 -> Reps | F3: =Pharma!K3 -> # Of Vacant | G3: Not Used IKON Toay | H3: =Pharma!P3 -> IKON Used | I3: # of Attn Yesterday | J3: # of Attn Today | K3: # of Attn MTD | L3: Active MIOs MTD | M3: Averg P/Rep/Day | N3: # of Calls Yesterday | O3: # of Calls Today | P3: Active MIOs Today | Q3: # of Calls MTD | R3: Active MIOs MTD | S3: Averg P/Rep/Day | T3: Status
A4: =Pharma!A10 -> ASM | B4: =Pharma!B10 -> South | C4: =Pharma!C10 -> Karachi-1 | D4: =Pharma!F10 -> VACANT ASM KHI-01 | E4: =Pharma!J10 -> 5 | F4: =Pharma!K10 -> 4 | G4: =E4-J4-F4 -> 1 | H4: =Pharma!P10 -> 1 | I4: =Pharma!AC10 -> 0 | J4: =Pharma!AD10 -> 0 | K4: =Pharma!AV10 -> 10 | L4: =Pharma!M10 -> 1 | M4: =Pharma!AW10 -> 0.76923077 | N4: =Pharma!BJ10 -> 0 | O4: =Pharma!BK10 -> 0 | P4: =Pharma!N10 -> 0 | Q4: =Pharma!CC10 -> 58 | R4: =Pharma!O10 -> 1 | S4: =Pharma!CD10 -> 4.4615385 | T4: =IF(S4>=12,"🟢 Excellent",IF(S4>=6,"🟡 Needs Improvement","🔴 Critical")) -> 🔴 Critical
A5: =Pharma!A16 -> ASM | B5: =Pharma!B16 -> South | C5: =Pharma!C16 -> Karachi-2 | D5: =Pharma!F16 -> M. ALI ANIS | E5: =Pharma!J16 -> 4 | F5: =Pharma!K16 -> 1 | G5: =E5-J5-F5 -> 1 | H5: =Pharma!P16 -> 3 | I5: =Pharma!AC16 -> 3 | J5: =Pharma!AD16 -> 2 | K5: =Pharma!AV16 -> 32 | L5: =Pharma!M16 -> 3 | M5: =Pharma!AW16 -> 0.82051282 | N5: =Pharma!BJ16 -> 32 | O5: =Pharma!BK16 -> 1 | P5: =Pharma!N16 -> 1 | Q5: =Pharma!CC16 -> 263 | R5: =Pharma!O16 -> 3 | S5: =Pharma!CD16 -> 6.7435897 | T5: =IF(S5>=12,"🟢 Excellent",IF(S5>=6,"🟡 Needs Improvement","🔴 Critical")) -> 🟡 Needs Improvement
A6: =Pharma!A24 -> ASM | B6: =Pharma!B24 -> South | C6: =Pharma!C24 -> Hyderabad | D6: =Pharma!F24 -> IMRAN QURESHI | E6: =Pharma!J24 -> 6 | F6: =Pharma!K24 -> 1 | G6: =E6-J6-F6 -> 0 | H6: =Pharma!P24 -> 5 | I6: =Pharma!AC24 -> 5 | J6: =Pharma!AD24 -> 5 | K6: =Pharma!AV24 -> 59 | L6: =Pharma!M24 -> 5 | M6: =Pharma!AW24 -> 0.90769231 | N6: =Pharma!BJ24 -> 34 | O6: =Pharma!BK24 -> 3 | P6: =Pharma!N24 -> 1 | Q6: =Pharma!CC24 -> 472 | R6: =Pharma!O24 -> 5 | S6: =Pharma!CD24 -> 7.2615385 | T6: =IF(S6>=12,"🟢 Excellent",IF(S6>=6,"🟡 Needs Improvement","🔴 Critical")) -> 🟡 Needs Improvement
A7: =Pharma!A32 -> ASM | B7: =Pharma!B32 -> South | C7: =Pharma!C32 -> Sukkur | D7: =Pharma!F32 -> TAHIR HUSSAIN | E7: =Pharma!J32 -> 6 | F7: =Pharma!K32 -> 1 | G7: =E7-J7-F7 -> 1 | H7: =Pharma!P32 -> 6 | I7: =Pharma!AC32 -> 5 | J7: =Pharma!AD32 -> 4 | K7: =Pharma!AV32 -> 57 | L7: =Pharma!M32 -> 5 | M7: =Pharma!AW32 -> 0.87692308 | N7: =Pharma!BJ32 -> 24 | O7: =Pharma!BK32 -> 3 | P7: =Pharma!N32 -> 1 | Q7: =Pharma!CC32 -> 326 | R7: =Pharma!O32 -> 6 | S7: =Pharma!CD32 -> 5.0153846 | T7: =IF(S7>=12,"🟢 Excellent",IF(S7>=6,"🟡 Needs Improvement","🔴 Critical")) -> 🔴 Critical
A8: =Pharma!A33 -> RSM | B8: =Pharma!B33 -> South | C8: =Pharma!C33 -> Karachi | D8: =Pharma!F33 -> Mr. Zahid Ali Shah | E8: =Pharma!J33 -> 21 | F8: =Pharma!K33 -> 7 | G8: =E8-J8-F8 -> 3 | H8: =Pharma!P33 -> 15 | I8: =Pharma!AC33 -> 13 | J8: =Pharma!AD33 -> 11 | K8: =Pharma!AV33 -> 158 | L8: =Pharma!M33 -> 14 | M8: =Pharma!AW33 -> 0.86813187 | N8: =Pharma!BJ33 -> 90 | O8: =Pharma!BK33 -> 7 | P8: =Pharma!N33 -> 3 | Q8: =Pharma!CC33 -> 1119 | R8: =Pharma!O33 -> 15 | S8: =Pharma!CD33 -> 6.1483516 | T8: =IF(S8>=12,"🟢 Excellent",IF(S8>=6,"🟡 Needs Improvement","🔴 Critical")) -> 🟡 Needs Improvement
A9: =Pharma!A40 -> ASM | B9: =Pharma!B40 -> Central | C9: =Pharma!C40 -> Lahore-1 | D9: =Pharma!F40 -> SHAHID SULTAN | E9: =Pharma!J40 -> 5 | F9: =Pharma!K40 -> 1 | G9: =E9-J9-F9 -> 1 | H9: =Pharma!P40 -> 4 | I9: =Pharma!AC40 -> 4 | J9: =Pharma!AD40 -> 3 | K9: =Pharma!AV40 -> 42 | L9: =Pharma!M40 -> 4 | M9: =Pharma!AW40 -> 0.80769231 | N9: =Pharma!BJ40 -> 37 | O9: =Pharma!BK40 -> 13 | P9: =Pharma!N40 -> 3 | Q9: =Pharma!CC40 -> 418 | R9: =Pharma!O40 -> 4 | S9: =Pharma!CD40 -> 8.0384615 | T9: =IF(S9>=12,"🟢 Excellent",IF(S9>=6,"🟡 Needs Improvement","🔴 Critical")) -> 🟡 Needs Improvement
A10: =Pharma!A47 -> ASM | B10: =Pharma!B47 -> Central | C10: =Pharma!C47 -> Lahore-2 | D10: =Pharma!F47 -> M. KHURRAM NAZIR | E10: =Pharma!J47 -> 5 | F10: =Pharma!K47 -> 1 | G10: =E10-J10-F10 -> 1 | H10: =Pharma!P47 -> 4 | I10: =Pharma!AC47 -> 3 | J10: =Pharma!AD47 -> 3 | K10: =Pharma!AV47 -> 41 | L10: =Pharma!M47 -> 4 | M10: =Pharma!AW47 -> 0.78846154 | N10: =Pharma!BJ47 -> 33 | O10: =Pharma!BK47 -> 1 | P10: =Pharma!N47 -> 1 | Q10: =Pharma!CC47 -> 309 | R10: =Pharma!O47 -> 4 | S10: =Pharma!CD47 -> 5.9423077 | T10: =IF(S10>=12,"🟢 Excellent",IF(S10>=6,"🟡 Needs Improvement","🔴 Critical")) -> 🔴 Critical
A11: =Pharma!A54 -> ASM | B11: =Pharma!B54 -> Central | C11: =Pharma!C54 -> Gujranwala-1 | D11: =Pharma!F54 -> UMAR SHARIF | E11: =Pharma!J54 -> 5 | F11: =Pharma!K54 -> 1 | G11: =E11-J11-F11 -> 1 | H11: =Pharma!P54 -> 4 | I11: =Pharma!AC54 -> 4 | J11: =Pharma!AD54 -> 3 | K11: =Pharma!AV54 -> 47 | L11: =Pharma!M54 -> 4 | M11: =Pharma!AW54 -> 0.90384615 | N11: =Pharma!BJ54 -> 54 | O11: =Pharma!BK54 -> 8 | P11: =Pharma!N54 -> 1 | Q11: =Pharma!CC54 -> 486 | R11: =Pharma!O54 -> 4 | S11: =Pharma!CD54 -> 9.3461538 | T11: =IF(S11>=12,"🟢 Excellent",IF(S11>=6,"🟡 Needs Improvement","🔴 Critical")) -> 🟡 Needs Improvement
A12: =Pharma!A61 -> ASM | B12: =Pharma!B61 -> Central | C12: =Pharma!C61 -> Bahawalpur | D12: =Pharma!F61 -> WAJIH UL MALIK | E12: =Pharma!J61 -> 5 | F12: =Pharma!K61 -> 0 | G12: =E12-J12-F12 -> 0 | H12: =Pharma!P61 -> 5 | I12: =Pharma!AC61 -> 5 | J12: =Pharma!AD61 -> 5 | K12: =Pharma!AV61 -> 60 | L12: =Pharma!M61 -> 5 | M12: =Pharma!AW61 -> 0.92307692 | N12: =Pharma!BJ61 -> 65 | O12: =Pharma!BK61 -> 5 | P12: =Pharma!N61 -> 3 | Q12: =Pharma!CC61 -> 711 | R12: =Pharma!O61 -> 5 | S12: =Pharma!CD61 -> 10.938462 | T12: =IF(S12>=12,"🟢 Excellent",IF(S12>=6,"🟡 Needs Improvement","🔴 Critical")) -> 🟡 Needs Improvement
A13: =Pharma!A68 -> ASM | B13: =Pharma!B68 -> Central | C13: =Pharma!C68 -> Multan | D13: =Pharma!F68 -> M. SAJID | E13: =Pharma!J68 -> 5 | F13: =Pharma!K68 -> 0 | G13: =E13-J13-F13 -> 0 | H13: =Pharma!P68 -> 5 | I13: =Pharma!AC68 -> 5 | J13: =Pharma!AD68 -> 5 | K13: =Pharma!AV68 -> 59 | L13: =Pharma!M68 -> 5 | M13: =Pharma!AW68 -> 0.90769231 | N13: =Pharma!BJ68 -> 49 | O13: =Pharma!BK68 -> 1 | P13: =Pharma!N68 -> 1 | Q13: =Pharma!CC68 -> 558 | R13: =Pharma!O68 -> 5 | S13: =Pharma!CD68 -> 8.5846154 | T13: =IF(S13>=12,"🟢 Excellent",IF(S13>=6,"🟡 Needs Improvement","🔴 Critical")) -> 🟡 Needs Improvement
A14: =Pharma!A69 -> RSM | B14: =Pharma!B69 -> Central | C14: =Pharma!C69 -> Lahore | D14: ATIF SULTAN | E14: =Pharma!J69 -> 25 | F14: =Pharma!K69 -> 3 | G14: =E14-J14-F14 -> 3 | H14: =Pharma!P69 -> 22 | I14: =Pharma!AC69 -> 21 | J14: =Pharma!AD69 -> 19 | K14: =Pharma!AV69 -> 249 | L14: =Pharma!M69 -> 22 | M14: =Pharma!AW69 -> 0.87062937 | N14: =Pharma!BJ69 -> 238 | O14: =Pharma!BK69 -> 28 | P14: =Pharma!N69 -> 9 | Q14: =Pharma!CC69 -> 2482 | R14: =Pharma!O69 -> 22 | S14: =Pharma!CD69 -> 8.6783217 | T14: =IF(S14>=12,"🟢 Excellent",IF(S14>=6,"🟡 Needs Improvement","🔴 Critical")) -> 🟡 Needs Improvement
A15: =Pharma!A77 -> ASM | B15: =Pharma!B77 -> North | C15: =Pharma!C77 -> Faisalabad | D15: =Pharma!F77 -> M. IMRAN | E15: =Pharma!J77 -> 6 | F15: =Pharma!K77 -> 0 | G15: =E15-J15-F15 -> 1 | H15: =Pharma!P77 -> 6 | I15: =Pharma!AC77 -> 6 | J15: =Pharma!AD77 -> 5 | K15: =Pharma!AV77 -> 65 | L15: =Pharma!M77 -> 6 | M15: =Pharma!AW77 -> 0.83333333 | N15: =Pharma!BJ77 -> 56 | O15: =Pharma!BK77 -> 9 | P15: =Pharma!N77 -> 5 | Q15: =Pharma!CC77 -> 595 | R15: =Pharma!O77 -> 6 | S15: =Pharma!CD77 -> 7.6282051 | T15: =IF(S15>=12,"🟢 Excellent",IF(S15>=6,"🟡 Needs Improvement","🔴 Critical")) -> 🟡 Needs Improvement
A16: =Pharma!A85 -> ASM | B16: =Pharma!B85 -> North | C16: =Pharma!C85 -> Sargodha | D16: =Pharma!F85 -> AMIR ABBAS | E16: =Pharma!J85 -> 6 | F16: =Pharma!K85 -> 1 | G16: =E16-J16-F16 -> 1 | H16: =Pharma!P85 -> 5 | I16: =Pharma!AC85 -> 5 | J16: =Pharma!AD85 -> 4 | K16: =Pharma!AV85 -> 56 | L16: =Pharma!M85 -> 5 | M16: =Pharma!AW85 -> 0.86153846 | N16: =Pharma!BJ85 -> 38 | O16: =Pharma!BK85 -> 2 | P16: =Pharma!N85 -> 1 | Q16: =Pharma!CC85 -> 422 | R16: =Pharma!O85 -> 5 | S16: =Pharma!CD85 -> 6.4923077 | T16: =IF(S16>=12,"🟢 Excellent",IF(S16>=6,"🟡 Needs Improvement","🔴 Critical")) -> 🟡 Needs Improvement
A17: =Pharma!A96 -> ASM | B17: =Pharma!B96 -> North | C17: =Pharma!C96 -> Islamabad | D17: =Pharma!F96 -> MS. AMNA YASIR | E17: =Pharma!J96 -> 9 | F17: =Pharma!K96 -> 1 | G17: =E17-J17-F17 -> 1 | H17: =Pharma!P96 -> 8 | I17: =Pharma!AC96 -> 7 | J17: =Pharma!AD96 -> 7 | K17: =Pharma!AV96 -> 88 | L17: =Pharma!M96 -> 8 | M17: =Pharma!AW96 -> 0.84615385 | N17: =Pharma!BJ96 -> 42 | O17: =Pharma!BK96 -> 11 | P17: =Pharma!N96 -> 4 | Q17: =Pharma!CC96 -> 649 | R17: =Pharma!O96 -> 8 | S17: =Pharma!CD96 -> 6.2403846 | T17: =IF(S17>=12,"🟢 Excellent",IF(S17>=6,"🟡 Needs Improvement","🔴 Critical")) -> 🟡 Needs Improvement
A18: =Pharma!A107 -> ASM | B18: =Pharma!B107 -> North | C18: =Pharma!C107 -> Peshawar | D18: FAROOQ AHMED | E18: =Pharma!J107 -> 9 | F18: =Pharma!K107 -> 5 | G18: =E18-J18-F18 -> 0 | H18: =Pharma!P107 -> 5 | I18: =Pharma!AC107 -> 4 | J18: =Pharma!AD107 -> 4 | K18: =Pharma!AV107 -> 46 | L18: =Pharma!M107 -> 5 | M18: =Pharma!AW107 -> 0.88461538 | N18: =Pharma!BJ107 -> 39 | O18: =Pharma!BK107 -> 6 | P18: =Pharma!N107 -> 2 | Q18: =Pharma!CC107 -> 420 | R18: =Pharma!O107 -> 5 | S18: =Pharma!CD107 -> 8.0769231 | T18: =IF(S18>=12,"🟢 Excellent",IF(S18>=6,"🟡 Needs Improvement","🔴 Critical")) -> 🟡 Needs Improvement
A19: =Pharma!A108 -> RSM | B19: =Pharma!B108 -> North | C19: =Pharma!C108 -> Islamabad | D19: ABID NASEEM | E19: =Pharma!J108 -> 30 | F19: =Pharma!K108 -> 7 | G19: =E19-J19-F19 -> 3 | H19: =Pharma!P108 -> 24 | I19: =Pharma!AC108 -> 22 | J19: =Pharma!AD108 -> 20 | K19: =Pharma!AV108 -> 255 | L19: =Pharma!M108 -> 24 | M19: =Pharma!AW108 -> 0.85284281 | N19: =Pharma!BJ108 -> 175 | O19: =Pharma!BK108 -> 28 | P19: =Pharma!N108 -> 12 | Q19: =Pharma!CC108 -> 2086 | R19: =Pharma!O108 -> 24 | S19: =Pharma!CD108 -> 6.9765886 | T19: =IF(S19>=12,"🟢 Excellent",IF(S19>=6,"🟡 Needs Improvement","🔴 Critical")) -> 🟡 Needs Improvement
